Workbook
Name COURSES: 'Course List'!$A:$A

Sheet SCOREBOARD
D3: Sautering Irons | O3: HileDrivers | W3: Hide this and everything to the right.
D4: =if(and(sum(Q17,Q26,Q35,Q44,Q57,Q66,Q75,Q84,Q93,Q102,Q111,Q120,Q133,Q142,Q151,Q160,Q190)=41.5, sum(D17,D26,D35,D44,D57,D66,D75,D84,D93,D102,D111,D120,D133,D142,D151,D160,D190)=41.5), sum(D17,D26,D35,D44,D57,D66,D75,D84,D93,D102,D111,D120,D133,D142,D151,D160,D190)+D192, sum(D17,D26,D35,D44,D57,D66,D75,D84,D93,D102,D111,D120,D133,D142,D151,D160,D190)) -> 37 | O4: =if(and(sum(Q17,Q26,Q35,Q44,Q57,Q66,Q75,Q84,Q93,Q102,Q111,Q120,Q133,Q142,Q151,Q160,Q190)=41.5, sum(D17,D26,D35,D44,D57,D66,D75,D84,D93,D102,D111,D120,D133,D142,D151,D160,D190)=41.5), sum(Q17,Q26,Q35,Q44,Q57,Q66,Q75,Q84,Q93,Q102,Q111,Q120,Q133,Q142,Q151,Q160,Q190)+Q192, sum(Q17,Q26,Q35,Q44,Q57,Q66,Q75,Q84,Q93,Q102,Q111,Q120,Q133,Q142,Q151,Q160,Q190)) -> 46
C6: Takes 42 to Win | N6: =if(and(G4+O4>83, G4>O4),"<< Tie Breaker", if(and(G4+O4>83, G4<O4),"Tie Breaker >>","Pts Avail: "&83-D4-O4)) -> Pts Avail: 0
B10: ='Master Input'!E6 -> GVSU Meadows - Blue | L10: ='Master Input'!F6 -> 2-Man Best Ball
B11: Score Tracking: Match Status and Points
A13: =W14 -> R1_G1 | C13: Match 1 | K13: Thru | L13: =18-countif(AC15:AT15,"") -> 18 | Y13: Front | Z13: Back | AA13: Overall | AB13: Hole: | AC13: 1 | AD13: 2 | AE13: 3 | AF13: 4 | AG13: 5 | AH13: 6 | AI13: 7 | AJ13: 8 | AK13: 9 | AL13: 10 | AM13: 11 | AN13: 12 | AO13: 13 | AP13: 14 | AQ13: 15 | AR13: 16 | AS13: 17 | AT13: 18
C14: ='Match Selection'!G4 -> CuzNick | I14: Front | L14: Back | P14: ='Match Selection'!D4 -> TJSC | W14: R1_G1 | X14: Base Team | Y14: =if(L13=0,"",sum(AC15:AK15)) -> -7 | Z14: =if(L13<10,"",sum(AL15:AT15)) -> -1 | AA14: =if(L13<10,"",sum(AC15:AT15)) -> -8 | AB14: VLOOKUP REF: | AC14: 4 | AD14: 5 | AE14: 6 | AF14: 7 | AG14: 8 | AH14: 9 | AI14: 10 | AJ14: 11 | AK14: 12 | AL14: 16 | AM14: 17 | AN14: 18 | AO14: 19 | AP14: 20 | AQ14: 21 | AR14: 22 | AS14: 23 | AT14: 24
C15: ='Match Selection'!G5 -> Saugy | I15: =if(and(Y16>0,Y14<>0,Y14<>"",Y17=""),abs(Y14)&" UP", if(abs(AG17)>AG16,abs(AG17)&"&"&AG16, if(abs(AH17)>AH16,abs(AH17)&"&"&AH16, if(abs(AI17)>AI16,abs(AI17)&"&"&AI16, if(abs(AJ17)>AJ16,abs(AJ17)&"&"&AJ16, if(abs(AK17)>AK16,abs(AK17)&"&"&AK16,"AS")))))) -> 4&3 | L15: =if(and(Z16>0,Z14<>0,Z14<>"",Z17=""),abs(Z14)&" UP", if(abs(AP17)>AP16,abs(AP17)&"&"&AP16, if(abs(AQ17)>AQ16,abs(AQ17)&"&"&AQ16, if(abs(AR17)>AR16,abs(AR17)&"&"&AR16, if(abs(AS17)>AS16,abs(AS17)&"&"&AS16, if(abs(AT17)>AT16,abs(AT17)&"&"&AT16,"AS")))))) -> 2&1 | P15: ='Match Selection'!D5 -> Joe O | W15: =$L$10 -> 2-Man Best Ball | X15: Opposition | Y15: =if(L13=0,"",if(Y14=0,0,Y14*-1)) -> 7 | Z15: =if(L13<10,"",if(Z14=0,0,Z14*-1)) -> 1 | AA15: =if(L13<10,"",if(AA14=0,0,AA14*-1)) -> 8 | AB15: Hole Won/Lost: | AC15: =VLOOKUP("Match",indirect($W14&"!"&"$B$23:$y$23"),AC14) -> -1 | AD15: =VLOOKUP("Match",indirect($W14&"!"&"$B$23:$y$23"),AD14) -> -1 | AE15: =VLOOKUP("Match",indirect($W14&"!"&"$B$23:$y$23"),AE14) -> -1 | AF15: =VLOOKUP("Match",indirect($W14&"!"&"$B$23:$y$23"),AF14) -> -1 | AG15: =VLOOKUP("Match",indirect($W14&"!"&"$B$23:$y$23"),AG14) -> 1 | AH15: =VLOOKUP("Match",indirect($W14&"!"&"$B$23:$y$23"),AH14) -> -1 | AI15: =VLOOKUP("Match",indirect($W14&"!"&"$B$23:$y$23"),AI14) -> -1 | AJ15: =VLOOKUP("Match",indirect($W14&"!"&"$B$23:$y$23"),AJ14) -> -1 | ... AT15: =VLOOKUP("Match",indirect($W14&"!"&"$B$23:$y$23"),AT14) -> 1
D16: Points | J16: Overall | Q16: Points | X16: Holes Left | Y16: {=(countif(indirect(W14&"!"&"$E$19:$M$19"),""))} -> 0 | Z16: {=(countif(indirect(W14&"!"&"$Q$19:$Y$19"),""))} -> 0 | AA16: {=(countif(indirect(W14&"!"&"$E$19:$M$19"),"")) +(countif(indirect(W14&"!"&"$Q$19:$Y$19"),""))} -> 0 | AB16: Holes Left Front Back | AC16: 8 | AD16: 7 | AE16: 6 | AF16: 5 | AG16: 4 | AH16: 3 | AI16: 2 | AJ16: 1 | AK16: 0 | AL16: 8 | AM16: 7 | AN16: 6 | AO16: 5 | AP16: 4 | AQ16: 3 | AR16: 2 | AS16: 1 | AT16: 0
D17: =if(Y18="","",sum(Y18:AA18)) -> 4 | J17: =if(and(AA16>0,AA14<>0,AA14<>"",AA17=""),abs(AA14)&" UP", if(abs(AG19)>AG18,abs(AG19)&"&"&AG18, if(abs(AH19)>AH18,abs(AH19)&"&"&AH18, if(abs(AI19)>AI18,abs(AI19)&"&"&AI18, if(abs(AJ19)>AJ18,abs(AJ19)&"&"&AJ18, if(abs(AK19)>AK18,abs(AK19)&"&"&AK18, if(abs(AL19)>AL18,abs(AL19)&"&"&AL18, if(abs(AM19)>AM18,abs(AM19)&"&"&AM18, if(abs(AN19)>AN18,abs(AN19)&"&"&AN18, if(abs(AO19)>AO18,abs(AO19)&"&"&AO18, if(abs(AP19)>AP18,abs(AP19)&"&"&AP18, if(abs(AQ19)>AQ18,abs(AQ19)&"&"&AQ18, if(abs(AR19)>AR18,abs(AR19)&"&"&AR18, if(abs(AS19)>AS18,abs(AS19)&"&"&AS18, if(abs(AT19)>AT18,abs(AT19)&"&"&AT18, "AS"))))))))))))))) -> 7&6 | Q17: =if(Y17="","",sum(Y17:AA17)) -> 0 | X17: Base Team Pts | Y17: =if(Y14="","",if(or(Y14>Y16,Y15>Y16,and(Y14=0,Y16=0)), if(Y14=0,vlookup($W15,'Master Input'!$O$12:$R$18,'Master Input'!P$11,false)/2, if(Y14>0,vlookup($W15,'Master Input'!$O$12:$R$18,'Master Input'!P$11,false), if(Y14<0,0,""))),"")) -> 0 | Z17: =if(Z14="","",if(or(Z14>Z16,Z15>Z16,and(Z14=0,Z16=0)), if(Z14=0,vlookup($W15,'Master Input'!$O$12:$R$18,'Master Input'!Q$11,false)/2, if(Z14>0,vlookup($W15,'Master Input'!$O$12:$R$18,'Master Input'!Q$11,false), if(Z14<0,0,""))),"")) -> 0 | AA17: =if(AA14="","",if(or(AA14>AA16,AA15>AA16,and(AA14=0,AA16=0)), if(AA14=0,vlookup($W15,'Master Input'!$O$12:$R$18,'Master Input'!R$11,false)/2, if(AA14>0,vlookup($W15,'Master Input'!$O$12:$R$18,'Master Input'!R$11,false), if(AA14<0,0,""))),"")) -> 0 | AB17: Match Front Back | AC17: =if(AC15="","",AC15) -> -1 | AD17: =if(AD15="","",AD15+AC17) -> -2 | AE17: =if(AE15="","",AE15+AD17) -> -3 | AF17: =if(AF15="","",AF15+AE17) -> -4 | AG17: =if(AG15="","",AG15+AF17) -> -3 | AH17: =if(AH15="","",AH15+AG17) -> -4 | AI17: =if(AI15="","",AI15+AH17) -> -5 | AJ17: =if(AJ15="","",AJ15+AI17) -> -6 | AK17: =if(AK15="","",AK15+AJ17) -> -7 | AL17: =if(AL15="","",AL15) -> 0 | AM17: =if(AM15="","",AM15+AL17) -> 0 | AN17: =if(AN15="","",AN15+AM17) -> 0 | AO17: =if(AO15="","",AO15+AN17) -> -1 | AP17: =if(AP15="","",AP15+AO17) -> -1 | AQ17: =if(AQ15="","",AQ15+AP17) -> 0 | AR17: =if(AR15="","",AR15+AQ17) -> -1 | AS17: =if(AS15="","",AS15+AR17) -> -2 | AT17: =if(AT15="","",AT15+AS17) -> -1
X18: Opposition Pts | Y18: =if(Y17="","",vlookup($W15,'Master Input'!$O$12:$R$18,'Master Input'!P$11,false)-Y17) -> 1 | Z18: =if(Z17="","",vlookup($W15,'Master Input'!$O$12:$R$18,'Master Input'!Q$11,false)-Z17) -> 1 | AA18: =if(AA17="","",vlookup($W15,'Master Input'!$O$12:$R$18,'Master Input'!R$11,false)-AA17) -> 2 | AB18: Holes Left Overall | AC18: 17 | AD18: 16 | AE18: 15 | AF18: 14 | AG18: 13 | AH18: 12 | AI18: 11 | AJ18: 10 | AK18: 9 | AL18: 8 | AM18: 7 | AN18: 6 | AO18: 5 | AP18: 4 | AQ18: 3 | AR18: 2 | AS18: 1 | AT18: 0
C19: 1 | D19: 2 | E19: 3 | F19: 4 | G19: 5 | H19: 6 | I19: 7 | J19: 8 | K19: 9 | L19: 10 | M19: 11 | N19: 12 | O19: 13 | P19: 14 | Q19: 15 | R19: 16 | S19: 17 | T19: 18 | AB19: Match Overall | AC19: =if(AC15="","",AC15) -> -1 | AD19: =if(AD15="","",AD15+AC19) -> -2 | AE19: =if(AE15="","",AE15+AD19) -> -3 | AF19: =if(AF15="","",AF15+AE19) -> -4 | AG19: =if(AG15="","",AG15+AF19) -> -3 | AH19: =if(AH15="","",AH15+AG19) -> -4 | AI19: =if(AI15="","",AI15+AH19) -> -5 | AJ19: =if(AJ15="","",AJ15+AI19) -> -6 | AK19: =if(AK15="","",AK15+AJ19) -> -7 | ... AT19: =if(AT15="","",AT15+AS19) -> -8
A22: =W23 -> R1_G2 | C22: Match 2 | K22: Thru | L22: =18-countif(AC24:AT24,"") -> 18 | Y22: Front | Z22: Back | AA22: Overall | AB22: Hole: | AC22: 1 | AD22: 2 | AE22: 3 | AF22: 4 | AG22: 5 | AH22: 6 | AI22: 7 | AJ22: 8 | AK22: 9 | AL22: 10 | AM22: 11 | AN22: 12 | AO22: 13 | AP22: 14 | AQ22: 15 | AR22: 16 | AS22: 17 | AT22: 18
C23: ='Match Selection'!M4 -> Andy | I23: Front | L23: Back | P23: ='Match Selection'!J4 -> R-Mac | W23: R1_G2 | X23: Base Team | Y23: =if(L22=0,"",sum(AC24:AK24)) -> -3 | Z23: =if(L22<10,"",sum(AL24:AT24)) -> -2 | AA23: =if(L22<10,"",sum(AC24:AT24)) -> -5 | AB23: VLOOKUP REF: | AC23: 4 | AD23: 5 | AE23: 6 | AF23: 7 | AG23: 8 | AH23: 9 | AI23: 10 | AJ23: 11 | AK23: 12 | AL23: 16 | AM23: 17 | AN23: 18 | AO23: 19 | AP23: 20 | AQ23: 21 | AR23: 22 | AS23: 23 | AT23: 24
C24: ='Match Selection'!M5 -> Pace | I24: =if(and(Y25>0,Y23<>0,Y23<>"",Y26=""),abs(Y23)&" UP", if(abs(AG26)>AG25,abs(AG26)&"&"&AG25, if(abs(AH26)>AH25,abs(AH26)&"&"&AH25, if(abs(AI26)>AI25,abs(AI26)&"&"&AI25, if(abs(AJ26)>AJ25,abs(AJ26)&"&"&AJ25, if(abs(AK26)>AK25,abs(AK26)&"&"&AK25,"AS")))))) -> 3&2 | L24: =if(and(Z25>0,Z23<>0,Z23<>"",Z26=""),abs(Z23)&" UP", if(abs(AP26)>AP25,abs(AP26)&"&"&AP25, if(abs(AQ26)>AQ25,abs(AQ26)&"&"&AQ25, if(abs(AR26)>AR25,abs(AR26)&"&"&AR25, if(abs(AS26)>AS25,abs(AS26)&"&"&AS25, if(abs(AT26)>AT25,abs(AT26)&"&"&AT25,"AS")))))) -> 2&0 | P24: ='Match Selection'!J5 -> T-Mo | W24: =$L$10 -> 2-Man Best Ball | X24: Opposition | Y24: =if(L22=0,"",if(Y23=0,0,Y23*-1)) -> 3 | Z24: =if(L22<10,"",if(Z23=0,0,Z23*-1)) -> 2 | AA24: =if(L22<10,"",if(AA23=0,0,AA23*-1)) -> 5 | AB24: Hole Won/Lost: | AC24: =VLOOKUP("Match",indirect($W23&"!"&"$B$23:$y$23"),AC23) -> -1 | AD24: =VLOOKUP("Match",indirect($W23&"!"&"$B$23:$y$23"),AD23) -> 0 | AE24: =VLOOKUP("Match",indirect($W23&"!"&"$B$23:$y$23"),AE23) -> -1 | AF24: =VLOOKUP("Match",indirect($W23&"!"&"$B$23:$y$23"),AF23) -> -1 | AG24: =VLOOKUP("Match",indirect($W23&"!"&"$B$23:$y$23"),AG23) -> 0 | AH24: =VLOOKUP("Match",indirect($W23&"!"&"$B$23:$y$23"),AH23) -> 0 | AI24: =VLOOKUP("Match",indirect($W23&"!"&"$B$23:$y$23"),AI23) -> 0 | AJ24: =VLOOKUP("Match",indirect($W23&"!"&"$B$23:$y$23"),AJ23) -> 1 | ... AT24: =VLOOKUP("Match",indirect($W23&"!"&"$B$23:$y$23"),AT23) -> -1
D25: Points | J25: Overall | Q25: Points | X25: Holes Left | Y25: {=(countif(indirect(W23&"!"&"$E$19:$M$19"),""))} -> 0 | Z25: {=(countif(indirect(W23&"!"&"$Q$19:$Y$19"),""))} -> 0 | AA25: {=(countif(indirect(W23&"!"&"$E$19:$M$19"),"")) +(countif(indirect(W23&"!"&"$Q$19:$Y$19"),""))} -> 0 | AB25: Holes Left Front Back | AC25: 8 | AD25: 7 | AE25: 6 | AF25: 5 | AG25: 4 | AH25: 3 | AI25: 2 | AJ25: 1 | AK25: 0 | AL25: 8 | AM25: 7 | AN25: 6 | AO25: 5 | AP25: 4 | AQ25: 3 | AR25: 2 | AS25: 1 | AT25: 0
D26: =if(Y27="","",sum(Y27:AA27)) -> 4 | J26: =if(and(AA25>0,AA23<>0,AA23<>"",AA26=""),abs(AA23)&" UP", if(abs(AG28)>AG27,abs(AG28)&"&"&AG27, if(abs(AH28)>AH27,abs(AH28)&"&"&AH27, if(abs(AI28)>AI27,abs(AI28)&"&"&AI27, if(abs(AJ28)>AJ27,abs(AJ28)&"&"&AJ27, if(abs(AK28)>AK27,abs(AK28)&"&"&AK27, if(abs(AL28)>AL27,abs(AL28)&"&"&AL27, if(abs(AM28)>AM27,abs(AM28)&"&"&AM27, if(abs(AN28)>AN27,abs(AN28)&"&"&AN27, if(abs(AO28)>AO27,abs(AO28)&"&"&AO27, if(abs(AP28)>AP27,abs(AP28)&"&"&AP27, if(abs(AQ28)>AQ27,abs(AQ28)&"&"&AQ27, if(abs(AR28)>AR27,abs(AR28)&"&"&AR27, if(abs(AS28)>AS27,abs(AS28)&"&"&AS27, if(abs(AT28)>AT27,abs(AT28)&"&"&AT27, "AS"))))))))))))))) -> 5&3 | Q26: =if(Y26="","",sum(Y26:AA26)) -> 0 | X26: Base Team Pts | Y26: =if(Y23="","",if(or(Y23>Y25,Y24>Y25,and(Y23=0,Y25=0)), if(Y23=0,vlookup($W24,'Master Input'!$O$12:$R$18,'Master Input'!P$11,false)/2, if(Y23>0,vlookup($W24,'Master Input'!$O$12:$R$18,'Master Input'!P$11,false), if(Y23<0,0,""))),"")) -> 0 | Z26: =if(Z23="","",if(or(Z23>Z25,Z24>Z25,and(Z23=0,Z25=0)), if(Z23=0,vlookup($W24,'Master Input'!$O$12:$R$18,'Master Input'!Q$11,false)/2, if(Z23>0,vlookup($W24,'Master Input'!$O$12:$R$18,'Master Input'!Q$11,false), if(Z23<0,0,""))),"")) -> 0 | AA26: =if(AA23="","",if(or(AA23>AA25,AA24>AA25,and(AA23=0,AA25=0)), if(AA23=0,vlookup($W24,'Master Input'!$O$12:$R$18,'Master Input'!R$11,false)/2, if(AA23>0,vlookup($W24,'Master Input'!$O$12:$R$18,'Master Input'!R$11,false), if(AA23<0,0,""))),"")) -> 0 | AB26: Match Front Back | AC26: =if(AC24="","",AC24) -> -1 | AD26: =if(AD24="","",AD24+AC26) -> -1 | AE26: =if(AE24="","",AE24+AD26) -> -2 | AF26: =if(AF24="","",AF24+AE26) -> -3 | AG26: =if(AG24="","",AG24+AF26) -> -3 | AH26: =if(AH24="","",AH24+AG26) -> -3 | AI26: =if(AI24="","",AI24+AH26) -> -3 | AJ26: =if(AJ24="","",AJ24+AI26) -> -2 | AK26: =if(AK24="","",AK24+AJ26) -> -3 | AL26: =if(AL24="","",AL24) -> -1 | AM26: =if(AM24="","",AM24+AL26) -> -1 | AN26: =if(AN24="","",AN24+AM26) -> 0 | AO26: =if(AO24="","",AO24+AN26) -> 0 | AP26: =if(AP24="","",AP24+AO26) -> -1 | AQ26: =if(AQ24="","",AQ24+AP26) -> -2 | AR26: =if(AR24="","",AR24+AQ26) -> -1 | AS26: =if(AS24="","",AS24+AR26) -> -1 | AT26: =if(AT24="","",AT24+AS26) -> -2
X27: Opposition Pts | Y27: =if(Y26="","",vlookup($W24,'Master Input'!$O$12:$R$18,'Master Input'!P$11,false)-Y26) -> 1 | Z27: =if(Z26="","",vlookup($W24,'Master Input'!$O$12:$R$18,'Master Input'!Q$11,false)-Z26) -> 1 | AA27: =if(AA26="","",vlookup($W24,'Master Input'!$O$12:$R$18,'Master Input'!R$11,false)-AA26) -> 2 | AB27: Holes Left Overall | AC27: 17 | AD27: 16 | AE27: 15 | AF27: 14 | AG27: 13 | AH27: 12 | AI27: 11 | AJ27: 10 | AK27: 9 | AL27: 8 | AM27: 7 | AN27: 6 | AO27: 5 | AP27: 4 | AQ27: 3 | AR27: 2 | AS27: 1 | AT27: 0
C28: 1 | D28: 2 | E28: 3 | F28: 4 | G28: 5 | H28: 6 | I28: 7 | J28: 8 | K28: 9 | L28: 10 | M28: 11 | N28: 12 | O28: 13 | P28: 14 | Q28: 15 | R28: 16 | S28: 17 | T28: 18 | AB28: Match Overall | AC28: =if(AC24="","",AC24) -> -1 | AD28: =if(AD24="","",AD24+AC28) -> -1 | AE28: =if(AE24="","",AE24+AD28) -> -2 | AF28: =if(AF24="","",AF24+AE28) -> -3 | AG28: =if(AG24="","",AG24+AF28) -> -3 | AH28: =if(AH24="","",AH24+AG28) -> -3 | AI28: =if(AI24="","",AI24+AH28) -> -3 | AJ28: =if(AJ24="","",AJ24+AI28) -> -2 | AK28: =if(AK24="","",AK24+AJ28) -> -3 | ... AT28: =if(AT24="","",AT24+AS28) -> -5
A31: =W32 -> R1_G3 | C31: Match 3 | K31: Thru | L31: =18-countif(AC33:AT33,"") -> 18 | Y31: Front | Z31: Back | AA31: Overall | AB31: Hole: | AC31: 1 | AD31: 2 | AE31: 3 | AF31: 4 | AG31: 5 | AH31: 6 | AI31: 7 | AJ31: 8 | AK31: 9 | AL31: 10 | AM31: 11 | AN31: 12 | AO31: 13 | AP31: 14 | AQ31: 15 | AR31: 16 | AS31: 17 | AT31: 18
C32: ='Match Selection'!S4 -> House | I32: Front | L32: Back | P32: ='Match Selection'!P4 -> KJ | W32: R1_G3 | X32: Base Team | Y32: =if(L31=0,"",sum(AC33:AK33)) -> 1 | Z32: =if(L31<10,"",sum(AL33:AT33)) -> 3 | AA32: =if(L31<10,"",sum(AC33:AT33)) -> 4 | AB32: VLOOKUP REF: | AC32: 4 | AD32: 5 | AE32: 6 | AF32: 7 | AG32: 8 | AH32: 9 | AI32: 10 | AJ32: 11 | AK32: 12 | AL32: 16 | AM32: 17 | AN32: 18 | AO32: 19 | AP32: 20 | AQ32: 21 | AR32: 22 | AS32: 23 | AT32: 24
C33: ='Match Selection'!S5 -> Carp | I33: =if(and(Y34>0,Y32<>0,Y32<>"",Y35=""),abs(Y32)&" UP", if(abs(AG35)>AG34,abs(AG35)&"&"&AG34, if(abs(AH35)>AH34,abs(AH35)&"&"&AH34, if(abs(AI35)>AI34,abs(AI35)&"&"&AI34, if(abs(AJ35)>AJ34,abs(AJ35)&"&"&AJ34, if(abs(AK35)>AK34,abs(AK35)&"&"&AK34,"AS")))))) -> 1&0 | L33: =if(and(Z34>0,Z32<>0,Z32<>"",Z35=""),abs(Z32)&" UP", if(abs(AP35)>AP34,abs(AP35)&"&"&AP34, if(abs(AQ35)>AQ34,abs(AQ35)&"&"&AQ34, if(abs(AR35)>AR34,abs(AR35)&"&"&AR34, if(abs(AS35)>AS34,abs(AS35)&"&"&AS34, if(abs(AT35)>AT34,abs(AT35)&"&"&AT34,"AS")))))) -> 3&2 | P33: ='Match Selection'!P5 -> Weezy | W33: =$L$10 -> 2-Man Best Ball | X33: Opposition | Y33: =if(L31=0,"",if(Y32=0,0,Y32*-1)) -> -1 | Z33: =if(L31<10,"",if(Z32=0,0,Z32*-1)) -> -3 | AA33: =if(L31<10,"",if(AA32=0,0,AA32*-1)) -> -4 | AB33: Hole Won/Lost: | AC33: =VLOOKUP("Match",indirect($W32&"!"&"$B$23:$y$23"),AC32) -> -1 | AD33: =VLOOKUP("Match",indirect($W32&"!"&"$B$23:$y$23"),AD32) -> 1 | AE33: =VLOOKUP("Match",indirect($W32&"!"&"$B$23:$y$23"),AE32) -> 0 | AF33: =VLOOKUP("Match",indirect($W32&"!"&"$B$23:$y$23"),AF32) -> -1 | AG33: =VLOOKUP("Match",indirect($W32&"!"&"$B$23:$y$23"),AG32) -> 1 | AH33: =VLOOKUP("Match",indirect($W32&"!"&"$B$23:$y$23"),AH32) -> 0 | AI33: =VLOOKUP("Match",indirect($W32&"!"&"$B$23:$y$23"),AI32) -> 1 | AJ33: =VLOOKUP("Match",indirect($W32&"!"&"$B$23:$y$23"),AJ32) -> 0 | ... AT33: =VLOOKUP("Match",indirect($W32&"!"&"$B$23:$y$23"),AT32) -> -1
D34: Points | J34: Overall | Q34: Points | X34: Holes Left | Y34: {=(countif(indirect(W32&"!"&"$E$19:$M$19"),""))} -> 0 | Z34: {=(countif(indirect(W32&"!"&"$Q$19:$Y$19"),""))} -> 0 | AA34: {=(countif(indirect(W32&"!"&"$E$19:$M$19"),"")) +(countif(indirect(W32&"!"&"$Q$19:$Y$19"),""))} -> 0 | AB34: Holes Left Front Back | AC34: 8 | AD34: 7 | AE34: 6 | AF34: 5 | AG34: 4 | AH34: 3 | AI34: 2 | AJ34: 1 | AK34: 0 | AL34: 8 | AM34: 7 | AN34: 6 | AO34: 5 | AP34: 4 | AQ34: 3 | AR34: 2 | AS34: 1 | AT34: 0
D35: =if(Y36="","",sum(Y36:AA36)) -> 0 | J35: =if(and(AA34>0,AA32<>0,AA32<>"",AA35=""),abs(AA32)&" UP", if(abs(AG37)>AG36,abs(AG37)&"&"&AG36, if(abs(AH37)>AH36,abs(AH37)&"&"&AH36, if(abs(AI37)>AI36,abs(AI37)&"&"&AI36, if(abs(AJ37)>AJ36,abs(AJ37)&"&"&AJ36, if(abs(AK37)>AK36,abs(AK37)&"&"&AK36, if(abs(AL37)>AL36,abs(AL37)&"&"&AL36, if(abs(AM37)>AM36,abs(AM37)&"&"&AM36, if(abs(AN37)>AN36,abs(AN37)&"&"&AN36, if(abs(AO37)>AO36,abs(AO37)&"&"&AO36, if(abs(AP37)>AP36,abs(AP37)&"&"&AP36, if(abs(AQ37)>AQ36,abs(AQ37)&"&"&AQ36, if(abs(AR37)>AR36,abs(AR37)&"&"&AR36, if(abs(AS37)>AS36,abs(AS37)&"&"&AS36, if(abs(AT37)>AT36,abs(AT37)&"&"&AT36, "AS"))))))))))))))) -> 4&3 | Q35: =if(Y35="","",sum(Y35:AA35)) -> 4 | X35: Base Team Pts | Y35: =if(Y32="","",if(or(Y32>Y34,Y33>Y34,and(Y32=0,Y34=0)), if(Y32=0,vlookup($W33,'Master Input'!$O$12:$R$18,'Master Input'!P$11,false)/2, if(Y32>0,vlookup($W33,'Master Input'!$O$12:$R$18,'Master Input'!P$11,false), if(Y32<0,0,""))),"")) -> 1 | Z35: =if(Z32="","",if(or(Z32>Z34,Z33>Z34,and(Z32=0,Z34=0)), if(Z32=0,vlookup($W33,'Master Input'!$O$12:$R$18,'Master Input'!Q$11,false)/2, if(Z32>0,vlookup($W33,'Master Input'!$O$12:$R$18,'Master Input'!Q$11,false), if(Z32<0,0,""))),"")) -> 1 | AA35: =if(AA32="","",if(or(AA32>AA34,AA33>AA34,and(AA32=0,AA34=0)), if(AA32=0,vlookup($W33,'Master Input'!$O$12:$R$18,'Master Input'!R$11,false)/2, if(AA32>0,vlookup($W33,'Master Input'!$O$12:$R$18,'Master Input'!R$11,false), if(AA32<0,0,""))),"")) -> 2 | AB35: Match Front Back | AC35: =if(AC33="","",AC33) -> -1 | AD35: =if(AD33="","",AD33+AC35) -> 0 | AE35: =if(AE33="","",AE33+AD35) -> 0 | AF35: =if(AF33="","",AF33+AE35) -> -1 | AG35: =if(AG33="","",AG33+AF35) -> 0 | AH35: =if(AH33="","",AH33+AG35) -> 0 | AI35: =if(AI33="","",AI33+AH35) -> 1 | AJ35: =if(AJ33="","",AJ33+AI35) -> 1 | AK35: =if(AK33="","",AK33+AJ35) -> 1 | AL35: =if(AL33="","",AL33) -> 1 | AM35: =if(AM33="","",AM33+AL35) -> 2 | AN35: =if(AN33="","",AN33+AM35) -> 2 | AO35: =if(AO33="","",AO33+AN35) -> 2 | AP35: =if(AP33="","",AP33+AO35) -> 2 | AQ35: =if(AQ33="","",AQ33+AP35) -> 3 | AR35: =if(AR33="","",AR33+AQ35) -> 3 | AS35: =if(AS33="","",AS33+AR35) -> 4 | AT35: =if(AT33="","",AT33+AS35) -> 3
X36: Opposition Pts | Y36: =if(Y35="","",vlookup($W33,'Master Input'!$O$12:$R$18,'Master Input'!P$11,false)-Y35) -> 0 | Z36: =if(Z35="","",vlookup($W33,'Master Input'!$O$12:$R$18,'Master Input'!Q$11,false)-Z35) -> 0 | AA36: =if(AA35="","",vlookup($W33,'Master Input'!$O$12:$R$18,'Master Input'!R$11,false)-AA35) -> 0 | AB36: Holes Left Overall | AC36: 17 | AD36: 16 | AE36: 15 | AF36: 14 | AG36: 13 | AH36: 12 | AI36: 11 | AJ36: 10 | AK36: 9 | AL36: 8 | AM36: 7 | AN36: 6 | AO36: 5 | AP36: 4 | AQ36: 3 | AR36: 2 | AS36: 1 | AT36: 0
C37: 1 | D37: 2 | E37: 3 | F37: 4 | G37: 5 | H37: 6 | I37: 7 | J37: 8 | K37: 9 | L37: 10 | M37: 11 | N37: 12 | O37: 13 | P37: 14 | Q37: 15 | R37: 16 | S37: 17 | T37: 18 | AB37: Match Overall | AC37: =if(AC33="","",AC33) -> -1 | AD37: =if(AD33="","",AD33+AC37) -> 0 | AE37: =if(AE33="","",AE33+AD37) -> 0 | AF37: =if(AF33="","",AF33+AE37) -> -1 | AG37: =if(AG33="","",AG33+AF37) -> 0 | AH37: =if(AH33="","",AH33+AG37) -> 0 | AI37: =if(AI33="","",AI33+AH37) -> 1 | AJ37: =if(AJ33="","",AJ33+AI37) -> 1 | AK37: =if(AK33="","",AK33+AJ37) -> 1 | ... AT37: =if(AT33="","",AT33+AS37) -> 4
A40: =W41 -> R1_G4 | C40: Match 4 | K40: Thru | L40: =18-countif(AC42:AT42,"") -> 18 | Y40: Front | Z40: Back | AA40: Overall | AB40: Hole: | AC40: 1 | AD40: 2 | AE40: 3 | AF40: 4 | AG40: 5 | AH40: 6 | AI40: 7 | AJ40: 8 | AK40: 9 | AL40: 10 | AM40: 11 | AN40: 12 | AO40: 13 | AP40: 14 | AQ40: 15 | AR40: 16 | AS40: 17 | AT40: 18
C41: ='Match Selection'!Y4 -> Jensen | I41: Front | L41: Back | P41: ='Match Selection'!V4 -> Telly | W41: R1_G4 | X41: Base Team | Y41: =if(L40=0,"",sum(AC42:AK42)) -> -4 | Z41: =if(L40<10,"",sum(AL42:AT42)) -> 0 | AA41: =if(L40<10,"",sum(AC42:AT42)) -> -4 | AB41: VLOOKUP REF: | AC41: 4 | AD41: 5 | AE41: 6 | AF41: 7 | AG41: 8 | AH41: 9 | AI41: 10 | AJ41: 11 | AK41: 12 | AL41: 16 | AM41: 17 | AN41: 18 | AO41: 19 | AP41: 20 | AQ41: 21 | AR41: 22 | AS41: 23 | AT41: 24
C42: ='Match Selection'!Y5 -> DK | I42: =if(and(Y43>0,Y41<>0,Y41<>"",Y44=""),abs(Y41)&" UP", if(abs(AG44)>AG43,abs(AG44)&"&"&AG43, if(abs(AH44)>AH43,abs(AH44)&"&"&AH43, if(abs(AI44)>AI43,abs(AI44)&"&"&AI43, if(abs(AJ44)>AJ43,abs(AJ44)&"&"&AJ43, if(abs(AK44)>AK43,abs(AK44)&"&"&AK43,"AS")))))) -> 3&2 | L42: =if(and(Z43>0,Z41<>0,Z41<>"",Z44=""),abs(Z41)&" UP", if(abs(AP44)>AP43,abs(AP44)&"&"&AP43, if(abs(AQ44)>AQ43,abs(AQ44)&"&"&AQ43, if(abs(AR44)>AR43,abs(AR44)&"&"&AR43, if(abs(AS44)>AS43,abs(AS44)&"&"&AS43, if(abs(AT44)>AT43,abs(AT44)&"&"&AT43,"AS")))))) -> AS | P42: ='Match Selection'!V5 -> Hile | W42: =$L$10 -> 2-Man Best Ball | X42: Opposition | Y42: =if(L40=0,"",if(Y41=0,0,Y41*-1)) -> 4 | Z42: =if(L40<10,"",if(Z41=0,0,Z41*-1)) -> 0 | AA42: =if(L40<10,"",if(AA41=0,0,AA41*-1)) -> 4 | AB42: Hole Won/Lost: | AC42: =VLOOKUP("Match",indirect($W41&"!"&"$B$23:$y$23"),AC41) -> -1 | AD42: =VLOOKUP("Match",indirect($W41&"!"&"$B$23:$y$23"),AD41) -> 0 | AE42: =VLOOKUP("Match",indirect($W41&"!"&"$B$23:$y$23"),AE41) -> 0 | AF42: =VLOOKUP("Match",indirect($W41&"!"&"$B$23:$y$23"),AF41) -> 0 | AG42: =VLOOKUP("Match",indirect($W41&"!"&"$B$23:$y$23"),AG41) -> -1 | AH42: =VLOOKUP("Match",indirect($W41&"!"&"$B$23:$y$23"),AH41) -> 0 | AI42: =VLOOKUP("Match",indirect($W41&"!"&"$B$23:$y$23"),AI41) -> -1 | AJ42: =VLOOKUP("Match",indirect($W41&"!"&"$B$23:$y$23"),AJ41) -> -1 | ... AT42: =VLOOKUP("Match",indirect($W41&"!"&"$B$23:$y$23"),AT41) -> 0
D43: Points | J43: Overall | Q43: Points | X43: Holes Left | Y43: {=(countif(indirect(W41&"!"&"$E$19:$M$19"),""))} -> 0 | Z43: {=(countif(indirect(W41&"!"&"$Q$19:$Y$19"),""))} -> 0 | AA43: {=(countif(indirect(W41&"!"&"$E$19:$M$19"),"")) +(countif(indirect(W41&"!"&"$Q$19:$Y$19"),""))} -> 0 | AB43: Holes Left Front Back | AC43: 8 | AD43: 7 | AE43: 6 | AF43: 5 | AG43: 4 | AH43: 3 | AI43: 2 | AJ43: 1 | AK43: 0 | AL43: 8 | AM43: 7 | AN43: 6 | AO43: 5 | AP43: 4 | AQ43: 3 | AR43: 2 | AS43: 1 | AT43: 0
D44: =if(Y45="","",sum(Y45:AA45)) -> 3.5 | J44: =if(and(AA43>0,AA41<>0,AA41<>"",AA44=""),abs(AA41)&" UP", if(abs(AG46)>AG45,abs(AG46)&"&"&AG45, if(abs(AH46)>AH45,abs(AH46)&"&"&AH45, if(abs(AI46)>AI45,abs(AI46)&"&"&AI45, if(abs(AJ46)>AJ45,abs(AJ46)&"&"&AJ45, if(abs(AK46)>AK45,abs(AK46)&"&"&AK45, if(abs(AL46)>AL45,abs(AL46)&"&"&AL45, if(abs(AM46)>AM45,abs(AM46)&"&"&AM45, if(abs(AN46)>AN45,abs(AN46)&"&"&AN45, if(abs(AO46)>AO45,abs(AO46)&"&"&AO45, if(abs(AP46)>AP45,abs(AP46)&"&"&AP45, if(abs(AQ46)>AQ45,abs(AQ46)&"&"&AQ45, if(abs(AR46)>AR45,abs(AR46)&"&"&AR45, if(abs(AS46)>AS45,abs(AS46)&"&"&AS45, if(abs(AT46)>AT45,abs(AT46)&"&"&AT45, "AS"))))))))))))))) -> 4&3 | Q44: =if(Y44="","",sum(Y44:AA44)) -> 0.5 | X44: Base Team Pts | Y44: =if(Y41="","",if(or(Y41>Y43,Y42>Y43,and(Y41=0,Y43=0)), if(Y41=0,vlookup($W42,'Master Input'!$O$12:$R$18,'Master Input'!P$11,false)/2, if(Y41>0,vlookup($W42,'Master Input'!$O$12:$R$18,'Master Input'!P$11,false), if(Y41<0,0,""))),"")) -> 0 | Z44: =if(Z41="","",if(or(Z41>Z43,Z42>Z43,and(Z41=0,Z43=0)), if(Z41=0,vlookup($W42,'Master Input'!$O$12:$R$18,'Master Input'!Q$11,false)/2, if(Z41>0,vlookup($W42,'Master Input'!$O$12:$R$18,'Master Input'!Q$11,false), if(Z41<0,0,""))),"")) -> 0.5 | AA44: =if(AA41="","",if(or(AA41>AA43,AA42>AA43,and(AA41=0,AA43=0)), if(AA41=0,vlookup($W42,'Master Input'!$O$12:$R$18,'Master Input'!R$11,false)/2, if(AA41>0,vlookup($W42,'Master Input'!$O$12:$R$18,'Master Input'!R$11,false), if(AA41<0,0,""))),"")) -> 0 | AB44: Match Front Back | AC44: =if(AC42="","",AC42) -> -1 | AD44: =if(AD42="","",AD42+AC44) -> -1 | AE44: =if(AE42="","",AE42+AD44) -> -1 | AF44: =if(AF42="","",AF42+AE44) -> -1 | AG44: =if(AG42="","",AG42+AF44) -> -2 | AH44: =if(AH42="","",AH42+AG44) -> -2 | AI44: =if(AI42="","",AI42+AH44) -> -3 | AJ44: =if(AJ42="","",AJ42+AI44) -> -4 | AK44: =if(AK42="","",AK42+AJ44) -> -4 | AL44: =if(AL42="","",AL42) -> 1 | AM44: =AM42+AL44 -> 1 | AN44: =AN42+AM44 -> 2 | AO44: =AO42+AN44 -> 2 | AP44: =AP42+AO44 -> 1 | AQ44: =AQ42+AP44 -> 0 | AR44: =AR42+AQ44 -> 1 | AS44: =AS42+AR44 -> 0 | AT44: =AT42+AS44 -> 0
X45: Opposition Pts | Y45: =if(Y44="","",vlookup($W42,'Master Input'!$O$12:$R$18,'Master Input'!P$11,false)-Y44) -> 1 | Z45: =if(Z44="","",vlookup($W42,'Master Input'!$O$12:$R$18,'Master Input'!Q$11,false)-Z44) -> 0.5 | AA45: =if(AA44="","",vlookup($W42,'Master Input'!$O$12:$R$18,'Master Input'!R$11,false)-AA44) -> 2 | AB45: Holes Left Overall | AC45: 17 | AD45: 16 | AE45: 15 | AF45: 14 | AG45: 13 | AH45: 12 | AI45: 11 | AJ45: 10 | AK45: 9 | AL45: 8 | AM45: 7 | AN45: 6 | AO45: 5 | AP45: 4 | AQ45: 3 | AR45: 2 | AS45: 1 | AT45: 0
C46: 1 | D46: 2 | E46: 3 | F46: 4 | G46: 5 | H46: 6 | I46: 7 | J46: 8 | K46: 9 | L46: 10 | M46: 11 | N46: 12 | O46: 13 | P46: 14 | Q46: 15 | R46: 16 | S46: 17 | T46: 18 | AB46: Match Overall | AC46: =if(AC42="","",AC42) -> -1 | AD46: =if(AD42="","",AD42+AC46) -> -1 | AE46: =if(AE42="","",AE42+AD46) -> -1 | AF46: =if(AF42="","",AF42+AE46) -> -1 | AG46: =if(AG42="","",AG42+AF46) -> -2 | AH46: =if(AH42="","",AH42+AG46) -> -2 | AI46: =if(AI42="","",AI42+AH46) -> -3 | AJ46: =if(AJ42="","",AJ42+AI46) -> -4 | AK46: =if(AK42="","",AK42+AJ46) -> -4 | AL46: =if(AL42="","",AL42+AK46) -> -3 | AM46: =AM42+AL46 -> -3 | AN46: =AN42+AM46 -> -2 | AO46: =AO42+AN46 -> -2 | AP46: =AP42+AO46 -> -3 | AQ46: =AQ42+AP46 -> -4 | AR46: =AR42+AQ46 -> -3 | AS46: =AS42+AR46 -> -4 | AT46: =AT42+AS46 -> -4
B50: ='Master Input'!G6 -> Ravines GC - White | L50: ='Master Input'!H6 -> Singles Matches
B51: Score Tracking: Match Status and Points
A53: =W54 -> R2_G1 | C53: Match 1 | K53: Thru | L53: =18-countif(AC55:AT55,"") -> 18 | Y53: Front | Z53: Back | AA53: Overall | AB53: Hole: | AC53: 1 | AD53: 2 | AE53: 3 | AF53: 4 | AG53: 5 | AH53: 6 | AI53: 7 | AJ53: 8 | AK53: 9 | AL53: 10 | AM53: 11 | AN53: 12 | AO53: 13 | AP53: 14 | AQ53: 15 | AR53: 16 | AS53: 17 | AT53: 18
C54: {=if(W56="top",indirect($W54&"!"&"A11"),indirect($W54&"!"&"A17"))} -> CuzNick | I54: Front | L54: Back | P54: {=if(W56="top",indirect($W54&"!"&"A8"),indirect($W54&"!"&"A14"))} -> Telly | W54: R2_G1 | X54: Base Team | Y54: =if(L53=0,"",sum(AC55:AK55)) -> -1 | Z54: =if(L53<10,"",sum(AL55:AT55)) -> 1 | AA54: =if(L53<10,"",sum(AC55:AT55)) -> 0 | AB54: VLOOKUP REF: | AC54: 4 | AD54: 5 | AE54: 6 | AF54: 7 | AG54: 8 | AH54: 9 | AI54: 10 | AJ54: 11 | AK54: 12 | AL54: 16 | AM54: 17 | AN54: 18 | AO54: 19 | AP54: 20 | AQ54: 21 | AR54: 22 | AS54: 23 | AT54: 24
I55: =if(and(Y56>0,Y54<>0,Y54<>"",Y57=""),abs(Y54)&" UP", if(abs(AG57)>AG56,abs(AG57)&"&"&AG56, if(abs(AH57)>AH56,abs(AH57)&"&"&AH56, if(abs(AI57)>AI56,abs(AI57)&"&"&AI56, if(abs(AJ57)>AJ56,abs(AJ57)&"&"&AJ56, if(abs(AK57)>AK56,abs(AK57)&"&"&AK56,"AS")))))) -> 2&1 | L55: =if(and(Z56>0,Z54<>0,Z54<>"",Z57=""),abs(Z54)&" UP", if(abs(AP57)>AP56,abs(AP57)&"&"&AP56, if(abs(AQ57)>AQ56,abs(AQ57)&"&"&AQ56, if(abs(AR57)>AR56,abs(AR57)&"&"&AR56, if(abs(AS57)>AS56,abs(AS57)&"&"&AS56, if(abs(AT57)>AT56,abs(AT57)&"&"&AT56,"AS")))))) -> 1&0 | W55: =$L$50 -> Singles Matches | X55: Opposition | Y55: =if(L53=0,"",if(Y54=0,0,Y54*-1)) -> 1 | Z55: =if(L53<10,"",if(Z54=0,0,Z54*-1)) -> -1 | AA55: =if(L53<10,"",if(AA54=0,0,AA54*-1)) -> 0 | AB55: Hole Won/Lost: | AC55: =VLOOKUP($W56&" - Front",indirect($W54&"!"&"$B$28:$y$31"),AC54,false) -> 1 | AD55: =VLOOKUP($W56&" - Front",indirect($W54&"!"&"$B$28:$y$31"),AD54,false) -> -1 | AE55: =VLOOKUP($W56&" - Front",indirect($W54&"!"&"$B$28:$y$31"),AE54,false) -> 1 | AF55: =VLOOKUP($W56&" - Front",indirect($W54&"!"&"$B$28:$y$31"),AF54,false) -> -1 | AG55: =VLOOKUP($W56&" - Front",indirect($W54&"!"&"$B$28:$y$31"),AG54,false) -> -1 | AH55: =VLOOKUP($W56&" - Front",indirect($W54&"!"&"$B$28:$y$31"),AH54,false) -> -1 | AI55: =VLOOKUP($W56&" - Front",indirect($W54&"!"&"$B$28:$y$31"),AI54,false) -> 0 | AJ55: =VLOOKUP($W56&" - Front",indirect($W54&"!"&"$B$28:$y$31"),AJ54,false) -> 0 | ... AT55: =VLOOKUP($W56&" - Front",indirect($W54&"!"&"$B$28:$y$31"),AT54,false) -> 1
D56: Points | J56: Overall | Q56: Points | W56: Top | X56: Holes Left | Y56: {=(countif(indirect(W54&"!"&"$E$20:$M$20"),""))} -> 0 | Z56: {=(countif(indirect(W54&"!"&"$Q$20:$Y$20"),""))} -> 0 | AA56: {=(countif(indirect(W54&"!"&"$E$20:$M$20"),"")) +(countif(indirect(W54&"!"&"$Q$20:$Y$20"),""))} -> 0 | AB56: Holes Left Front Back | AC56: 8 | AD56: 7 | AE56: 6 | AF56: 5 | AG56: 4 | AH56: 3 | AI56: 2 | AJ56: 1 | AK56: 0 | AL56: 8 | AM56: 7 | AN56: 6 | AO56: 5 | AP56: 4 | AQ56: 3 | AR56: 2 | AS56: 1 | AT56: 0
D57: =if(Y58="","",sum(Y58:AA58)) -> 1.5 | J57: =if(and(AA56>0,AA54<>0,AA54<>"",AA57=""),abs(AA54)&" UP", if(abs(AG59)>AG58,abs(AG59)&"&"&AG58, if(abs(AH59)>AH58,abs(AH59)&"&"&AH58, if(abs(AI59)>AI58,abs(AI59)&"&"&AI58, if(abs(AJ59)>AJ58,abs(AJ59)&"&"&AJ58, if(abs(AK59)>AK58,abs(AK59)&"&"&AK58, if(abs(AL59)>AL58,abs(AL59)&"&"&AL58, if(abs(AM59)>AM58,abs(AM59)&"&"&AM58, if(abs(AN59)>AN58,abs(AN59)&"&"&AN58, if(abs(AO59)>AO58,abs(AO59)&"&"&AO58, if(abs(AP59)>AP58,abs(AP59)&"&"&AP58, if(abs(AQ59)>AQ58,abs(AQ59)&"&"&AQ58, if(abs(AR59)>AR58,abs(AR59)&"&"&AR58, if(abs(AS59)>AS58,abs(AS59)&"&"&AS58, if(abs(AT59)>AT58,abs(AT59)&"&"&AT58, "AS"))))))))))))))) -> AS | Q57: =if(Y57="","",sum(Y57:AA57)) -> 1.5 | X57: Base Team Pts | Y57: =if(Y54="","",if(or(Y54>Y56,Y55>Y56,and(Y54=0,Y56=0)), if(Y54=0,vlookup($W55,'Master Input'!$O$12:$R$18,'Master Input'!P$11,false)/2, if(Y54>0,vlookup($W55,'Master Input'!$O$12:$R$18,'Master Input'!P$11,false), if(Y54<0,0,""))),"")) -> 0 | Z57: =if(Z54="","",if(or(Z54>Z56,Z55>Z56,and(Z54=0,Z56=0)), if(Z54=0,vlookup($W55,'Master Input'!$O$12:$R$18,'Master Input'!Q$11,false)/2, if(Z54>0,vlookup($W55,'Master Input'!$O$12:$R$18,'Master Input'!Q$11,false), if(Z54<0,0,""))),"")) -> 1 | AA57: =if(AA54="","",if(or(AA54>AA56,AA55>AA56,and(AA54=0,AA56=0)), if(AA54=0,vlookup($W55,'Master Input'!$O$12:$R$18,'Master Input'!R$11,false)/2, if(AA54>0,vlookup($W55,'Master Input'!$O$12:$R$18,'Master Input'!R$11,false), if(AA54<0,0,""))),"")) -> 0.5 | AB57: Match Front Back | AC57: =if(AC55="","",AC55) -> 1 | AD57: =if(AD55="","",AD55+AC57) -> 0 | AE57: =if(AE55="","",AE55+AD57) -> 1 | AF57: =if(AF55="","",AF55+AE57) -> 0 | AG57: =if(AG55="","",AG55+AF57) -> -1 | AH57: =if(AH55="","",AH55+AG57) -> -2 | AI57: =if(AI55="","",AI55+AH57) -> -2 | AJ57: =if(AJ55="","",AJ55+AI57) -> -2 | AK57: =if(AK55="","",AK55+AJ57) -> -1 | AL57: =if(AL55="","",AL55) -> 0 | AM57: =if(AM55="","",AM55+AL57) -> 0 | AN57: =if(AN55="","",AN55+AM57) -> 0 | AO57: =if(AO55="","",AO55+AN57) -> 0 | AP57: =if(AP55="","",AP55+AO57) -> 0 | AQ57: =if(AQ55="","",AQ55+AP57) -> -1 | AR57: =if(AR55="","",AR55+AQ57) -> 0 | AS57: =if(AS55="","",AS55+AR57) -> 0 | AT57: =if(AT55="","",AT55+AS57) -> 1
...

Sheet R1_G1
A1: Group 1 | B1: ='Master Input'!E3 -> 0.52083333 | C1: ='Master Input'!$E$2 -> Round 1 | E1: ='Master Input'!$E$6 -> GVSU Meadows - Blue | P1: ='Master Input'!$E$2 -> Round 1 | R1: ='Master Input'!$E$6 -> GVSU Meadows - Blue
A2: Handi: | B2: ='Match Selection'!B4 -> 2-Man Best Ball | D2: Handi: | E2: =vlookup($E1, 'Course List'!$A$3:$AS$14,5+E4, false) -> 2 | F2: =vlookup($E1, 'Course List'!$A$3:$AS$14,5+F4, false) -> 8 | G2: =vlookup($E1, 'Course List'!$A$3:$AS$14,5+G4, false) -> 14 | H2: =vlookup($E1, 'Course List'!$A$3:$AS$14,5+H4, false) -> 12 | I2: =vlookup($E1, 'Course List'!$A$3:$AS$14,5+I4, false) -> 6 | J2: =vlookup($E1, 'Course List'!$A$3:$AS$14,5+J4, false) -> 18 | K2: =vlookup($E1, 'Course List'!$A$3:$AS$14,5+K4, false) -> 10 | L2: =vlookup($E1, 'Course List'!$A$3:$AS$14,5+L4, false) -> 4 | M2: =vlookup($E1, 'Course List'!$A$3:$AS$14,5+M4, false) -> 16 | P2: Handi: | Q2: =vlookup($E1, 'Course List'!$A$3:$AS$14,5+Q4, false) -> 13 | R2: =vlookup($E1, 'Course List'!$A$3:$AS$14,5+R4, false) -> 3 | S2: =vlookup($E1, 'Course List'!$A$3:$AS$14,5+S4, false) -> 9 | T2: =vlookup($E1, 'Course List'!$A$3:$AS$14,5+T4, false) -> 15 | U2: =vlookup($E1, 'Course List'!$A$3:$AS$14,5+U4, false) -> 11 | V2: =vlookup($E1, 'Course List'!$A$3:$AS$14,5+V4, false) -> 5 | W2: =vlookup($E1, 'Course List'!$A$3:$AS$14,5+W4, false) -> 7 | X2: =vlookup($E1, 'Course List'!$A$3:$AS$14,5+X4, false) -> 17 | Y2: =vlookup($E1, 'Course List'!$A$3:$AS$14,5+Y4, false) -> 1
A3: Par: | D3: Par: | E3: =vlookup($E1, 'Course List'!$A$3:$AS$14,27+E4, false) -> 4 | F3: =vlookup($E1, 'Course List'!$A$3:$AS$14,27+F4, false) -> 4 | G3: =vlookup($E1, 'Course List'!$A$3:$AS$14,27+G4, false) -> 3 | H3: =vlookup($E1, 'Course List'!$A$3:$AS$14,27+H4, false) -> 5 | I3: =vlookup($E1, 'Course List'!$A$3:$AS$14,27+I4, false) -> 4 | J3: =vlookup($E1, 'Course List'!$A$3:$AS$14,27+J4, false) -> 4 | K3: =vlookup($E1, 'Course List'!$A$3:$AS$14,27+K4, false) -> 3 | L3: =vlookup($E1, 'Course List'!$A$3:$AS$14,27+L4, false) -> 4 | M3: =vlookup($E1, 'Course List'!$A$3:$AS$14,27+M4, false) -> 5 | N3: =SUM(E3:M3) -> 36 | P3: Par: | Q3: =vlookup($E1, 'Course List'!$A$3:$AS$14,27+Q4, false) -> 4 | R3: =vlookup($E1, 'Course List'!$A$3:$AS$14,27+R4, false) -> 4 | S3: =vlookup($E1, 'Course List'!$A$3:$AS$14,27+S4, false) -> 4 | T3: =vlookup($E1, 'Course List'!$A$3:$AS$14,27+T4, false) -> 3 | U3: =vlookup($E1, 'Course List'!$A$3:$AS$14,27+U4, false) -> 5 | V3: =vlookup($E1, 'Course List'!$A$3:$AS$14,27+V4, false) -> 4 | W3: =vlookup($E1, 'Course List'!$A$3:$AS$14,27+W4, false) -> 4 | X3: =vlookup($E1, 'Course List'!$A$3:$AS$14,27+X4, false) -> 3 | Y3: =vlookup($E1, 'Course List'!$A$3:$AS$14,27+Y4, false) -> 4 | Z3: =SUM(Q3:Y3) -> 35 | AA3: =N3+Z3 -> 71
A4: Hole: | B4: Team | C4: Tee HCP | D4: Net HCP | E4: 1 | F4: 2 | G4: 3 | H4: 4 | I4: 5 | J4: 6 | K4: 7 | L4: 8 | M4: 9 | N4: OUT | P4: Hole: | Q4: 10 | R4: 11 | S4: 12 | T4: 13 | U4: 14 | V4: 15 | W4: 16 | X4: 17 | Y4: 18 | Z4: IN | AA4: Total Gross | AB4: Total Net
E6: =if(E7=1,"O", if(E7=2,"O O","")) -> O | F6: =if(F7=1,"O", if(F7=2,"O O","")) | G6: =if(G7=1,"O", if(G7=2,"O O","")) | H6: =if(H7=1,"O", if(H7=2,"O O","")) | I6: =if(I7=1,"O", if(I7=2,"O O","")) -> O | J6: =if(J7=1,"O", if(J7=2,"O O","")) | K6: =if(K7=1,"O", if(K7=2,"O O","")) | L6: =if(L7=1,"O", if(L7=2,"O O","")) -> O | M6: =if(M7=1,"O", if(M7=2,"O O","")) | Q6: =if(Q7=1,"O", if(Q7=2,"O O","")) | R6: =if(R7=1,"O", if(R7=2,"O O","")) -> O | S6: =if(S7=1,"O", if(S7=2,"O O","")) | T6: =if(T7=1,"O", if(T7=2,"O O","")) | U6: =if(U7=1,"O", if(U7=2,"O O","")) | V6: =if(V7=1,"O", if(V7=2,"O O","")) -> O | W6: =if(W7=1,"O", if(W7=2,"O O","")) | X6: =if(X7=1,"O", if(X7=2,"O O","")) | Y6: =if(Y7=1,"O", if(Y7=2,"O O","")) -> O
E7: =IF($D8>0,FLOOR($D8/18,1),0)+IF(AND(MOD($D8,18)>=E$2,$D8>0),1,0)-IF(E$2-18>$D8,1,0) -> 1 | F7: =IF($D8>0,FLOOR($D8/18,1),0)+IF(AND(MOD($D8,18)>=F$2,$D8>0),1,0)-IF(F$2-18>$D8,1,0) -> 0 | G7: =IF($D8>0,FLOOR($D8/18,1),0)+IF(AND(MOD($D8,18)>=G$2,$D8>0),1,0)-IF(G$2-18>$D8,1,0) -> 0 | H7: =IF($D8>0,FLOOR($D8/18,1),0)+IF(AND(MOD($D8,18)>=H$2,$D8>0),1,0)-IF(H$2-18>$D8,1,0) -> 0 | I7: =IF($D8>0,FLOOR($D8/18,1),0)+IF(AND(MOD($D8,18)>=I$2,$D8>0),1,0)-IF(I$2-18>$D8,1,0) -> 1 | J7: =IF($D8>0,FLOOR($D8/18,1),0)+IF(AND(MOD($D8,18)>=J$2,$D8>0),1,0)-IF(J$2-18>$D8,1,0) -> 0 | K7: =IF($D8>0,FLOOR($D8/18,1),0)+IF(AND(MOD($D8,18)>=K$2,$D8>0),1,0)-IF(K$2-18>$D8,1,0) -> 0 | L7: =IF($D8>0,FLOOR($D8/18,1),0)+IF(AND(MOD($D8,18)>=L$2,$D8>0),1,0)-IF(L$2-18>$D8,1,0) -> 1 | M7: =IF($D8>0,FLOOR($D8/18,1),0)+IF(AND(MOD($D8,18)>=M$2,$D8>0),1,0)-IF(M$2-18>$D8,1,0) -> 0 | Q7: =IF($D8>0,FLOOR($D8/18,1),0)+IF(AND(MOD($D8,18)>=Q$2,$D8>0),1,0)-IF(Q$2-18>$D8,1,0) -> 0 | R7: =IF($D8>0,FLOOR($D8/18,1),0)+IF(AND(MOD($D8,18)>=R$2,$D8>0),1,0)-IF(R$2-18>$D8,1,0) -> 1 | S7: =IF($D8>0,FLOOR($D8/18,1),0)+IF(AND(MOD($D8,18)>=S$2,$D8>0),1,0)-IF(S$2-18>$D8,1,0) -> 0 | T7: =IF($D8>0,FLOOR($D8/18,1),0)+IF(AND(MOD($D8,18)>=T$2,$D8>0),1,0)-IF(T$2-18>$D8,1,0) -> 0 | U7: =IF($D8>0,FLOOR($D8/18,1),0)+IF(AND(MOD($D8,18)>=U$2,$D8>0),1,0)-IF(U$2-18>$D8,1,0) -> 0 | V7: =IF($D8>0,FLOOR($D8/18,1),0)+IF(AND(MOD($D8,18)>=V$2,$D8>0),1,0)-IF(V$2-18>$D8,1,0) -> 1 | W7: =IF($D8>0,FLOOR($D8/18,1),0)+IF(AND(MOD($D8,18)>=W$2,$D8>0),1,0)-IF(W$2-18>$D8,1,0) -> 0 | X7: =IF($D8>0,FLOOR($D8/18,1),0)+IF(AND(MOD($D8,18)>=X$2,$D8>0),1,0)-IF(X$2-18>$D8,1,0) -> 0 | Y7: =IF($D8>0,FLOOR($D8/18,1),0)+IF(AND(MOD($D8,18)>=Y$2,$D8>0),1,0)-IF(Y$2-18>$D8,1,0) -> 1
A8: ='Match Selection'!D4 -> TJSC | B8: =vlookup(A8, 'Master Input'!$A$11:$B$27, 2, false) -> Drivers | C8: =vlookup(A8,'Master Input'!$A$11:$L$27,'Master Input'!$F$28, false) -> 15 | D8: =C8-SMALL($C$8:$C$17,1) -> 6 | E8: 7 | F8: 5 | G8: 4 | H8: 6 | I8: 4 | J8: 5 | K8: 4 | L8: 6 | M8: 7 | N8: =if(M8="","", sum(E8:M8)) -> 48 | P8: =A8 -> TJSC | Q8: 4 | R8: 5 | S8: 4 | T8: 5 | U8: 7 | V8: 5 | W8: 5 | X8: 4 | Y8: 4 | Z8: =if(Y8="","", sum(Q8:Y8)) -> 43 | AA8: =if(Z8="", "", sum(N8,Z8)) -> 91 | AB8: =if(Y8="", "", AA8-C8) -> 76
E9: =if(E10=1,"O", if(E10=2,"O O","")) -> O | F9: =if(F10=1,"O", if(F10=2,"O O","")) -> O | G9: =if(G10=1,"O", if(G10=2,"O O","")) | H9: =if(H10=1,"O", if(H10=2,"O O","")) | I9: =if(I10=1,"O", if(I10=2,"O O","")) -> O | J9: =if(J10=1,"O", if(J10=2,"O O","")) | K9: =if(K10=1,"O", if(K10=2,"O O","")) | L9: =if(L10=1,"O", if(L10=2,"O O","")) -> O | M9: =if(M10=1,"O", if(M10=2,"O O","")) | Q9: =if(Q10=1,"O", if(Q10=2,"O O","")) | R9: =if(R10=1,"O", if(R10=2,"O O","")) -> O | S9: =if(S10=1,"O", if(S10=2,"O O","")) | T9: =if(T10=1,"O", if(T10=2,"O O","")) | U9: =if(U10=1,"O", if(U10=2,"O O","")) | V9: =if(V10=1,"O", if(V10=2,"O O","")) -> O | W9: =if(W10=1,"O", if(W10=2,"O O","")) -> O | X9: =if(X10=1,"O", if(X10=2,"O O","")) | Y9: =if(Y10=1,"O", if(Y10=2,"O O","")) -> O
E10: =IF($D11>0,FLOOR($D11/18,1),0)+IF(AND(MOD($D11,18)>=E$2,$D11>0),1,0)-IF(E$2-18>$D11,1,0) -> 1 | F10: =IF($D11>0,FLOOR($D11/18,1),0)+IF(AND(MOD($D11,18)>=F$2,$D11>0),1,0)-IF(F$2-18>$D11,1,0) -> 1 | G10: =IF($D11>0,FLOOR($D11/18,1),0)+IF(AND(MOD($D11,18)>=G$2,$D11>0),1,0)-IF(G$2-18>$D11,1,0) -> 0 | H10: =IF($D11>0,FLOOR($D11/18,1),0)+IF(AND(MOD($D11,18)>=H$2,$D11>0),1,0)-IF(H$2-18>$D11,1,0) -> 0 | I10: =IF($D11>0,FLOOR($D11/18,1),0)+IF(AND(MOD($D11,18)>=I$2,$D11>0),1,0)-IF(I$2-18>$D11,1,0) -> 1 | J10: =IF($D11>0,FLOOR($D11/18,1),0)+IF(AND(MOD($D11,18)>=J$2,$D11>0),1,0)-IF(J$2-18>$D11,1,0) -> 0 | K10: =IF($D11>0,FLOOR($D11/18,1),0)+IF(AND(MOD($D11,18)>=K$2,$D11>0),1,0)-IF(K$2-18>$D11,1,0) -> 0 | L10: =IF($D11>0,FLOOR($D11/18,1),0)+IF(AND(MOD($D11,18)>=L$2,$D11>0),1,0)-IF(L$2-18>$D11,1,0) -> 1 | M10: =IF($D11>0,FLOOR($D11/18,1),0)+IF(AND(MOD($D11,18)>=M$2,$D11>0),1,0)-IF(M$2-18>$D11,1,0) -> 0 | Q10: =IF($D11>0,FLOOR($D11/18,1),0)+IF(AND(MOD($D11,18)>=Q$2,$D11>0),1,0)-IF(Q$2-18>$D11,1,0) -> 0 | R10: =IF($D11>0,FLOOR($D11/18,1),0)+IF(AND(MOD($D11,18)>=R$2,$D11>0),1,0)-IF(R$2-18>$D11,1,0) -> 1 | S10: =IF($D11>0,FLOOR($D11/18,1),0)+IF(AND(MOD($D11,18)>=S$2,$D11>0),1,0)-IF(S$2-18>$D11,1,0) -> 0 | T10: =IF($D11>0,FLOOR($D11/18,1),0)+IF(AND(MOD($D11,18)>=T$2,$D11>0),1,0)-IF(T$2-18>$D11,1,0) -> 0 | U10: =IF($D11>0,FLOOR($D11/18,1),0)+IF(AND(MOD($D11,18)>=U$2,$D11>0),1,0)-IF(U$2-18>$D11,1,0) -> 0 | V10: =IF($D11>0,FLOOR($D11/18,1),0)+IF(AND(MOD($D11,18)>=V$2,$D11>0),1,0)-IF(V$2-18>$D11,1,0) -> 1 | W10: =IF($D11>0,FLOOR($D11/18,1),0)+IF(AND(MOD($D11,18)>=W$2,$D11>0),1,0)-IF(W$2-18>$D11,1,0) -> 1 | X10: =IF($D11>0,FLOOR($D11/18,1),0)+IF(AND(MOD($D11,18)>=X$2,$D11>0),1,0)-IF(X$2-18>$D11,1,0) -> 0 | Y10: =IF($D11>0,FLOOR($D11/18,1),0)+IF(AND(MOD($D11,18)>=Y$2,$D11>0),1,0)-IF(Y$2-18>$D11,1,0) -> 1
A11: ='Match Selection'!D5 -> Joe O | B11: =vlookup(A11, 'Master Input'!$A$11:$B$27, 2, false) -> Drivers | C11: =vlookup(A11,'Master Input'!$A$11:$L$27,'Master Input'!$F$28, false) -> 17 | D11: =C11-SMALL($C$8:$C$17,1) -> 8 | E11: 7 | F11: 6 | G11: 4 | H11: 6 | I11: 7 | J11: 7 | K11: 5 | L11: 6 | M11: 6 | N11: =if(M11="","", sum(E11:M11)) -> 54 | P11: =A11 -> Joe O | Q11: 5 | R11: 6 | S11: 5 | T11: 5 | U11: 5 | V11: 4 | W11: 11 | X11: 5 | Y11: 8 | Z11: =if(Y11="","", sum(Q11:Y11)) -> 54 | AA11: =if(Z11="", "", sum(N11,Z11)) -> 108 | AB11: =if(Y11="", "", AA11-C11) -> 91
E12: =if(E13=1,"O", if(E13=2,"O O","")) | F12: =if(F13=1,"O", if(F13=2,"O O","")) | G12: =if(G13=1,"O", if(G13=2,"O O","")) | H12: =if(H13=1,"O", if(H13=2,"O O","")) | I12: =if(I13=1,"O", if(I13=2,"O O","")) | J12: =if(J13=1,"O", if(J13=2,"O O","")) | K12: =if(K13=1,"O", if(K13=2,"O O","")) | L12: =if(L13=1,"O", if(L13=2,"O O","")) | M12: =if(M13=1,"O", if(M13=2,"O O","")) | Q12: =if(Q13=1,"O", if(Q13=2,"O O","")) | R12: =if(R13=1,"O", if(R13=2,"O O","")) | S12: =if(S13=1,"O", if(S13=2,"O O","")) | T12: =if(T13=1,"O", if(T13=2,"O O","")) | U12: =if(U13=1,"O", if(U13=2,"O O","")) | V12: =if(V13=1,"O", if(V13=2,"O O","")) | W12: =if(W13=1,"O", if(W13=2,"O O","")) | X12: =if(X13=1,"O", if(X13=2,"O O","")) | Y12: =if(Y13=1,"O", if(Y13=2,"O O",""))
E13: =IF($D14>0,FLOOR($D14/18,1),0)+IF(AND(MOD($D14,18)>=E$2,$D14>0),1,0)-IF(E$2-18>$D14,1,0) -> 0 | F13: =IF($D14>0,FLOOR($D14/18,1),0)+IF(AND(MOD($D14,18)>=F$2,$D14>0),1,0)-IF(F$2-18>$D14,1,0) -> 0 | G13: =IF($D14>0,FLOOR($D14/18,1),0)+IF(AND(MOD($D14,18)>=G$2,$D14>0),1,0)-IF(G$2-18>$D14,1,0) -> 0 | H13: =IF($D14>0,FLOOR($D14/18,1),0)+IF(AND(MOD($D14,18)>=H$2,$D14>0),1,0)-IF(H$2-18>$D14,1,0) -> 0 | I13: =IF($D14>0,FLOOR($D14/18,1),0)+IF(AND(MOD($D14,18)>=I$2,$D14>0),1,0)-IF(I$2-18>$D14,1,0) -> 0 | J13: =IF($D14>0,FLOOR($D14/18,1),0)+IF(AND(MOD($D14,18)>=J$2,$D14>0),1,0)-IF(J$2-18>$D14,1,0) -> 0 | K13: =IF($D14>0,FLOOR($D14/18,1),0)+IF(AND(MOD($D14,18)>=K$2,$D14>0),1,0)-IF(K$2-18>$D14,1,0) -> 0 | L13: =IF($D14>0,FLOOR($D14/18,1),0)+IF(AND(MOD($D14,18)>=L$2,$D14>0),1,0)-IF(L$2-18>$D14,1,0) -> 0 | M13: =IF($D14>0,FLOOR($D14/18,1),0)+IF(AND(MOD($D14,18)>=M$2,$D14>0),1,0)-IF(M$2-18>$D14,1,0) -> 0 | Q13: =IF($D14>0,FLOOR($D14/18,1),0)+IF(AND(MOD($D14,18)>=Q$2,$D14>0),1,0)-IF(Q$2-18>$D14,1,0) -> 0 | R13: =IF($D14>0,FLOOR($D14/18,1),0)+IF(AND(MOD($D14,18)>=R$2,$D14>0),1,0)-IF(R$2-18>$D14,1,0) -> 0 | S13: =IF($D14>0,FLOOR($D14/18,1),0)+IF(AND(MOD($D14,18)>=S$2,$D14>0),1,0)-IF(S$2-18>$D14,1,0) -> 0 | T13: =IF($D14>0,FLOOR($D14/18,1),0)+IF(AND(MOD($D14,18)>=T$2,$D14>0),1,0)-IF(T$2-18>$D14,1,0) -> 0 | U13: =IF($D14>0,FLOOR($D14/18,1),0)+IF(AND(MOD($D14,18)>=U$2,$D14>0),1,0)-IF(U$2-18>$D14,1,0) -> 0 | V13: =IF($D14>0,FLOOR($D14/18,1),0)+IF(AND(MOD($D14,18)>=V$2,$D14>0),1,0)-IF(V$2-18>$D14,1,0) -> 0 | W13: =IF($D14>0,FLOOR($D14/18,1),0)+IF(AND(MOD($D14,18)>=W$2,$D14>0),1,0)-IF(W$2-18>$D14,1,0) -> 0 | X13: =IF($D14>0,FLOOR($D14/18,1),0)+IF(AND(MOD($D14,18)>=X$2,$D14>0),1,0)-IF(X$2-18>$D14,1,0) -> 0 | Y13: =IF($D14>0,FLOOR($D14/18,1),0)+IF(AND(MOD($D14,18)>=Y$2,$D14>0),1,0)-IF(Y$2-18>$D14,1,0) -> 0
A14: ='Match Selection'!G4 -> CuzNick | B14: =vlookup(A14, 'Master Input'!$A$11:$B$27, 2, false) -> Irons | C14: =vlookup(A14,'Master Input'!$A$11:$L$27,'Master Input'!$F$28, false) -> 9 | D14: =C14-SMALL($C$8:$C$17,1) -> 0 | E14: 5 | F14: 5 | G14: 3 | H14: 4 | I14: 4 | J14: 5 | K14: 4 | L14: 3 | M14: 5 | N14: =if(M14="","", sum(E14:M14)) -> 38 | P14: =A14 -> CuzNick | Q14: 4 | R14: 6 | S14: 4 | T14: 3 | U14: 5 | V14: 5 | W14: 4 | X14: 4 | Y14: 5 | Z14: =if(Y14="","", sum(Q14:Y14)) -> 40 | AA14: =if(Z14="", "", sum(N14,Z14)) -> 78 | AB14: =if(Y14="", "", AA14-C14) -> 69
E15: =if(E16=1,"O", if(E16=2,"O O","")) -> O O | F15: =if(F16=1,"O", if(F16=2,"O O","")) -> O O | G15: =if(G16=1,"O", if(G16=2,"O O","")) -> O | H15: =if(H16=1,"O", if(H16=2,"O O","")) -> O | I15: =if(I16=1,"O", if(I16=2,"O O","")) -> O O | J15: =if(J16=1,"O", if(J16=2,"O O","")) -> O | K15: =if(K16=1,"O", if(K16=2,"O O","")) -> O | L15: =if(L16=1,"O", if(L16=2,"O O","")) -> O O | M15: =if(M16=1,"O", if(M16=2,"O O","")) -> O | Q15: =if(Q16=1,"O", if(Q16=2,"O O","")) -> O | R15: =if(R16=1,"O", if(R16=2,"O O","")) -> O O | S15: =if(S16=1,"O", if(S16=2,"O O","")) -> O O | T15: =if(T16=1,"O", if(T16=2,"O O","")) -> O | U15: =if(U16=1,"O", if(U16=2,"O O","")) -> O | V15: =if(V16=1,"O", if(V16=2,"O O","")) -> O O | W15: =if(W16=1,"O", if(W16=2,"O O","")) -> O O | X15: =if(X16=1,"O", if(X16=2,"O O","")) -> O | Y15: =if(Y16=1,"O", if(Y16=2,"O O","")) -> O O
E16: =IF($D17>0,FLOOR($D17/18,1),0)+IF(AND(MOD($D17,18)>=E$2,$D17>0),1,0)-IF(E$2-18>$D17,1,0) -> 2 | F16: =IF($D17>0,FLOOR($D17/18,1),0)+IF(AND(MOD($D17,18)>=F$2,$D17>0),1,0)-IF(F$2-18>$D17,1,0) -> 2 | G16: =IF($D17>0,FLOOR($D17/18,1),0)+IF(AND(MOD($D17,18)>=G$2,$D17>0),1,0)-IF(G$2-18>$D17,1,0) -> 1 | H16: =IF($D17>0,FLOOR($D17/18,1),0)+IF(AND(MOD($D17,18)>=H$2,$D17>0),1,0)-IF(H$2-18>$D17,1,0) -> 1 | I16: =IF($D17>0,FLOOR($D17/18,1),0)+IF(AND(MOD($D17,18)>=I$2,$D17>0),1,0)-IF(I$2-18>$D17,1,0) -> 2 | J16: =IF($D17>0,FLOOR($D17/18,1),0)+IF(AND(MOD($D17,18)>=J$2,$D17>0),1,0)-IF(J$2-18>$D17,1,0) -> 1 | K16: =IF($D17>0,FLOOR($D17/18,1),0)+IF(AND(MOD($D17,18)>=K$2,$D17>0),1,0)-IF(K$2-18>$D17,1,0) -> 1 | L16: =IF($D17>0,FLOOR($D17/18,1),0)+IF(AND(MOD($D17,18)>=L$2,$D17>0),1,0)-IF(L$2-18>$D17,1,0) -> 2 | M16: =IF($D17>0,FLOOR($D17/18,1),0)+IF(AND(MOD($D17,18)>=M$2,$D17>0),1,0)-IF(M$2-18>$D17,1,0) -> 1 | Q16: =IF($D17>0,FLOOR($D17/18,1),0)+IF(AND(MOD($D17,18)>=Q$2,$D17>0),1,0)-IF(Q$2-18>$D17,1,0) -> 1 | R16: =IF($D17>0,FLOOR($D17/18,1),0)+IF(AND(MOD($D17,18)>=R$2,$D17>0),1,0)-IF(R$2-18>$D17,1,0) -> 2 | S16: =IF($D17>0,FLOOR($D17/18,1),0)+IF(AND(MOD($D17,18)>=S$2,$D17>0),1,0)-IF(S$2-18>$D17,1,0) -> 2 | T16: =IF($D17>0,FLOOR($D17/18,1),0)+IF(AND(MOD($D17,18)>=T$2,$D17>0),1,0)-IF(T$2-18>$D17,1,0) -> 1 | U16: =IF($D17>0,FLOOR($D17/18,1),0)+IF(AND(MOD($D17,18)>=U$2,$D17>0),1,0)-IF(U$2-18>$D17,1,0) -> 1 | V16: =IF($D17>0,FLOOR($D17/18,1),0)+IF(AND(MOD($D17,18)>=V$2,$D17>0),1,0)-IF(V$2-18>$D17,1,0) -> 2 | W16: =IF($D17>0,FLOOR($D17/18,1),0)+IF(AND(MOD($D17,18)>=W$2,$D17>0),1,0)-IF(W$2-18>$D17,1,0) -> 2 | X16: =IF($D17>0,FLOOR($D17/18,1),0)+IF(AND(MOD($D17,18)>=X$2,$D17>0),1,0)-IF(X$2-18>$D17,1,0) -> 1 | Y16: =IF($D17>0,FLOOR($D17/18,1),0)+IF(AND(MOD($D17,18)>=Y$2,$D17>0),1,0)-IF(Y$2-18>$D17,1,0) -> 2
A17: ='Match Selection'!G5 -> Saugy | B17: =vlookup(A17, 'Master Input'!$A$11:$B$27, 2, false) -> Irons | C17: =vlookup(A17,'Master Input'!$A$11:$L$27,'Master Input'!$F$28, false) -> 36 | D17: =C17-SMALL($C$8:$C$17,1) -> 27 | E17: 7 | F17: 6 | G17: 3 | H17: 10 | I17: 7 | J17: 5 | K17: 4 | L17: 6 | M17: 6 | N17: =if(M17="","", sum(E17:M17)) -> 54 | P17: =A17 -> Saugy | Q17: 5 | R17: 6 | S17: 6 | T17: 4 | U17: 6 | V17: 9 | W17: 9 | X17: 3 | Y17: 9 | Z17: =if(Y17="","", sum(Q17:Y17)) -> 57 | AA17: =if(Z17="", "", sum(N17,Z17)) -> 111 | AB17: =if(Y17="", "", AA17-C17) -> 75
N18: Front | AB18: Cup Pts
A19: =B8&" Status" -> Drivers Status | B19: Match - Front | E19: =if(E23="","",E23) -> -1 | F19: =if(F23="","",F23+E19) -> -2 | G19: =if(G23="","",G23+F19) -> -3 | H19: =if(H23="","",H23+G19) -> -4 | I19: =if(I23="","",I23+H19) -> -3 | J19: =if(J23="","",J23+I19) -> -4 | K19: =if(K23="","",K23+J19) -> -5 | L19: =if(L23="","",L23+K19) -> -6 | M19: =if(M23="","",M23+L19) -> -7 | N19: =if(M19="", "", if(M19<0, 0, if(M19>0, vlookup($B$2,'Master Input'!$O$12:$R$23,'Master Input'!P$11,false), vlookup($B$2,'Master Input'!$O$12:$R$23,'Master Input'!P$11,false)*0.5))) -> 0 | P19: Match - Overall | Q19: =if(Q23="","",Q23+M19) -> -7 | R19: =if(R23="","",R23+Q19) -> -7 | S19: =if(S23="","",S23+R19) -> -7 | T19: =if(T23="","",T23+S19) -> -8 | U19: =if(U23="","",U23+T19) -> -8 | V19: =if(V23="","",V23+U19) -> -7 | W19: =if(W23="","",W23+V19) -> -8 | X19: =if(X23="","",X23+W19) -> -9 | Y19: =if(Y23="","",Y23+X19) -> -8 | Z19: =if(Y19="", "", if(Y19<0, 0, if(Y19>0, vlookup($B$2,'Master Input'!$O$12:$R$23,'Master Input'!R$11,false), vlookup($B$2,'Master Input'!$O$12:$R$23,'Master Input'!R$11,false)*0.5))) -> 0 | AA19: Overall | AB19: =if(Z19="","", sum(N19,Z19,Z20)) -> 0
P20: Match - Back | Q20: =if(Q23="","",Q23) -> 0 | R20: =if(R23="","",R23+Q20) -> 0 | S20: =if(S23="","",S23+R20) -> 0 | T20: =if(T23="","",T23+S20) -> -1 | U20: =if(U23="","",U23+T20) -> -1 | V20: =if(V23="","",V23+U20) -> 0 | W20: =if(W23="","",W23+V20) -> -1 | X20: =if(X23="","",X23+W20) -> -2 | Y20: =if(Y23="","",Y23+X20) -> -1 | Z20: =if(Y20="", "", if(Y20<0, 0, if(Y20>0, vlookup($B$2,'Master Input'!$O$12:$R$23,'Master Input'!Q$11,false), vlookup($B$2,'Master Input'!$O$12:$R$23,'Master Input'!Q$11,false)*0.5))) -> 0 | AA20: Back | AB20: =if(AB19="","",vlookup($B$2,'Master Input'!$O$12:$R$23,2,false)+vlookup($B$2,'Master Input'!$O$12:$R$23,3,false)+vlookup($B$2,'Master Input'!$O$12:$R$23,4,false)-AB19) -> 4
B22: 1 | C22: 2 | D22: 3 | E22: 4 | F22: 5 | G22: 6 | H22: 7 | I22: 8 | J22: 9 | K22: 10 | L22: 11 | M22: 12 | N22: 13 | O22: 14 | P22: 15 | Q22: 16 | R22: 17 | S22: 18 | T22: 19 | U22: 20 | V22: 21 | W22: 22 | X22: 23 | Y22: 24 | Z22: Hole | AA22: Holes | AB22: Point
B23: Match | E23: =if(OR(E8="", E11="", E14="", E17=""), "", if(small({E8-E7,E11-E10},1)<small({E14-E13,E17-E16},1),1, if(small({E8-E7,E11-E10},1)>small({E14-E13,E17-E16},1),-1, 0))) -> -1 | F23: =if(OR(F8="", F11="", F14="", F17=""), "", if(small({F8-F7,F11-F10},1)<small({F14-F13,F17-F16},1),1, if(small({F8-F7,F11-F10},1)>small({F14-F13,F17-F16},1),-1, 0))) -> -1 | G23: =if(OR(G8="", G11="", G14="", G17=""), "", if(small({G8-G7,G11-G10},1)<small({G14-G13,G17-G16},1),1, if(small({G8-G7,G11-G10},1)>small({G14-G13,G17-G16},1),-1, 0))) -> -1 | H23: =if(OR(H8="", H11="", H14="", H17=""), "", if(small({H8-H7,H11-H10},1)<small({H14-H13,H17-H16},1),1, if(small({H8-H7,H11-H10},1)>small({H14-H13,H17-H16},1),-1, 0))) -> -1 | I23: =if(OR(I8="", I11="", I14="", I17=""), "", if(small({I8-I7,I11-I10},1)<small({I14-I13,I17-I16},1),1, if(small({I8-I7,I11-I10},1)>small({I14-I13,I17-I16},1),-1, 0))) -> 1 | J23: =if(OR(J8="", J11="", J14="", J17=""), "", if(small({J8-J7,J11-J10},1)<small({J14-J13,J17-J16},1),1, if(small({J8-J7,J11-J10},1)>small({J14-J13,J17-J16},1),-1, 0))) -> -1 | K23: =if(OR(K8="", K11="", K14="", K17=""), "", if(small({K8-K7,K11-K10},1)<small({K14-K13,K17-K16},1),1, if(small({K8-K7,K11-K10},1)>small({K14-K13,K17-K16},1),-1, 0))) -> -1 | L23: =if(OR(L8="", L11="", L14="", L17=""), "", if(small({L8-L7,L11-L10},1)<small({L14-L13,L17-L16},1),1, if(small({L8-L7,L11-L10},1)>small({L14-L13,L17-L16},1),-1, 0))) -> -1 | M23: =if(OR(M8="", M11="", M14="", M17=""), "", if(small({M8-M7,M11-M10},1)<small({M14-M13,M17-M16},1),1, if(small({M8-M7,M11-M10},1)>small({M14-M13,M17-M16},1),-1, 0))) -> -1 | Q23: =if(OR(Q8="", Q11="", Q14="", Q17=""), "", if(small({Q8-Q7,Q11-Q10},1)<small({Q14-Q13,Q17-Q16},1),1, if(small({Q8-Q7,Q11-Q10},1)>small({Q14-Q13,Q17-Q16},1),-1, 0))) -> 0 | R23: =if(OR(R8="", R11="", R14="", R17=""), "", if(small({R8-R7,R11-R10},1)<small({R14-R13,R17-R16},1),1, if(small({R8-R7,R11-R10},1)>small({R14-R13,R17-R16},1),-1, 0))) -> 0 | S23: =if(OR(S8="", S11="", S14="", S17=""), "", if(small({S8-S7,S11-S10},1)<small({S14-S13,S17-S16},1),1, if(small({S8-S7,S11-S10},1)>small({S14-S13,S17-S16},1),-1, 0))) -> 0 | T23: =if(OR(T8="", T11="", T14="", T17=""), "", if(small({T8-T7,T11-T10},1)<small({T14-T13,T17-T16},1),1, if(small({T8-T7,T11-T10},1)>small({T14-T13,T17-T16},1),-1, 0))) -> -1 | U23: =if(OR(U8="", U11="", U14="", U17=""), "", if(small({U8-U7,U11-U10},1)<small({U14-U13,U17-U16},1),1, if(small({U8-U7,U11-U10},1)>small({U14-U13,U17-U16},1),-1, 0))) -> 0 | V23: =if(OR(V8="", V11="", V14="", V17=""), "", if(small({V8-V7,V11-V10},1)<small({V14-V13,V17-V16},1),1, if(small({V8-V7,V11-V10},1)>small({V14-V13,V17-V16},1),-1, 0))) -> 1 | W23: =if(OR(W8="", W11="", W14="", W17=""), "", if(small({W8-W7,W11-W10},1)<small({W14-W13,W17-W16},1),1, if(small({W8-W7,W11-W10},1)>small({W14-W13,W17-W16},1),-1, 0))) -> -1 | X23: =if(OR(X8="", X11="", X14="", X17=""), "", if(small({X8-X7,X11-X10},1)<small({X14-X13,X17-X16},1),1, if(small({X8-X7,X11-X10},1)>small({X14-X13,X17-X16},1),-1, 0))) -> -1 | Y23: =if(OR(Y8="", Y11="", Y14="", Y17=""), "", if(small({Y8-Y7,Y11-Y10},1)<small({Y14-Y13,Y17-Y16},1),1, if(small({Y8-Y7,Y11-Y10},1)>small({Y14-Y13,Y17-Y16},1),-1, 0))) -> 1 | Z23: Contr | AA23: Won | AB23: Share
B24: =B8 -> Drivers | E24: =if(E23="","",(E23+1)/2) -> 0 | F24: =if(F23="","",(F23+1)/2) -> 0 | G24: =if(G23="","",(G23+1)/2) -> 0 | H24: =if(H23="","",(H23+1)/2) -> 0 | I24: =if(I23="","",(I23+1)/2) -> 1 | J24: =if(J23="","",(J23+1)/2) -> 0 | K24: =if(K23="","",(K23+1)/2) -> 0 | L24: =if(L23="","",(L23+1)/2) -> 0 | M24: =if(M23="","",(M23+1)/2) -> 0 | N24: =if(M23="","",sum(E24:M24)) -> 1 | Q24: =if(Q23="","",(Q23+1)/2) -> 0.5 | R24: =if(R23="","",(R23+1)/2) -> 0.5 | S24: =if(S23="","",(S23+1)/2) -> 0.5 | T24: =if(T23="","",(T23+1)/2) -> 0 | U24: =if(U23="","",(U23+1)/2) -> 0.5 | V24: =if(V23="","",(V23+1)/2) -> 1 | W24: =if(W23="","",(W23+1)/2) -> 0 | X24: =if(X23="","",(X23+1)/2) -> 0 | Y24: =if(Y23="","",(Y23+1)/2) -> 1 | Z24: =if(Y23="","",sum(Q24:Y24)) -> 4 | AA24: =if(Y23="","",sum(Z24,N24)) -> 5
A25: =A8 -> TJSC | E25: =if(E23="","",if(E8-E7<E11-E10,1,if(E8-E7=E11-E10,0.5,0))) -> 0.5 | F25: =if(F23="","",if(F8-F7<F11-F10,1,if(F8-F7=F11-F10,0.5,0))) -> 0.5 | G25: =if(G23="","",if(G8-G7<G11-G10,1,if(G8-G7=G11-G10,0.5,0))) -> 0.5 | H25: =if(H23="","",if(H8-H7<H11-H10,1,if(H8-H7=H11-H10,0.5,0))) -> 0.5 | I25: =if(I23="","",if(I8-I7<I11-I10,1,if(I8-I7=I11-I10,0.5,0))) -> 1 | J25: =if(J23="","",if(J8-J7<J11-J10,1,if(J8-J7=J11-J10,0.5,0))) -> 1 | K25: =if(K23="","",if(K8-K7<K11-K10,1,if(K8-K7=K11-K10,0.5,0))) -> 1 | L25: =if(L23="","",if(L8-L7<L11-L10,1,if(L8-L7=L11-L10,0.5,0))) -> 0.5 | M25: =if(M23="","",if(M8-M7<M11-M10,1,if(M8-M7=M11-M10,0.5,0))) -> 0 | Q25: =if(Q23="","",if(Q8-Q7<Q11-Q10,1,if(Q8-Q7=Q11-Q10,0.5,0))) -> 1 | R25: =if(R23="","",if(R8-R7<R11-R10,1,if(R8-R7=R11-R10,0.5,0))) -> 1 | S25: =if(S23="","",if(S8-S7<S11-S10,1,if(S8-S7=S11-S10,0.5,0))) -> 1 | T25: =if(T23="","",if(T8-T7<T11-T10,1,if(T8-T7=T11-T10,0.5,0))) -> 0.5 | U25: =if(U23="","",if(U8-U7<U11-U10,1,if(U8-U7=U11-U10,0.5,0))) -> 0 | V25: =if(V23="","",if(V8-V7<V11-V10,1,if(V8-V7=V11-V10,0.5,0))) -> 0 | W25: =if(W23="","",if(W8-W7<W11-W10,1,if(W8-W7=W11-W10,0.5,0))) -> 1 | X25: =if(X23="","",if(X8-X7<X11-X10,1,if(X8-X7=X11-X10,0.5,0))) -> 1 | Y25: =if(Y23="","",if(Y8-Y7<Y11-Y10,1,if(Y8-Y7=Y11-Y10,0.5,0))) -> 1 | Z25: =if(Y25="","",sum(E25:M25,Q25:Y25)) -> 12 | AA25: =if(Y25="","",sumproduct({E25:M25,Q25:Y25},{$E$24:$M$24,$Q$24:$Y$24})) -> 3.5 | AB25: =if(Y25="","",if($N$24=0,0,((sumproduct(E25:M25,$E$24:$M$24)/$N$24)*$N$19)) +if($Z$24=0,0,((sumproduct(Q25:Y25,$Q$24:$Y$24)/$Z$24)*$Z$20)) +if($AA$24=0,0,((AA25/$AA$24)*$Z$19))) -> 0
A26: =A11 -> Joe O | E26: =if(E23="","",if(E8-E7>E11-E10,1,if(E8-E7=E11-E10,0.5,0))) -> 0.5 | F26: =if(F23="","",if(F8-F7>F11-F10,1,if(F8-F7=F11-F10,0.5,0))) -> 0.5 | G26: =if(G23="","",if(G8-G7>G11-G10,1,if(G8-G7=G11-G10,0.5,0))) -> 0.5 | H26: =if(H23="","",if(H8-H7>H11-H10,1,if(H8-H7=H11-H10,0.5,0))) -> 0.5 | I26: =if(I23="","",if(I8-I7>I11-I10,1,if(I8-I7=I11-I10,0.5,0))) -> 0 | J26: =if(J23="","",if(J8-J7>J11-J10,1,if(J8-J7=J11-J10,0.5,0))) -> 0 | K26: =if(K23="","",if(K8-K7>K11-K10,1,if(K8-K7=K11-K10,0.5,0))) -> 0 | L26: =if(L23="","",if(L8-L7>L11-L10,1,if(L8-L7=L11-L10,0.5,0))) -> 0.5 | M26: =if(M23="","",if(M8-M7>M11-M10,1,if(M8-M7=M11-M10,0.5,0))) -> 1 | Q26: =if(Q23="","",if(Q8-Q7>Q11-Q10,1,if(Q8-Q7=Q11-Q10,0.5,0))) -> 0 | R26: =if(R23="","",if(R8-R7>R11-R10,1,if(R8-R7=R11-R10,0.5,0))) -> 0 | S26: =if(S23="","",if(S8-S7>S11-S10,1,if(S8-S7=S11-S10,0.5,0))) -> 0 | T26: =if(T23="","",if(T8-T7>T11-T10,1,if(T8-T7=T11-T10,0.5,0))) -> 0.5 | U26: =if(U23="","",if(U8-U7>U11-U10,1,if(U8-U7=U11-U10,0.5,0))) -> 1 | V26: =if(V23="","",if(V8-V7>V11-V10,1,if(V8-V7=V11-V10,0.5,0))) -> 1 | W26: =if(W23="","",if(W8-W7>W11-W10,1,if(W8-W7=W11-W10,0.5,0))) -> 0 | X26: =if(X23="","",if(X8-X7>X11-X10,1,if(X8-X7=X11-X10,0.5,0))) -> 0 | Y26: =if(Y23="","",if(Y8-Y7>Y11-Y10,1,if(Y8-Y7=Y11-Y10,0.5,0))) -> 0 | Z26: =if(Y26="","",sum(E26:M26,Q26:Y26)) -> 6 | AA26: =if(Y26="","",sumproduct({E26:M26,Q26:Y26},{$E$24:$M$24,$Q$24:$Y$24})) -> 1.5 | AB26: =if(Y26="","",if($N$24=0,0,((sumproduct(E26:M26,$E$24:$M$24)/$N$24)*$N$19)) +if($Z$24=0,0,((sumproduct(Q26:Y26,$Q$24:$Y$24)/$Z$24)*$Z$20)) +if($AA$24=0,0,((AA26/$AA$24)*$Z$19))) -> 0
B27: =B14 -> Irons | E27: =if(E23="","",(1-E23)/2) -> 1 | F27: =if(F23="","",(1-F23)/2) -> 1 | G27: =if(G23="","",(1-G23)/2) -> 1 | H27: =if(H23="","",(1-H23)/2) -> 1 | I27: =if(I23="","",(1-I23)/2) -> 0 | J27: =if(J23="","",(1-J23)/2) -> 1 | K27: =if(K23="","",(1-K23)/2) -> 1 | L27: =if(L23="","",(1-L23)/2) -> 1 | M27: =if(M23="","",(1-M23)/2) -> 1 | N27: =if(M26="","",sum(E27:M27)) -> 8 | Q27: =if(Q23="","",(1-Q23)/2) -> 0.5 | R27: =if(R23="","",(1-R23)/2) -> 0.5 | S27: =if(S23="","",(1-S23)/2) -> 0.5 | T27: =if(T23="","",(1-T23)/2) -> 1 | U27: =if(U23="","",(1-U23)/2) -> 0.5 | V27: =if(V23="","",(1-V23)/2) -> 0 | W27: =if(W23="","",(1-W23)/2) -> 1 | X27: =if(X23="","",(1-X23)/2) -> 1 | Y27: =if(Y23="","",(1-Y23)/2) -> 0 | Z27: =if(Y26="","",sum(Q27:Y27)) -> 5 | AA27: =if(Y26="","",sum(Z27,N27)) -> 13
A28: =A14 -> CuzNick | E28: =if(E23="","",if(E17-E16>E14-E13,1,if(E17-E16=E14-E13,0.5,0))) -> 0.5 | F28: =if(F23="","",if(F17-F16>F14-F13,1,if(F17-F16=F14-F13,0.5,0))) -> 0 | G28: =if(G23="","",if(G17-G16>G14-G13,1,if(G17-G16=G14-G13,0.5,0))) -> 0 | H28: =if(H23="","",if(H17-H16>H14-H13,1,if(H17-H16=H14-H13,0.5,0))) -> 1 | I28: =if(I23="","",if(I17-I16>I14-I13,1,if(I17-I16=I14-I13,0.5,0))) -> 1 | J28: =if(J23="","",if(J17-J16>J14-J13,1,if(J17-J16=J14-J13,0.5,0))) -> 0 | K28: =if(K23="","",if(K17-K16>K14-K13,1,if(K17-K16=K14-K13,0.5,0))) -> 0 | L28: =if(L23="","",if(L17-L16>L14-L13,1,if(L17-L16=L14-L13,0.5,0))) -> 1 | M28: =if(M23="","",if(M17-M16>M14-M13,1,if(M17-M16=M14-M13,0.5,0))) -> 0.5 | Q28: =if(Q23="","",if(Q17-Q16>Q14-Q13,1,if(Q17-Q16=Q14-Q13,0.5,0))) -> 0.5 | R28: =if(R23="","",if(R17-R16>R14-R13,1,if(R17-R16=R14-R13,0.5,0))) -> 0 | S28: =if(S23="","",if(S17-S16>S14-S13,1,if(S17-S16=S14-S13,0.5,0))) -> 0.5 | T28: =if(T23="","",if(T17-T16>T14-T13,1,if(T17-T16=T14-T13,0.5,0))) -> 0.5 | U28: =if(U23="","",if(U17-U16>U14-U13,1,if(U17-U16=U14-U13,0.5,0))) -> 0.5 | V28: =if(V23="","",if(V17-V16>V14-V13,1,if(V17-V16=V14-V13,0.5,0))) -> 1 | W28: =if(W23="","",if(W17-W16>W14-W13,1,if(W17-W16=W14-W13,0.5,0))) -> 1 | X28: =if(X23="","",if(X17-X16>X14-X13,1,if(X17-X16=X14-X13,0.5,0))) -> 0 | Y28: =if(Y23="","",if(Y17-Y16>Y14-Y13,1,if(Y17-Y16=Y14-Y13,0.5,0))) -> 1 | Z28: =if(Y28="","",sum(E28:M28,Q28:Y28)) -> 9 | AA28: =if(Y28="","",sumproduct({E28:M28,Q28:Y28},{$E$27:$M$27,$Q$27:$Y$27})) -> 5.25 | AB28: =if(Y28="","",if($N$27=0,0,((sumproduct(E28:M28,$E$27:$M$27)/$N$27)*(vlookup($B$2,'Master Input'!$O$12:$R$23,'Master Input'!P$11,false)-$N$19))) +if($Z$27=0,0,((sumproduct(Q28:Y28,$Q$27:$Y$27)/$Z$27)*(vlookup($B$2,'Master Input'!$O$12:$R$23,'Master Input'!Q$11,false)-$Z$20))) +if($AA$27=0,0,((AA28/$AA$27)*(vlookup($B$2,'Master Input'!$O$12:$R$23,'Master Input'!R$11,false)-$Z$19)))) -> 1.6326923
