Workbook
Name COURSES: 'Course List'!$A:$A

Sheet SCOREBOARD
A1: 0 | E1: Takes 42 to Win
C2: Master | H2: Weez
C3: =IF(AND(SUM(E10,E14,E18,E22,E29,E33,E37,E41,E45,E49,E53,E57,E64,E68,E72,E76,B81:B98)=41.5,SUM(G10,G14,G18,G22,G29,G33,G37,G41,G45,G49,G53,G57,G64,G68,G72,G76,J81:J98)=41.5), SUM(E10,E14,E18,E22,E29,E33,E37,E41,E45,E49,E53,E57,E64,E68,E72,E76,B81:B98)+C100, SUM(E10,E14,E18,E22,E29,E33,E37,E41,E45,E49,E53,E57,E64,E68,E72,E76,B81:B98)) -> 45.5 | H3: =IF(AND(SUM(E10,E14,E18,E22,E29,E33,E37,E41,E45,E49,E53,E57,E64,E68,E72,E76,B81:B98)=41.5,SUM(G10,G14,G18,G22,G29,G33,G37,G41,G45,G49,G53,G57,G64,G68,G72,G76,J81:J98)=41.5), SUM(G10,G14,G18,G22,G29,G33,G37,G41,G45,G49,G53,G57,G64,G68,G72,G76,J81:J98)+H100, SUM(G10,G14,G18,G22,G29,G33,G37,G41,G45,G49,G53,G57,G64,G68,G72,G76,J81:J98)) -> 37.5
C4: Tees | E4: =IF(AND(C3+H3>83, C3>H3),"<< Tie Breaker", IF(AND(C3+H3>83, C3<H3),"Tie Breaker >>","Pts Avail: "&83-C3-H3)) -> Pts Avail: 0 | H4: Dogs
B6: ='Master Input'!E6 -> Sundance - Blue | G6: ='Master Input'!F6 -> Dirty Dozen
A7: Score Tracking Method: Net Points then BC Points
B8: =IF(F8=0,"",IF(AND(F8<9,VLOOKUP("Match - Front",'R1_G1'!$B$19:$N$19,12-COUNTIF('R1_G1'!$E$19:$M$19,"."))*-1=0),"AS", IF(AND(F8<9,VLOOKUP("Match - Front",'R1_G1'!$B$19:$N$19,12-COUNTIF('R1_G1'!$E$19:$M$19,"."))*-1>0), "+" & VLOOKUP("Match - Front",'R1_G1'!$B$19:$N$19,12-COUNTIF('R1_G1'!$E$19:$M$19,"."))*-1, IF(F8>8,1-'R1_G1'!$N$19, VLOOKUP("Match - Front",'R1_G1'!$B$19:$N$19,12-COUNTIF('R1_G1'!$E$19:$M$19,"."))*-1)))) | C8: =IF(F8<10,"",IF(AND(F8<18,VLOOKUP("Match - Overall",'R1_G1'!$P$19:$Z$19,10-COUNTIF('R1_G1'!$P$19:$Z$19,"."))*-1=0),"AS", IF(AND(F8<18,VLOOKUP("Match - Overall",'R1_G1'!$P$19:$Z$19,10-COUNTIF('R1_G1'!$P$19:$Z$19,"."))*-1>0), "+" & VLOOKUP("Match - Overall",'R1_G1'!$P$19:$Z$19,10-COUNTIF('R1_G1'!$P$19:$Z$19,"."))*-1, IF(F8>17,1-'R1_G1'!$Z$19, VLOOKUP("Match - Overall",'R1_G1'!$P$19:$Z$19,10-COUNTIF('R1_G1'!$P$19:$Z$19,"."))*-1)))) | D8: =IF(F8<10,"",IF(AND(F8<18,VLOOKUP("Match - Back",'R1_G1'!$P$20:$Z$20,10-COUNTIF('R1_G1'!$P$20:$Z$20,"."))*-1=0),"AS", IF(AND(F8<18,VLOOKUP("Match - Back",'R1_G1'!$P$20:$Z$20,10-COUNTIF('R1_G1'!$P$20:$Z$20,"."))*-1>0), "+" & VLOOKUP("Match - Back",'R1_G1'!$P$20:$Z$20,10-COUNTIF('R1_G1'!$P$20:$Z$20,"."))*-1, IF(F8>17,1-'R1_G1'!$Z$20, VLOOKUP("Match - Back",'R1_G1'!$P$20:$Z$20,10-COUNTIF('R1_G1'!$P$20:$Z$20,"."))*-1)))) | E8: =IF(AND(F8>8,F8<18),B8, IF(F8=18,SUM(B8:D8),""))
B9: ='Match Selection'!G4 -> R-Mac | D9: ='Match Selection'!G5 -> House | F9: Thru | G9: ='Match Selection'!D4 -> Elger | I9: ='Match Selection'!D5 -> T-Mo
B10: =IF(F10=0,"", IF(AND(F10<9,'R1_G1'!N20='R1_G1'!N19),"AS", IF(AND(F10<9,'R1_G1'!N20>'R1_G1'!N19),"+"&'R1_G1'!N20-'R1_G1'!N19, IF(AND(F10<9,'R1_G1'!N20<'R1_G1'!N19), 'R1_G1'!N20-'R1_G1'!N19, 1-'R1_G1'!N21 )))) -> 0 | C10: =IF(F10<10,"", IF(AND(F10<18,'R1_G1'!AA20='R1_G1'!AA19),"AS", IF(AND(F10<18,'R1_G1'!AA20>'R1_G1'!AA19),"+"&'R1_G1'!AA20-'R1_G1'!AA19, IF(AND(F10<18,'R1_G1'!AA20<'R1_G1'!AA19), 'R1_G1'!AA20-'R1_G1'!AA19, 2-'R1_G1'!AA21 )))) -> 0 | D10: =IF(F10<10,"", IF(AND(F10<18,'R1_G1'!Z20='R1_G1'!Z19),"AS", IF(AND(F10<18,'R1_G1'!Z20>'R1_G1'!Z19),"+"&'R1_G1'!Z20-'R1_G1'!Z19, IF(AND(F10<18,'R1_G1'!Z20<'R1_G1'!Z19), 'R1_G1'!Z20-'R1_G1'!Z19, 1-'R1_G1'!Z21 )))) -> 1 | E10: =IF(AND(F10>8,F10<18),B10, IF(F10=18,SUM(B10:D10),"")) -> 1 | F10: =21-COUNTIF('R1_G1'!$E$23:$Y$23,"") -> 18 | G10: =IF(AND(F10>8,F10<18),J10, IF(F10=18,SUM(H10:J10),"")) -> 3 | H10: =IF(F10<10,"", IF(AND(F10<18,'R1_G1'!Z20='R1_G1'!Z19),"AS", IF(AND(F10<18,'R1_G1'!Z20<'R1_G1'!Z19),"+"&'R1_G1'!Z19-'R1_G1'!Z20, IF(AND(F10<18,'R1_G1'!Z20>'R1_G1'!Z19), 'R1_G1'!Z19-'R1_G1'!Z20, 'R1_G1'!Z21 )))) -> 0 | I10: =IF(F10<10,"", IF(AND(F10<18,'R1_G1'!AA20='R1_G1'!AA19),"AS", IF(AND(F10<18,'R1_G1'!AA20<'R1_G1'!AA19),"+"&'R1_G1'!AA19-'R1_G1'!AA20, IF(AND(F10<18,'R1_G1'!AA20>'R1_G1'!AA19), 'R1_G1'!AA19-'R1_G1'!AA20, 'R1_G1'!AA21 )))) -> 2 | J10: =IF(F10=0,"", IF(AND(F10<9,'R1_G1'!N20='R1_G1'!N19),"AS", IF(AND(F10<9,'R1_G1'!N20<'R1_G1'!N19),"+"&'R1_G1'!N19-'R1_G1'!N20, IF(AND(F10<9,'R1_G1'!N20>'R1_G1'!N19), 'R1_G1'!N19-'R1_G1'!N20, 'R1_G1'!N21 )))) -> 1
B11: Front | C11: OA | D11: Back | E11: TOT | G11: TOT | H11: Back | I11: OA | J11: Front
B13: ='Match Selection'!M4 -> CuzNick | D13: ='Match Selection'!M5 -> Saugy | F13: Thru | G13: ='Match Selection'!J4 -> Pace | I13: ='Match Selection'!J5 -> Weezy
B14: =IF(F14=0,"", IF(AND(F14<9,'R1_G2'!N20='R1_G2'!N19),"AS", IF(AND(F14<9,'R1_G2'!N20>'R1_G2'!N19),"+"&'R1_G2'!N20-'R1_G2'!N19, IF(AND(F14<9,'R1_G2'!N20<'R1_G2'!N19), 'R1_G2'!N20-'R1_G2'!N19, 1-'R1_G2'!N21 )))) -> 1 | C14: =IF(F14<10,"", IF(AND(F14<18,'R1_G2'!AA20='R1_G2'!AA19),"AS", IF(AND(F14<18,'R1_G2'!AA20>'R1_G2'!AA19),"+"&'R1_G2'!AA20-'R1_G2'!AA19, IF(AND(F14<18,'R1_G2'!AA20<'R1_G2'!AA19), 'R1_G2'!AA20-'R1_G2'!AA19, 2-'R1_G2'!AA21 )))) -> 2 | D14: =IF(F14<10,"", IF(AND(F14<18,'R1_G2'!Z20='R1_G2'!Z19),"AS", IF(AND(F14<18,'R1_G2'!Z20>'R1_G2'!Z19),"+"&'R1_G2'!Z20-'R1_G2'!Z19, IF(AND(F14<18,'R1_G2'!Z20<'R1_G2'!Z19), 'R1_G2'!Z20-'R1_G2'!Z19, 1-'R1_G2'!Z21 )))) -> 0 | E14: =IF(AND(F14>8,F14<18),B14, IF(F14=18,SUM(B14:D14),"")) -> 3 | F14: =21-COUNTIF('R1_G2'!$E$23:$Y$23,"") -> 18 | G14: =IF(AND(F14>8,F14<18),J14, IF(F14=18,SUM(H14:J14),"")) -> 1 | H14: =IF(F14<10,"", IF(AND(F14<18,'R1_G2'!Z20='R1_G2'!Z19),"AS", IF(AND(F14<18,'R1_G2'!Z20<'R1_G2'!Z19),"+"&'R1_G2'!Z19-'R1_G2'!Z20, IF(AND(F14<18,'R1_G2'!Z20>'R1_G2'!Z19), 'R1_G2'!Z19-'R1_G2'!Z20, 'R1_G2'!Z21 )))) -> 1 | I14: =IF(F14<10,"", IF(AND(F14<18,'R1_G2'!AA20='R1_G2'!AA19),"AS", IF(AND(F14<18,'R1_G2'!AA20<'R1_G2'!AA19),"+"&'R1_G2'!AA19-'R1_G2'!AA20, IF(AND(F14<18,'R1_G2'!AA20>'R1_G2'!AA19), 'R1_G2'!AA19-'R1_G2'!AA20, 'R1_G2'!AA21 )))) -> 0 | J14: =IF(F14=0,"", IF(AND(F14<9,'R1_G2'!N20='R1_G2'!N19),"AS", IF(AND(F14<9,'R1_G2'!N20<'R1_G2'!N19),"+"&'R1_G2'!N19-'R1_G2'!N20, IF(AND(F14<9,'R1_G2'!N20>'R1_G2'!N19), 'R1_G2'!N19-'R1_G2'!N20, 'R1_G2'!N21 )))) -> 0
B15: Front | C15: OA | E15: TOT | G15: TOT | H15: Back | I15: OA | J15: Front
B17: ='Match Selection'!S4 -> Telly | D17: ='Match Selection'!S5 -> DK | F17: Thru | G17: ='Match Selection'!P4 -> Andy | I17: ='Match Selection'!P5 -> Joe O
B18: =IF(F18=0,"", IF(AND(F18<9,'R1_G3'!N20='R1_G3'!N19),"AS", IF(AND(F18<9,'R1_G3'!N20>'R1_G3'!N19),"+"&'R1_G3'!N20-'R1_G3'!N19, IF(AND(F18<9,'R1_G3'!N20<'R1_G3'!N19), 'R1_G3'!N20-'R1_G3'!N19, 1-'R1_G3'!N21 )))) -> 1 | C18: =IF(F18<10,"", IF(AND(F18<18,'R1_G3'!AA20='R1_G3'!AA19),"AS", IF(AND(F18<18,'R1_G3'!AA20>'R1_G3'!AA19),"+"&'R1_G3'!AA20-'R1_G3'!AA19, IF(AND(F18<18,'R1_G3'!AA20<'R1_G3'!AA19), 'R1_G3'!AA20-'R1_G3'!AA19, 2-'R1_G3'!AA21 )))) -> 0 | D18: =IF(F18<10,"", IF(AND(F18<18,'R1_G3'!Z20='R1_G3'!Z19),"AS", IF(AND(F18<18,'R1_G3'!Z20>'R1_G3'!Z19),"+"&'R1_G3'!Z20-'R1_G3'!Z19, IF(AND(F18<18,'R1_G3'!Z20<'R1_G3'!Z19), 'R1_G3'!Z20-'R1_G3'!Z19, 1-'R1_G3'!Z21 )))) -> 0 | E18: =IF(AND(F18>8,F18<18),B18, IF(F18=18,SUM(B18:D18),"")) -> 1 | F18: =21-COUNTIF('R1_G3'!$E$23:$Y$23,"") -> 18 | G18: =IF(AND(F18>8,F18<18),J18, IF(F18=18,SUM(H18:J18),"")) -> 3 | H18: =IF(F18<10,"", IF(AND(F18<18,'R1_G3'!Z20='R1_G3'!Z19),"AS", IF(AND(F18<18,'R1_G3'!Z20<'R1_G3'!Z19),"+"&'R1_G3'!Z19-'R1_G3'!Z20, IF(AND(F18<18,'R1_G3'!Z20>'R1_G3'!Z19), 'R1_G3'!Z19-'R1_G3'!Z20, 'R1_G3'!Z21 )))) -> 1 | I18: =IF(F18<10,"", IF(AND(F18<18,'R1_G3'!AA20='R1_G3'!AA19),"AS", IF(AND(F18<18,'R1_G3'!AA20<'R1_G3'!AA19),"+"&'R1_G3'!AA19-'R1_G3'!AA20, IF(AND(F18<18,'R1_G3'!AA20>'R1_G3'!AA19), 'R1_G3'!AA19-'R1_G3'!AA20, 'R1_G3'!AA21 )))) -> 2 | J18: =IF(F18=0,"", IF(AND(F18<9,'R1_G3'!N20='R1_G3'!N19),"AS", IF(AND(F18<9,'R1_G3'!N20<'R1_G3'!N19),"+"&'R1_G3'!N19-'R1_G3'!N20, IF(AND(F18<9,'R1_G3'!N20>'R1_G3'!N19), 'R1_G3'!N19-'R1_G3'!N20, 'R1_G3'!N21 )))) -> 0
B19: Front | C19: OA | D19: Back | E19: TOT | G19: TOT | H19: Back | I19: OA | J19: Front
B21: ='Match Selection'!Y4 -> KJ | D21: ='Match Selection'!Y5 -> TJSC | F21: Thru | G21: ='Match Selection'!V4 -> Jensen | I21: ='Match Selection'!V5 -> Hile
B22: =IF(F22=0,"", IF(AND(F22<9,'R1_G4'!N20='R1_G4'!N19),"AS", IF(AND(F22<9,'R1_G4'!N20>'R1_G4'!N19),"+"&'R1_G4'!N20-'R1_G4'!N19, IF(AND(F22<9,'R1_G4'!N20<'R1_G4'!N19), 'R1_G4'!N20-'R1_G4'!N19, 1-'R1_G4'!N21 )))) -> 0 | C22: =IF(F22<10,"", IF(AND(F22<18,'R1_G4'!AA20='R1_G4'!AA19),"AS", IF(AND(F22<18,'R1_G4'!AA20>'R1_G4'!AA19),"+"&'R1_G4'!AA20-'R1_G4'!AA19, IF(AND(F22<18,'R1_G4'!AA20<'R1_G4'!AA19), 'R1_G4'!AA20-'R1_G4'!AA19, 2-'R1_G4'!AA21 )))) -> 2 | D22: =IF(F22<10,"", IF(AND(F22<18,'R1_G4'!Z20='R1_G4'!Z19),"AS", IF(AND(F22<18,'R1_G4'!Z20>'R1_G4'!Z19),"+"&'R1_G4'!Z20-'R1_G4'!Z19, IF(AND(F22<18,'R1_G4'!Z20<'R1_G4'!Z19), 'R1_G4'!Z20-'R1_G4'!Z19, 1-'R1_G4'!Z21 )))) -> 1 | E22: =IF(AND(F22>8,F22<18),B22, IF(F22=18,SUM(B22:D22),"")) -> 3 | F22: =21-COUNTIF('R1_G4'!$E$23:$Y$23,"") -> 18 | G22: =IF(AND(F22>8,F22<18),J22, IF(F22=18,SUM(H22:J22),"")) -> 1 | H22: =IF(F22<10,"", IF(AND(F22<18,'R1_G4'!Z20='R1_G4'!Z19),"AS", IF(AND(F22<18,'R1_G4'!Z20<'R1_G4'!Z19),"+"&'R1_G4'!Z19-'R1_G4'!Z20, IF(AND(F22<18,'R1_G4'!Z20>'R1_G4'!Z19), 'R1_G4'!Z19-'R1_G4'!Z20, 'R1_G4'!Z21 )))) -> 0 | I22: =IF(F22<10,"", IF(AND(F22<18,'R1_G4'!AA20='R1_G4'!AA19),"AS", IF(AND(F22<18,'R1_G4'!AA20<'R1_G4'!AA19),"+"&'R1_G4'!AA19-'R1_G4'!AA20, IF(AND(F22<18,'R1_G4'!AA20>'R1_G4'!AA19), 'R1_G4'!AA19-'R1_G4'!AA20, 'R1_G4'!AA21 )))) -> 0 | J22: =IF(F22=0,"", IF(AND(F22<9,'R1_G4'!N20='R1_G4'!N19),"AS", IF(AND(F22<9,'R1_G4'!N20<'R1_G4'!N19),"+"&'R1_G4'!N19-'R1_G4'!N20, IF(AND(F22<9,'R1_G4'!N20>'R1_G4'!N19), 'R1_G4'!N19-'R1_G4'!N20, 'R1_G4'!N21 )))) -> 1
B23: Front | C23: OA | D23: Back | E23: TOT | G23: TOT | H23: Back | I23: OA | J23: Front
B25: ='Master Input'!G6 -> The Wolverine - White | G25: ='Master Input'!H6 -> Singles Matches
A26: Score Tracking Method: Match Status then BC Points
B28: ='Match Selection'!G9 -> CuzNick | F28: Thru | G28: ='Match Selection'!D9 -> Jensen
B29: =IF(F29=0,"",IF(AND(F29<9,VLOOKUP("Top - Front",'R2_G1'!$B$19:$N$19,12-COUNTIF('R2_G1'!$E$19:$M$19,"."))*-1=0),"AS", IF(AND(F29<9,VLOOKUP("Top - Front",'R2_G1'!$B$19:$N$19,12-COUNTIF('R2_G1'!$E$19:$M$19,"."))*-1>0), "+" & VLOOKUP("Top - Front",'R2_G1'!$B$19:$N$19,12-COUNTIF('R2_G1'!$E$19:$M$19,"."))*-1, IF(F29>8,VLOOKUP($G$25,'Master Input'!$O$12:$R$23,'Master Input'!$P$11,FALSE)-'R2_G1'!$N$19, VLOOKUP("Top - Front",'R2_G1'!$B$19:$N$19,12-COUNTIF('R2_G1'!$E$19:$M$19,"."))*-1)))) -> 0.5 | C29: =IF(F29<10,"",IF(AND(F29<18,VLOOKUP("Top - Overall",'R2_G1'!$P$19:$Z$19,10-COUNTIF('R2_G1'!$P$19:$Z$19,"."))*-1=0),"AS", IF(AND(F29<18,VLOOKUP("Top - Overall",'R2_G1'!$P$19:$Z$19,10-COUNTIF('R2_G1'!$P$19:$Z$19,"."))*-1>0), "+" & VLOOKUP("Top - Overall",'R2_G1'!$P$19:$Z$19,10-COUNTIF('R2_G1'!$P$19:$Z$19,"."))*-1, IF(F29>17,VLOOKUP($G$25,'Master Input'!$O$12:$R$23,'Master Input'!$R$11,FALSE)-'R2_G1'!$Z$19, VLOOKUP("Top - Overall",'R2_G1'!$P$19:$Z$19,10-COUNTIF('R2_G1'!$P$19:$Z$19,"."))*-1)))) -> 0 | D29: =IF(F29<10,"",IF(AND(F29<18,VLOOKUP("Top - Back",'R2_G1'!$P$20:$Z$20,10-COUNTIF('R2_G1'!$P$20:$Z$20,"."))*-1=0),"AS", IF(AND(F29<18,VLOOKUP("Top - Back",'R2_G1'!$P$20:$Z$20,10-COUNTIF('R2_G1'!$P$20:$Z$20,"."))*-1>0), "+" & VLOOKUP("Top - Back",'R2_G1'!$P$20:$Z$20,10-COUNTIF('R2_G1'!$P$20:$Z$20,"."))*-1, IF(F29>17,VLOOKUP($G$25,'Master Input'!$O$12:$R$23,'Master Input'!$Q$11,FALSE)-'R2_G1'!$Z$20, VLOOKUP("Top - Back",'R2_G1'!$P$20:$Z$20,10-COUNTIF('R2_G1'!$P$20:$Z$20,"."))*-1)))) -> 0 | E29: =IF(AND(F29>8,F29<18),B29, IF(F29=18,SUM(B29:D29),"")) -> 0.5 | F29: =20-COUNTIF('R2_G1'!$E$26:$Y$26,"") -> 18 | G29: =IF(AND(F29>8,F29<18),J29, IF(F29=18,SUM(H29:J29),"")) -> 2.5 | H29: =IF(F29<10,"",IF(AND(F29<18,VLOOKUP("Top - Back",'R2_G1'!$P$20:$Z$20,10-COUNTIF('R2_G1'!$P$20:$Z$20,"."))=0),"AS", IF(AND(F29<18,VLOOKUP("Top - Back",'R2_G1'!$P$20:$Z$20,10-COUNTIF('R2_G1'!$P$20:$Z$20,"."))>0), "+" & VLOOKUP("Top - Back",'R2_G1'!$P$20:$Z$20,10-COUNTIF('R2_G1'!$P$20:$Z$20,".")), IF(F29>17,'R2_G1'!$Z$20, VLOOKUP("Top - Back",'R2_G1'!$P$20:$Z$20,10-COUNTIF('R2_G1'!$P$20:$Z$20,".")))))) -> 1 | I29: =IF(F29<10,"",IF(AND(F29<18,VLOOKUP("Top - Overall",'R2_G1'!$P$19:$Z$19,10-COUNTIF('R2_G1'!$P$19:$Z$19,"."))=0),"AS", IF(AND(F29<18,VLOOKUP("Top - Overall",'R2_G1'!$P$19:$Z$19,10-COUNTIF('R2_G1'!$P$19:$Z$19,"."))>0), "+" & VLOOKUP("Top - Overall",'R2_G1'!$P$19:$Z$19,10-COUNTIF('R2_G1'!$P$19:$Z$19,".")), IF(F29>17,'R2_G1'!$Z$19, VLOOKUP("Top - Overall",'R2_G1'!$P$19:$Z$19,10-COUNTIF('R2_G1'!$P$19:$Z$19,".")))))) -> 1 | J29: =IF(F29=0,"",IF(AND(F29<9,VLOOKUP("Top - Front",'R2_G1'!$B$19:$N$19,12-COUNTIF('R2_G1'!$E$19:$M$19,"."))=0),"AS", IF(AND(F29<9,VLOOKUP("Top - Front",'R2_G1'!$B$19:$N$19,12-COUNTIF('R2_G1'!$E$19:$M$19,"."))>0), "+" & VLOOKUP("Top - Front",'R2_G1'!$B$19:$N$19,12-COUNTIF('R2_G1'!$E$19:$M$19,".")), IF(F29>8,'R2_G1'!$N$19, VLOOKUP("Top - Front",'R2_G1'!$B$19:$N$19,12-COUNTIF('R2_G1'!$E$19:$M$19,".")))))) -> 0.5
B30: Front | C30: OA | D30: Back | E30: TOT | G30: TOT | H30: Back | I30: OA | J30: Front
B32: ='Match Selection'!G10 -> House | F32: Thru | G32: ='Match Selection'!D10 -> Elger
B33: =IF(F33=0,"",IF(AND(F33<9,VLOOKUP("Top - Front",'R2_G1'!$B$21:$N$21,12-COUNTIF('R2_G1'!$E$21:$M$21,"."))*-1=0),"AS", IF(AND(F33<9,VLOOKUP("Top - Front",'R2_G1'!$B$21:$N$21,12-COUNTIF('R2_G1'!$E$21:$M$21,"."))*-1>0), "+" & VLOOKUP("Top - Front",'R2_G1'!$B$21:$N$21,12-COUNTIF('R2_G1'!$E$21:$M$21,"."))*-1, IF(F33>8,VLOOKUP($G$25,'Master Input'!$O$12:$R$23,'Master Input'!$P$11,FALSE)-'R2_G1'!$N$21, VLOOKUP("Top - Front",'R2_G1'!$B$21:$N$21,12-COUNTIF('R2_G1'!$E$21:$M$21,"."))*-1)))) -> 1 | C33: =IF(F33<10,"",IF(AND(F33<18,VLOOKUP("Top - Overall",'R2_G1'!$P$21:$Z$21,10-COUNTIF('R2_G1'!$P$21:$Z$21,"."))*-1=0),"AS", IF(AND(F33<18,VLOOKUP("Top - Overall",'R2_G1'!$P$21:$Z$21,10-COUNTIF('R2_G1'!$P$21:$Z$21,"."))*-1>0), "+" & VLOOKUP("Top - Overall",'R2_G1'!$P$21:$Z$21,10-COUNTIF('R2_G1'!$P$21:$Z$21,"."))*-1, IF(F33>17,VLOOKUP($G$25,'Master Input'!$O$12:$R$23,'Master Input'!$R$11,FALSE)-'R2_G1'!$Z$21, VLOOKUP("Top - Overall",'R2_G1'!$P$21:$Z$21,10-COUNTIF('R2_G1'!$P$21:$Z$21,"."))*-1)))) -> 1 | D33: =IF(F33<10,"",IF(AND(F33<18,VLOOKUP("Top - Back",'R2_G1'!$P$22:$Z$22,10-COUNTIF('R2_G1'!$P$22:$Z$22,"."))*-1=0),"AS", IF(AND(F33<18,VLOOKUP("Top - Back",'R2_G1'!$P$22:$Z$22,10-COUNTIF('R2_G1'!$P$22:$Z$22,"."))*-1>0), "+" & VLOOKUP("Top - Back",'R2_G1'!$P$22:$Z$22,10-COUNTIF('R2_G1'!$P$22:$Z$22,"."))*-1, IF(F33>17,VLOOKUP($G$25,'Master Input'!$O$12:$R$23,'Master Input'!$Q$11,FALSE)-'R2_G1'!$Z$22, VLOOKUP("Top - Back",'R2_G1'!$P$22:$Z$22,10-COUNTIF('R2_G1'!$P$22:$Z$22,"."))*-1)))) -> 1 | E33: =IF(AND(F33>8,F33<18),B33, IF(F33=18,SUM(B33:D33),"")) -> 3 | F33: =20-COUNTIF('R2_G1'!$E$29:$Y$29,"") -> 18 | G33: =IF(AND(F33>8,F33<18),J33, IF(F33=18,SUM(H33:J33),"")) -> 0 | H33: =IF(F33<10,"",IF(AND(F33<18,VLOOKUP("Top - Back",'R2_G1'!$P$22:$Z$22,10-COUNTIF('R2_G1'!$P$22:$Z$22,"."))=0),"AS", IF(AND(F33<18,VLOOKUP("Top - Back",'R2_G1'!$P$22:$Z$22,10-COUNTIF('R2_G1'!$P$22:$Z$22,"."))>0), "+" & VLOOKUP("Top - Back",'R2_G1'!$P$22:$Z$22,10-COUNTIF('R2_G1'!$P$22:$Z$22,".")), IF(F33>17,'R2_G1'!$Z$22, VLOOKUP("Top - Back",'R2_G1'!$P$22:$Z$22,10-COUNTIF('R2_G1'!$P$22:$Z$22,".")))))) -> 0 | I33: =IF(F33<10,"",IF(AND(F33<18,VLOOKUP("Top - Overall",'R2_G1'!$P$21:$Z$21,10-COUNTIF('R2_G1'!$P$21:$Z$21,"."))=0),"AS", IF(AND(F33<18,VLOOKUP("Top - Overall",'R2_G1'!$P$21:$Z$21,10-COUNTIF('R2_G1'!$P$21:$Z$21,"."))>0), "+" & VLOOKUP("Top - Overall",'R2_G1'!$P$21:$Z$21,10-COUNTIF('R2_G1'!$P$21:$Z$21,".")), IF(F33>17,'R2_G1'!$Z$21, VLOOKUP("Top - Overall",'R2_G1'!$P$21:$Z$21,10-COUNTIF('R2_G1'!$P$21:$Z$21,".")))))) -> 0 | J33: =IF(F33=0,"",IF(AND(F33<9,VLOOKUP("Top - Front",'R2_G1'!$B$21:$N$21,12-COUNTIF('R2_G1'!$E$21:$M$21,"."))=0),"AS", IF(AND(F33<9,VLOOKUP("Top - Front",'R2_G1'!$B$21:$N$21,12-COUNTIF('R2_G1'!$E$21:$M$21,"."))>0), "+" & VLOOKUP("Top - Front",'R2_G1'!$B$21:$N$21,12-COUNTIF('R2_G1'!$E$21:$M$21,".")), IF(F33>8,'R2_G1'!$N$21, VLOOKUP("Top - Front",'R2_G1'!$B$21:$N$21,12-COUNTIF('R2_G1'!$E$21:$M$21,".")))))) -> 0
B34: Front | C34: OA | D34: Back | E34: TOT | G34: TOT | H34: Back | I34: OA | J34: Front
B36: ='Match Selection'!M9 -> KJ | F36: Thru | G36: ='Match Selection'!J9 -> T-Mo
B37: =IF(F37=0,"",IF(AND(F37<9,VLOOKUP("Top - Front",'R2_G2'!$B$19:$N$19,12-COUNTIF('R2_G2'!$E$19:$M$19,"."))*-1=0),"AS", IF(AND(F37<9,VLOOKUP("Top - Front",'R2_G2'!$B$19:$N$19,12-COUNTIF('R2_G2'!$E$19:$M$19,"."))*-1>0), "+" & VLOOKUP("Top - Front",'R2_G2'!$B$19:$N$19,12-COUNTIF('R2_G2'!$E$19:$M$19,"."))*-1, IF(F37>8,VLOOKUP($G$25,'Master Input'!$O$12:$R$23,'Master Input'!$P$11,FALSE)-'R2_G2'!$N$19, VLOOKUP("Top - Front",'R2_G2'!$B$19:$N$19,12-COUNTIF('R2_G2'!$E$19:$M$19,"."))*-1)))) -> 1 | C37: =IF(F37<10,"",IF(AND(F37<18,VLOOKUP("Top - Overall",'R2_G2'!$P$19:$Z$19,10-COUNTIF('R2_G2'!$P$19:$Z$19,"."))*-1=0),"AS", IF(AND(F37<18,VLOOKUP("Top - Overall",'R2_G2'!$P$19:$Z$19,10-COUNTIF('R2_G2'!$P$19:$Z$19,"."))*-1>0), "+" & VLOOKUP("Top - Overall",'R2_G2'!$P$19:$Z$19,10-COUNTIF('R2_G2'!$P$19:$Z$19,"."))*-1, IF(F37>17,VLOOKUP($G$25,'Master Input'!$O$12:$R$23,'Master Input'!$R$11,FALSE)-'R2_G2'!$Z$19, VLOOKUP("Top - Overall",'R2_G2'!$P$19:$Z$19,10-COUNTIF('R2_G2'!$P$19:$Z$19,"."))*-1)))) -> 1 | D37: =IF(F37<10,"",IF(AND(F37<18,VLOOKUP("Top - Back",'R2_G2'!$P$20:$Z$20,10-COUNTIF('R2_G2'!$P$20:$Z$20,"."))*-1=0),"AS", IF(AND(F37<18,VLOOKUP("Top - Back",'R2_G2'!$P$20:$Z$20,10-COUNTIF('R2_G2'!$P$20:$Z$20,"."))*-1>0), "+" & VLOOKUP("Top - Back",'R2_G2'!$P$20:$Z$20,10-COUNTIF('R2_G2'!$P$20:$Z$20,"."))*-1, IF(F37>17,VLOOKUP($G$25,'Master Input'!$O$12:$R$23,'Master Input'!$Q$11,FALSE)-'R2_G2'!$Z$20, VLOOKUP("Top - Back",'R2_G2'!$P$20:$Z$20,10-COUNTIF('R2_G2'!$P$20:$Z$20,"."))*-1)))) -> 1 | E37: =IF(AND(F37>8,F37<18),B37, IF(F37=18,SUM(B37:D37),"")) -> 3 | F37: =20-COUNTIF('R2_G2'!$E$26:$Y$26,"") -> 18 | G37: =IF(AND(F37>8,F37<18),J37, IF(F37=18,SUM(H37:J37),"")) -> 0 | H37: =IF(F37<10,"",IF(AND(F37<18,VLOOKUP("Top - Back",'R2_G2'!$P$20:$Z$20,10-COUNTIF('R2_G2'!$P$20:$Z$20,"."))=0),"AS", IF(AND(F37<18,VLOOKUP("Top - Back",'R2_G2'!$P$20:$Z$20,10-COUNTIF('R2_G2'!$P$20:$Z$20,"."))>0), "+" & VLOOKUP("Top - Back",'R2_G2'!$P$20:$Z$20,10-COUNTIF('R2_G2'!$P$20:$Z$20,".")), IF(F37>17,'R2_G2'!$Z$20, VLOOKUP("Top - Back",'R2_G2'!$P$20:$Z$20,10-COUNTIF('R2_G2'!$P$20:$Z$20,".")))))) -> 0 | I37: =IF(F37<10,"",IF(AND(F37<18,VLOOKUP("Top - Overall",'R2_G2'!$P$19:$Z$19,10-COUNTIF('R2_G2'!$P$19:$Z$19,"."))=0),"AS", IF(AND(F37<18,VLOOKUP("Top - Overall",'R2_G2'!$P$19:$Z$19,10-COUNTIF('R2_G2'!$P$19:$Z$19,"."))>0), "+" & VLOOKUP("Top - Overall",'R2_G2'!$P$19:$Z$19,10-COUNTIF('R2_G2'!$P$19:$Z$19,".")), IF(F37>17,'R2_G2'!$Z$19, VLOOKUP("Top - Overall",'R2_G2'!$P$19:$Z$19,10-COUNTIF('R2_G2'!$P$19:$Z$19,".")))))) -> 0 | J37: =IF(F37=0,"",IF(AND(F37<9,VLOOKUP("Top - Front",'R2_G2'!$B$19:$N$19,12-COUNTIF('R2_G2'!$E$19:$M$19,"."))=0),"AS", IF(AND(F37<9,VLOOKUP("Top - Front",'R2_G2'!$B$19:$N$19,12-COUNTIF('R2_G2'!$E$19:$M$19,"."))>0), "+" & VLOOKUP("Top - Front",'R2_G2'!$B$19:$N$19,12-COUNTIF('R2_G2'!$E$19:$M$19,".")), IF(F37>8,'R2_G2'!$N$19, VLOOKUP("Top - Front",'R2_G2'!$B$19:$N$19,12-COUNTIF('R2_G2'!$E$19:$M$19,".")))))) -> 0
B38: Front | C38: OA | D38: Back | E38: TOT | G38: TOT | H38: Back | I38: OA | J38: Front
B40: ='Match Selection'!M10 -> TJSC | F40: Thru | G40: ='Match Selection'!J10 -> Weezy
B41: =IF(F41=0,"",IF(AND(F41<9,VLOOKUP("Top - Front",'R2_G2'!$B$21:$N$21,12-COUNTIF('R2_G2'!$E$21:$M$21,"."))*-1=0),"AS", IF(AND(F41<9,VLOOKUP("Top - Front",'R2_G2'!$B$21:$N$21,12-COUNTIF('R2_G2'!$E$21:$M$21,"."))*-1>0), "+" & VLOOKUP("Top - Front",'R2_G2'!$B$21:$N$21,12-COUNTIF('R2_G2'!$E$21:$M$21,"."))*-1, IF(F41>8,VLOOKUP($G$25,'Master Input'!$O$12:$R$23,'Master Input'!$P$11,FALSE)-'R2_G2'!$N$21, VLOOKUP("Top - Front",'R2_G2'!$B$21:$N$21,12-COUNTIF('R2_G2'!$E$21:$M$21,"."))*-1)))) -> 0 | C41: =IF(F41<10,"",IF(AND(F41<18,VLOOKUP("Top - Overall",'R2_G2'!$P$21:$Z$21,10-COUNTIF('R2_G2'!$P$21:$Z$21,"."))*-1=0),"AS", IF(AND(F41<18,VLOOKUP("Top - Overall",'R2_G2'!$P$21:$Z$21,10-COUNTIF('R2_G2'!$P$21:$Z$21,"."))*-1>0), "+" & VLOOKUP("Top - Overall",'R2_G2'!$P$21:$Z$21,10-COUNTIF('R2_G2'!$P$21:$Z$21,"."))*-1, IF(F41>17,VLOOKUP($G$25,'Master Input'!$O$12:$R$23,'Master Input'!$R$11,FALSE)-'R2_G2'!$Z$21, VLOOKUP("Top - Overall",'R2_G2'!$P$21:$Z$21,10-COUNTIF('R2_G2'!$P$21:$Z$21,"."))*-1)))) -> 0 | D41: =IF(F41<10,"",IF(AND(F41<18,VLOOKUP("Top - Back",'R2_G2'!$P$22:$Z$22,10-COUNTIF('R2_G2'!$P$22:$Z$22,"."))*-1=0),"AS", IF(AND(F41<18,VLOOKUP("Top - Back",'R2_G2'!$P$22:$Z$22,10-COUNTIF('R2_G2'!$P$22:$Z$22,"."))*-1>0), "+" & VLOOKUP("Top - Back",'R2_G2'!$P$22:$Z$22,10-COUNTIF('R2_G2'!$P$22:$Z$22,"."))*-1, IF(F41>17,VLOOKUP($G$25,'Master Input'!$O$12:$R$23,'Master Input'!$Q$11,FALSE)-'R2_G2'!$Z$22, VLOOKUP("Top - Back",'R2_G2'!$P$22:$Z$22,10-COUNTIF('R2_G2'!$P$22:$Z$22,"."))*-1)))) -> 0 | E41: =IF(AND(F41>8,F41<18),B41, IF(F41=18,SUM(B41:D41),"")) -> 0 | F41: =20-COUNTIF('R2_G2'!$E$29:$Y$29,"") -> 18 | G41: =IF(AND(F41>8,F41<18),J41, IF(F41=18,SUM(H41:J41),"")) -> 3 | H41: =IF(F41<10,"",IF(AND(F41<18,VLOOKUP("Top - Back",'R2_G2'!$P$22:$Z$22,10-COUNTIF('R2_G2'!$P$22:$Z$22,"."))=0),"AS", IF(AND(F41<18,VLOOKUP("Top - Back",'R2_G2'!$P$22:$Z$22,10-COUNTIF('R2_G2'!$P$22:$Z$22,"."))>0), "+" & VLOOKUP("Top - Back",'R2_G2'!$P$22:$Z$22,10-COUNTIF('R2_G2'!$P$22:$Z$22,".")), IF(F41>17,'R2_G2'!$Z$22, VLOOKUP("Top - Back",'R2_G2'!$P$22:$Z$22,10-COUNTIF('R2_G2'!$P$22:$Z$22,".")))))) -> 1 | I41: =IF(F41<10,"",IF(AND(F41<18,VLOOKUP("Top - Overall",'R2_G2'!$P$21:$Z$21,10-COUNTIF('R2_G2'!$P$21:$Z$21,"."))=0),"AS", IF(AND(F41<18,VLOOKUP("Top - Overall",'R2_G2'!$P$21:$Z$21,10-COUNTIF('R2_G2'!$P$21:$Z$21,"."))>0), "+" & VLOOKUP("Top - Overall",'R2_G2'!$P$21:$Z$21,10-COUNTIF('R2_G2'!$P$21:$Z$21,".")), IF(F41>17,'R2_G2'!$Z$21, VLOOKUP("Top - Overall",'R2_G2'!$P$21:$Z$21,10-COUNTIF('R2_G2'!$P$21:$Z$21,".")))))) -> 1 | J41: =IF(F41=0,"",IF(AND(F41<9,VLOOKUP("Top - Front",'R2_G2'!$B$21:$N$21,12-COUNTIF('R2_G2'!$E$21:$M$21,"."))=0),"AS", IF(AND(F41<9,VLOOKUP("Top - Front",'R2_G2'!$B$21:$N$21,12-COUNTIF('R2_G2'!$E$21:$M$21,"."))>0), "+" & VLOOKUP("Top - Front",'R2_G2'!$B$21:$N$21,12-COUNTIF('R2_G2'!$E$21:$M$21,".")), IF(F41>8,'R2_G2'!$N$21, VLOOKUP("Top - Front",'R2_G2'!$B$21:$N$21,12-COUNTIF('R2_G2'!$E$21:$M$21,".")))))) -> 1
B42: Front | C42: OA | D42: Back | E42: TOT | G42: TOT | H42: Back | I42: OA | J42: Front
B44: ='Match Selection'!S9 -> Telly | F44: Thru | G44: ='Match Selection'!P9 -> Pace
B45: =IF(F45=0,"",IF(AND(F45<9,VLOOKUP("Top - Front",'R2_G3'!$B$19:$N$19,12-COUNTIF('R2_G3'!$E$19:$M$19,"."))*-1=0),"AS", IF(AND(F45<9,VLOOKUP("Top - Front",'R2_G3'!$B$19:$N$19,12-COUNTIF('R2_G3'!$E$19:$M$19,"."))*-1>0), "+" & VLOOKUP("Top - Front",'R2_G3'!$B$19:$N$19,12-COUNTIF('R2_G3'!$E$19:$M$19,"."))*-1, IF(F45>8,VLOOKUP($G$25,'Master Input'!$O$12:$R$23,'Master Input'!$P$11,FALSE)-'R2_G3'!$N$19, VLOOKUP("Top - Front",'R2_G3'!$B$19:$N$19,12-COUNTIF('R2_G3'!$E$19:$M$19,"."))*-1)))) -> 1 | C45: =IF(F45<10,"",IF(AND(F45<18,VLOOKUP("Top - Overall",'R2_G3'!$P$19:$Z$19,10-COUNTIF('R2_G3'!$P$19:$Z$19,"."))*-1=0),"AS", IF(AND(F45<18,VLOOKUP("Top - Overall",'R2_G3'!$P$19:$Z$19,10-COUNTIF('R2_G3'!$P$19:$Z$19,"."))*-1>0), "+" & VLOOKUP("Top - Overall",'R2_G3'!$P$19:$Z$19,10-COUNTIF('R2_G3'!$P$19:$Z$19,"."))*-1, IF(F45>17,VLOOKUP($G$25,'Master Input'!$O$12:$R$23,'Master Input'!$R$11,FALSE)-'R2_G3'!$Z$19, VLOOKUP("Top - Overall",'R2_G3'!$P$19:$Z$19,10-COUNTIF('R2_G3'!$P$19:$Z$19,"."))*-1)))) -> 1 | D45: =IF(F45<10,"",IF(AND(F45<18,VLOOKUP("Top - Back",'R2_G3'!$P$20:$Z$20,10-COUNTIF('R2_G3'!$P$20:$Z$20,"."))*-1=0),"AS", IF(AND(F45<18,VLOOKUP("Top - Back",'R2_G3'!$P$20:$Z$20,10-COUNTIF('R2_G3'!$P$20:$Z$20,"."))*-1>0), "+" & VLOOKUP("Top - Back",'R2_G3'!$P$20:$Z$20,10-COUNTIF('R2_G3'!$P$20:$Z$20,"."))*-1, IF(F45>17,VLOOKUP($G$25,'Master Input'!$O$12:$R$23,'Master Input'!$Q$11,FALSE)-'R2_G3'!$Z$20, VLOOKUP("Top - Back",'R2_G3'!$P$20:$Z$20,10-COUNTIF('R2_G3'!$P$20:$Z$20,"."))*-1)))) -> 1 | E45: =IF(AND(F45>8,F45<18),B45, IF(F45=18,SUM(B45:D45),"")) -> 3 | F45: =20-COUNTIF('R2_G3'!$E$26:$Y$26,"") -> 18 | G45: =IF(AND(F45>8,F45<18),J45, IF(F45=18,SUM(H45:J45),"")) -> 0 | H45: =IF(F45<10,"",IF(AND(F45<18,VLOOKUP("Top - Back",'R2_G3'!$P$20:$Z$20,10-COUNTIF('R2_G3'!$P$20:$Z$20,"."))=0),"AS", IF(AND(F45<18,VLOOKUP("Top - Back",'R2_G3'!$P$20:$Z$20,10-COUNTIF('R2_G3'!$P$20:$Z$20,"."))>0), "+" & VLOOKUP("Top - Back",'R2_G3'!$P$20:$Z$20,10-COUNTIF('R2_G3'!$P$20:$Z$20,".")), IF(F45>17,'R2_G3'!$Z$20, VLOOKUP("Top - Back",'R2_G3'!$P$20:$Z$20,10-COUNTIF('R2_G3'!$P$20:$Z$20,".")))))) -> 0 | I45: =IF(F45<10,"",IF(AND(F45<18,VLOOKUP("Top - Overall",'R2_G3'!$P$19:$Z$19,10-COUNTIF('R2_G3'!$P$19:$Z$19,"."))=0),"AS", IF(AND(F45<18,VLOOKUP("Top - Overall",'R2_G3'!$P$19:$Z$19,10-COUNTIF('R2_G3'!$P$19:$Z$19,"."))>0), "+" & VLOOKUP("Top - Overall",'R2_G3'!$P$19:$Z$19,10-COUNTIF('R2_G3'!$P$19:$Z$19,".")), IF(F45>17,'R2_G3'!$Z$19, VLOOKUP("Top - Overall",'R2_G3'!$P$19:$Z$19,10-COUNTIF('R2_G3'!$P$19:$Z$19,".")))))) -> 0 | J45: =IF(F45=0,"",IF(AND(F45<9,VLOOKUP("Top - Front",'R2_G3'!$B$19:$N$19,12-COUNTIF('R2_G3'!$E$19:$M$19,"."))=0),"AS", IF(AND(F45<9,VLOOKUP("Top - Front",'R2_G3'!$B$19:$N$19,12-COUNTIF('R2_G3'!$E$19:$M$19,"."))>0), "+" & VLOOKUP("Top - Front",'R2_G3'!$B$19:$N$19,12-COUNTIF('R2_G3'!$E$19:$M$19,".")), IF(F45>8,'R2_G3'!$N$19, VLOOKUP("Top - Front",'R2_G3'!$B$19:$N$19,12-COUNTIF('R2_G3'!$E$19:$M$19,".")))))) -> 0
B46: Front | C46: OA | D46: Back | E46: TOT | G46: TOT | H46: Back | I46: OA | J46: Front
B48: ='Match Selection'!S10 -> DK | F48: Thru | G48: ='Match Selection'!P10 -> Andy
B49: =IF(F49=0,"",IF(AND(F49<9,VLOOKUP("Top - Front",'R2_G3'!$B$21:$N$21,12-COUNTIF('R2_G3'!$E$21:$M$21,"."))*-1=0),"AS", IF(AND(F49<9,VLOOKUP("Top - Front",'R2_G3'!$B$21:$N$21,12-COUNTIF('R2_G3'!$E$21:$M$21,"."))*-1>0), "+" & VLOOKUP("Top - Front",'R2_G3'!$B$21:$N$21,12-COUNTIF('R2_G3'!$E$21:$M$21,"."))*-1, IF(F49>8,VLOOKUP($G$25,'Master Input'!$O$12:$R$23,'Master Input'!$P$11,FALSE)-'R2_G3'!$N$21, VLOOKUP("Top - Front",'R2_G3'!$B$21:$N$21,12-COUNTIF('R2_G3'!$E$21:$M$21,"."))*-1)))) -> 1 | C49: =IF(F49<10,"",IF(AND(F49<18,VLOOKUP("Top - Overall",'R2_G3'!$P$21:$Z$21,10-COUNTIF('R2_G3'!$P$21:$Z$21,"."))*-1=0),"AS", IF(AND(F49<18,VLOOKUP("Top - Overall",'R2_G3'!$P$21:$Z$21,10-COUNTIF('R2_G3'!$P$21:$Z$21,"."))*-1>0), "+" & VLOOKUP("Top - Overall",'R2_G3'!$P$21:$Z$21,10-COUNTIF('R2_G3'!$P$21:$Z$21,"."))*-1, IF(F49>17,VLOOKUP($G$25,'Master Input'!$O$12:$R$23,'Master Input'!$R$11,FALSE)-'R2_G3'!$Z$21, VLOOKUP("Top - Overall",'R2_G3'!$P$21:$Z$21,10-COUNTIF('R2_G3'!$P$21:$Z$21,"."))*-1)))) -> 1 | D49: =IF(F49<10,"",IF(AND(F49<18,VLOOKUP("Top - Back",'R2_G3'!$P$22:$Z$22,10-COUNTIF('R2_G3'!$P$22:$Z$22,"."))*-1=0),"AS", IF(AND(F49<18,VLOOKUP("Top - Back",'R2_G3'!$P$22:$Z$22,10-COUNTIF('R2_G3'!$P$22:$Z$22,"."))*-1>0), "+" & VLOOKUP("Top - Back",'R2_G3'!$P$22:$Z$22,10-COUNTIF('R2_G3'!$P$22:$Z$22,"."))*-1, IF(F49>17,VLOOKUP($G$25,'Master Input'!$O$12:$R$23,'Master Input'!$Q$11,FALSE)-'R2_G3'!$Z$22, VLOOKUP("Top - Back",'R2_G3'!$P$22:$Z$22,10-COUNTIF('R2_G3'!$P$22:$Z$22,"."))*-1)))) -> 1 | E49: =IF(AND(F49>8,F49<18),B49, IF(F49=18,SUM(B49:D49),"")) -> 3 | F49: =20-COUNTIF('R2_G3'!$E$29:$Y$29,"") -> 18 | G49: =IF(AND(F49>8,F49<18),J49, IF(F49=18,SUM(H49:J49),"")) -> 0 | H49: =IF(F49<10,"",IF(AND(F49<18,VLOOKUP("Top - Back",'R2_G3'!$P$22:$Z$22,10-COUNTIF('R2_G3'!$P$22:$Z$22,"."))=0),"AS", IF(AND(F49<18,VLOOKUP("Top - Back",'R2_G3'!$P$22:$Z$22,10-COUNTIF('R2_G3'!$P$22:$Z$22,"."))>0), "+" & VLOOKUP("Top - Back",'R2_G3'!$P$22:$Z$22,10-COUNTIF('R2_G3'!$P$22:$Z$22,".")), IF(F49>17,'R2_G3'!$Z$22, VLOOKUP("Top - Back",'R2_G3'!$P$22:$Z$22,10-COUNTIF('R2_G3'!$P$22:$Z$22,".")))))) -> 0 | I49: =IF(F49<10,"",IF(AND(F49<18,VLOOKUP("Top - Overall",'R2_G3'!$P$21:$Z$21,10-COUNTIF('R2_G3'!$P$21:$Z$21,"."))=0),"AS", IF(AND(F49<18,VLOOKUP("Top - Overall",'R2_G3'!$P$21:$Z$21,10-COUNTIF('R2_G3'!$P$21:$Z$21,"."))>0), "+" & VLOOKUP("Top - Overall",'R2_G3'!$P$21:$Z$21,10-COUNTIF('R2_G3'!$P$21:$Z$21,".")), IF(F49>17,'R2_G3'!$Z$21, VLOOKUP("Top - Overall",'R2_G3'!$P$21:$Z$21,10-COUNTIF('R2_G3'!$P$21:$Z$21,".")))))) -> 0 | J49: =IF(F49=0,"",IF(AND(F49<9,VLOOKUP("Top - Front",'R2_G3'!$B$21:$N$21,12-COUNTIF('R2_G3'!$E$21:$M$21,"."))=0),"AS", IF(AND(F49<9,VLOOKUP("Top - Front",'R2_G3'!$B$21:$N$21,12-COUNTIF('R2_G3'!$E$21:$M$21,"."))>0), "+" & VLOOKUP("Top - Front",'R2_G3'!$B$21:$N$21,12-COUNTIF('R2_G3'!$E$21:$M$21,".")), IF(F49>8,'R2_G3'!$N$21, VLOOKUP("Top - Front",'R2_G3'!$B$21:$N$21,12-COUNTIF('R2_G3'!$E$21:$M$21,".")))))) -> 0
B50: Front | C50: OA | D50: Back | E50: TOT | G50: TOT | H50: Back | I50: OA | J50: Front
B52: ='Match Selection'!Y9 -> R-Mac | F52: Thru | G52: ='Match Selection'!V9 -> Joe O
...

Sheet R1_G1
A1: Group 1 | B1: ='Master Input'!E3 -> 0.041666667 | C1: ='Master Input'!$E$2 -> Round 1 | E1: ='Master Input'!$E$6 -> Sundance - Blue | P1: ='Master Input'!$E$2&" - "&A1 -> Round 1 - Group 1 | U1: ='Master Input'!$E$6 -> Sundance - Blue
A2: Hole: | B2: ='Match Selection'!B4 -> Dirty Dozen | D2: Hole: | E2: 1 | F2: 2 | G2: 3 | H2: 4 | I2: 5 | J2: 6 | K2: 7 | L2: 8 | M2: 9 | N2: OUT | P2: Hole: | Q2: 10 | R2: 11 | S2: 12 | T2: 13 | U2: 14 | V2: 15 | W2: 16 | X2: 17 | Y2: 18 | Z2: IN | AA2: TOTAL | AB2: NET
A3: Handicap: | D3: Handicap: | E3: =VLOOKUP($E1, 'Course List'!$A$3:$AS$14,5+E2, FALSE) -> 14 | F3: =VLOOKUP($E1, 'Course List'!$A$3:$AS$14,5+F2, FALSE) -> 16 | G3: =VLOOKUP($E1, 'Course List'!$A$3:$AS$14,5+G2, FALSE) -> 11 | H3: =VLOOKUP($E1, 'Course List'!$A$3:$AS$14,5+H2, FALSE) -> 12 | I3: =VLOOKUP($E1, 'Course List'!$A$3:$AS$14,5+I2, FALSE) -> 6 | J3: =VLOOKUP($E1, 'Course List'!$A$3:$AS$14,5+J2, FALSE) -> 8 | K3: =VLOOKUP($E1, 'Course List'!$A$3:$AS$14,5+K2, FALSE) -> 17 | L3: =VLOOKUP($E1, 'Course List'!$A$3:$AS$14,5+L2, FALSE) -> 5 | M3: =VLOOKUP($E1, 'Course List'!$A$3:$AS$14,5+M2, FALSE) -> 2 | P3: Handi: | Q3: =VLOOKUP($E1, 'Course List'!$A$3:$AS$14,5+Q2, FALSE) -> 9 | R3: =VLOOKUP($E1, 'Course List'!$A$3:$AS$14,5+R2, FALSE) -> 13 | S3: =VLOOKUP($E1, 'Course List'!$A$3:$AS$14,5+S2, FALSE) -> 4 | T3: =VLOOKUP($E1, 'Course List'!$A$3:$AS$14,5+T2, FALSE) -> 18 | U3: =VLOOKUP($E1, 'Course List'!$A$3:$AS$14,5+U2, FALSE) -> 7 | V3: =VLOOKUP($E1, 'Course List'!$A$3:$AS$14,5+V2, FALSE) -> 3 | W3: =VLOOKUP($E1, 'Course List'!$A$3:$AS$14,5+W2, FALSE) -> 10 | X3: =VLOOKUP($E1, 'Course List'!$A$3:$AS$14,5+X2, FALSE) -> 15 | Y3: =VLOOKUP($E1, 'Course List'!$A$3:$AS$14,5+Y2, FALSE) -> 1
A4: Par: | D4: Par: | E4: =VLOOKUP($E1, 'Course List'!$A$3:$AS$14,27+E2, FALSE) -> 4 | F4: =VLOOKUP($E1, 'Course List'!$A$3:$AS$14,27+F2, FALSE) -> 4 | G4: =VLOOKUP($E1, 'Course List'!$A$3:$AS$14,27+G2, FALSE) -> 3 | H4: =VLOOKUP($E1, 'Course List'!$A$3:$AS$14,27+H2, FALSE) -> 4 | I4: =VLOOKUP($E1, 'Course List'!$A$3:$AS$14,27+I2, FALSE) -> 4 | J4: =VLOOKUP($E1, 'Course List'!$A$3:$AS$14,27+J2, FALSE) -> 5 | K4: =VLOOKUP($E1, 'Course List'!$A$3:$AS$14,27+K2, FALSE) -> 4 | L4: =VLOOKUP($E1, 'Course List'!$A$3:$AS$14,27+L2, FALSE) -> 3 | M4: =VLOOKUP($E1, 'Course List'!$A$3:$AS$14,27+M2, FALSE) -> 5 | N4: =SUM(E4:M4) -> 36 | P4: Par: | Q4: =VLOOKUP($E1, 'Course List'!$A$3:$AS$14,27+Q2, FALSE) -> 4 | R4: =VLOOKUP($E1, 'Course List'!$A$3:$AS$14,27+R2, FALSE) -> 4 | S4: =VLOOKUP($E1, 'Course List'!$A$3:$AS$14,27+S2, FALSE) -> 4 | T4: =VLOOKUP($E1, 'Course List'!$A$3:$AS$14,27+T2, FALSE) -> 3 | U4: =VLOOKUP($E1, 'Course List'!$A$3:$AS$14,27+U2, FALSE) -> 5 | V4: =VLOOKUP($E1, 'Course List'!$A$3:$AS$14,27+V2, FALSE) -> 4 | W4: =VLOOKUP($E1, 'Course List'!$A$3:$AS$14,27+W2, FALSE) -> 5 | X4: =VLOOKUP($E1, 'Course List'!$A$3:$AS$14,27+X2, FALSE) -> 3 | Y4: =VLOOKUP($E1, 'Course List'!$A$3:$AS$14,27+Y2, FALSE) -> 4 | Z4: =SUM(Q4:Y4) -> 36 | AA4: =N4+Z4 -> 72
A5: Player | B5: Team | C5: Tee HCP | D5: Net HCP | E5: 1 | F5: 2 | G5: 3 | H5: 4 | I5: 5 | J5: 6 | K5: 7 | L5: 8 | M5: 9 | N5: OUT | P5: Player | Q5: 10 | R5: 11 | S5: 12 | T5: 13 | U5: 14 | V5: 15 | W5: 16 | X5: 17 | Y5: 18 | Z5: IN | AA5: Total Gross | AB5: Total Net
E6: =IF(E7=1,"O", IF(E7=2,"O O","")) | F6: =IF(F7=1,"O", IF(F7=2,"O O","")) | G6: =IF(G7=1,"O", IF(G7=2,"O O","")) | H6: =IF(H7=1,"O", IF(H7=2,"O O","")) | I6: =IF(I7=1,"O", IF(I7=2,"O O","")) | J6: =IF(J7=1,"O", IF(J7=2,"O O","")) | K6: =IF(K7=1,"O", IF(K7=2,"O O","")) | L6: =IF(L7=1,"O", IF(L7=2,"O O","")) | M6: =IF(M7=1,"O", IF(M7=2,"O O","")) | Q6: =IF(Q7=1,"O", IF(Q7=2,"O O","")) | R6: =IF(R7=1,"O", IF(R7=2,"O O","")) | S6: =IF(S7=1,"O", IF(S7=2,"O O","")) | T6: =IF(T7=1,"O", IF(T7=2,"O O","")) | U6: =IF(U7=1,"O", IF(U7=2,"O O","")) | V6: =IF(V7=1,"O", IF(V7=2,"O O","")) | W6: =IF(W7=1,"O", IF(W7=2,"O O","")) | X6: =IF(X7=1,"O", IF(X7=2,"O O","")) | Y6: =IF(Y7=1,"O", IF(Y7=2,"O O",""))
E7: =IF($D8>0,FLOOR($D8/18,1),0)+IF(AND(MOD($D8,18)>=E$3,$D8>0),1,0)-IF(E$3-18>$D8,1,0) -> 0 | F7: =IF($D8>0,FLOOR($D8/18,1),0)+IF(AND(MOD($D8,18)>=F$3,$D8>0),1,0)-IF(F$3-18>$D8,1,0) -> 0 | G7: =IF($D8>0,FLOOR($D8/18,1),0)+IF(AND(MOD($D8,18)>=G$3,$D8>0),1,0)-IF(G$3-18>$D8,1,0) -> 0 | H7: =IF($D8>0,FLOOR($D8/18,1),0)+IF(AND(MOD($D8,18)>=H$3,$D8>0),1,0)-IF(H$3-18>$D8,1,0) -> 0 | I7: =IF($D8>0,FLOOR($D8/18,1),0)+IF(AND(MOD($D8,18)>=I$3,$D8>0),1,0)-IF(I$3-18>$D8,1,0) -> 0 | J7: =IF($D8>0,FLOOR($D8/18,1),0)+IF(AND(MOD($D8,18)>=J$3,$D8>0),1,0)-IF(J$3-18>$D8,1,0) -> 0 | K7: =IF($D8>0,FLOOR($D8/18,1),0)+IF(AND(MOD($D8,18)>=K$3,$D8>0),1,0)-IF(K$3-18>$D8,1,0) -> 0 | L7: =IF($D8>0,FLOOR($D8/18,1),0)+IF(AND(MOD($D8,18)>=L$3,$D8>0),1,0)-IF(L$3-18>$D8,1,0) -> 0 | M7: =IF($D8>0,FLOOR($D8/18,1),0)+IF(AND(MOD($D8,18)>=M$3,$D8>0),1,0)-IF(M$3-18>$D8,1,0) -> 0 | Q7: =IF($D8>0,FLOOR($D8/18,1),0)+IF(AND(MOD($D8,18)>=Q$3,$D8>0),1,0)-IF(Q$3-18>$D8,1,0) -> 0 | R7: =IF($D8>0,FLOOR($D8/18,1),0)+IF(AND(MOD($D8,18)>=R$3,$D8>0),1,0)-IF(R$3-18>$D8,1,0) -> 0 | S7: =IF($D8>0,FLOOR($D8/18,1),0)+IF(AND(MOD($D8,18)>=S$3,$D8>0),1,0)-IF(S$3-18>$D8,1,0) -> 0 | T7: =IF($D8>0,FLOOR($D8/18,1),0)+IF(AND(MOD($D8,18)>=T$3,$D8>0),1,0)-IF(T$3-18>$D8,1,0) -> 0 | U7: =IF($D8>0,FLOOR($D8/18,1),0)+IF(AND(MOD($D8,18)>=U$3,$D8>0),1,0)-IF(U$3-18>$D8,1,0) -> 0 | V7: =IF($D8>0,FLOOR($D8/18,1),0)+IF(AND(MOD($D8,18)>=V$3,$D8>0),1,0)-IF(V$3-18>$D8,1,0) -> 0 | W7: =IF($D8>0,FLOOR($D8/18,1),0)+IF(AND(MOD($D8,18)>=W$3,$D8>0),1,0)-IF(W$3-18>$D8,1,0) -> 0 | X7: =IF($D8>0,FLOOR($D8/18,1),0)+IF(AND(MOD($D8,18)>=X$3,$D8>0),1,0)-IF(X$3-18>$D8,1,0) -> 0 | Y7: =IF($D8>0,FLOOR($D8/18,1),0)+IF(AND(MOD($D8,18)>=Y$3,$D8>0),1,0)-IF(Y$3-18>$D8,1,0) -> 0
A8: ='Match Selection'!D4 -> Elger | B8: =VLOOKUP(A8, 'Master Input'!$A$11:$B$27, 2, FALSE) -> WEEZ | C8: =VLOOKUP(A8,'Master Input'!$A$11:$L$27,'Master Input'!$F$28, FALSE) -> 5 | D8: =C8-SMALL($C$8:$C$17,1) -> 0 | E8: 6 | F8: 5 | G8: 4 | H8: 4 | I8: 6 | J8: 4 | K8: 4 | L8: 3 | M8: 5 | N8: =IF(M8="","", SUM(E8:M8)) -> 41 | P8: =A8 -> Elger | Q8: 5 | R8: 4 | S8: 6 | T8: 3 | U8: 6 | V8: 5 | W8: 5 | X8: 4 | Y8: 9 | Z8: =IF(Y8="","", SUM(Q8:Y8)) -> 47 | AA8: =IF(Z8="", "", SUM(N8,Z8)) -> 88 | AB8: =IF(Y8="", "", AA8-C8) -> 83
E9: =IF(E10=1,"O", IF(E10=2,"O O","")) | F9: =IF(F10=1,"O", IF(F10=2,"O O","")) | G9: =IF(G10=1,"O", IF(G10=2,"O O","")) | H9: =IF(H10=1,"O", IF(H10=2,"O O","")) | I9: =IF(I10=1,"O", IF(I10=2,"O O","")) -> O | J9: =IF(J10=1,"O", IF(J10=2,"O O","")) | K9: =IF(K10=1,"O", IF(K10=2,"O O","")) | L9: =IF(L10=1,"O", IF(L10=2,"O O","")) -> O | M9: =IF(M10=1,"O", IF(M10=2,"O O","")) -> O | Q9: =IF(Q10=1,"O", IF(Q10=2,"O O","")) | R9: =IF(R10=1,"O", IF(R10=2,"O O","")) | S9: =IF(S10=1,"O", IF(S10=2,"O O","")) -> O | T9: =IF(T10=1,"O", IF(T10=2,"O O","")) | U9: =IF(U10=1,"O", IF(U10=2,"O O","")) | V9: =IF(V10=1,"O", IF(V10=2,"O O","")) -> O | W9: =IF(W10=1,"O", IF(W10=2,"O O","")) | X9: =IF(X10=1,"O", IF(X10=2,"O O","")) | Y9: =IF(Y10=1,"O", IF(Y10=2,"O O","")) -> O
E10: =IF($D11>0,FLOOR($D11/18,1),0)+IF(AND(MOD($D11,18)>=E$3,$D11>0),1,0)-IF(E$3-18>$D11,1,0) -> 0 | F10: =IF($D11>0,FLOOR($D11/18,1),0)+IF(AND(MOD($D11,18)>=F$3,$D11>0),1,0)-IF(F$3-18>$D11,1,0) -> 0 | G10: =IF($D11>0,FLOOR($D11/18,1),0)+IF(AND(MOD($D11,18)>=G$3,$D11>0),1,0)-IF(G$3-18>$D11,1,0) -> 0 | H10: =IF($D11>0,FLOOR($D11/18,1),0)+IF(AND(MOD($D11,18)>=H$3,$D11>0),1,0)-IF(H$3-18>$D11,1,0) -> 0 | I10: =IF($D11>0,FLOOR($D11/18,1),0)+IF(AND(MOD($D11,18)>=I$3,$D11>0),1,0)-IF(I$3-18>$D11,1,0) -> 1 | J10: =IF($D11>0,FLOOR($D11/18,1),0)+IF(AND(MOD($D11,18)>=J$3,$D11>0),1,0)-IF(J$3-18>$D11,1,0) -> 0 | K10: =IF($D11>0,FLOOR($D11/18,1),0)+IF(AND(MOD($D11,18)>=K$3,$D11>0),1,0)-IF(K$3-18>$D11,1,0) -> 0 | L10: =IF($D11>0,FLOOR($D11/18,1),0)+IF(AND(MOD($D11,18)>=L$3,$D11>0),1,0)-IF(L$3-18>$D11,1,0) -> 1 | M10: =IF($D11>0,FLOOR($D11/18,1),0)+IF(AND(MOD($D11,18)>=M$3,$D11>0),1,0)-IF(M$3-18>$D11,1,0) -> 1 | Q10: =IF($D11>0,FLOOR($D11/18,1),0)+IF(AND(MOD($D11,18)>=Q$3,$D11>0),1,0)-IF(Q$3-18>$D11,1,0) -> 0 | R10: =IF($D11>0,FLOOR($D11/18,1),0)+IF(AND(MOD($D11,18)>=R$3,$D11>0),1,0)-IF(R$3-18>$D11,1,0) -> 0 | S10: =IF($D11>0,FLOOR($D11/18,1),0)+IF(AND(MOD($D11,18)>=S$3,$D11>0),1,0)-IF(S$3-18>$D11,1,0) -> 1 | T10: =IF($D11>0,FLOOR($D11/18,1),0)+IF(AND(MOD($D11,18)>=T$3,$D11>0),1,0)-IF(T$3-18>$D11,1,0) -> 0 | U10: =IF($D11>0,FLOOR($D11/18,1),0)+IF(AND(MOD($D11,18)>=U$3,$D11>0),1,0)-IF(U$3-18>$D11,1,0) -> 0 | V10: =IF($D11>0,FLOOR($D11/18,1),0)+IF(AND(MOD($D11,18)>=V$3,$D11>0),1,0)-IF(V$3-18>$D11,1,0) -> 1 | W10: =IF($D11>0,FLOOR($D11/18,1),0)+IF(AND(MOD($D11,18)>=W$3,$D11>0),1,0)-IF(W$3-18>$D11,1,0) -> 0 | X10: =IF($D11>0,FLOOR($D11/18,1),0)+IF(AND(MOD($D11,18)>=X$3,$D11>0),1,0)-IF(X$3-18>$D11,1,0) -> 0 | Y10: =IF($D11>0,FLOOR($D11/18,1),0)+IF(AND(MOD($D11,18)>=Y$3,$D11>0),1,0)-IF(Y$3-18>$D11,1,0) -> 1
A11: ='Match Selection'!D5 -> T-Mo | B11: =VLOOKUP(A11, 'Master Input'!$A$11:$B$27, 2, FALSE) -> WEEZ | C11: =VLOOKUP(A11,'Master Input'!$A$11:$L$27,'Master Input'!$F$28, FALSE) -> 11 | D11: =C11-SMALL($C$8:$C$17,1) -> 6 | E11: 4 | F11: 3 | G11: 4 | H11: 5 | I11: 4 | J11: 4 | K11: 6 | L11: 5 | M11: 6 | N11: =IF(M11="","", SUM(E11:M11)) -> 41 | P11: =A11 -> T-Mo | Q11: 4 | R11: 5 | S11: 8 | T11: 5 | U11: 3 | V11: 8 | W11: 5 | X11: 4 | Y11: 4 | Z11: =IF(Y11="","", SUM(Q11:Y11)) -> 46 | AA11: =IF(Z11="", "", SUM(N11,Z11)) -> 87 | AB11: =IF(Y11="", "", AA11-C11) -> 76
E12: =IF(E13=1,"O", IF(E13=2,"O O","")) | F12: =IF(F13=1,"O", IF(F13=2,"O O","")) | G12: =IF(G13=1,"O", IF(G13=2,"O O","")) | H12: =IF(H13=1,"O", IF(H13=2,"O O","")) | I12: =IF(I13=1,"O", IF(I13=2,"O O","")) | J12: =IF(J13=1,"O", IF(J13=2,"O O","")) | K12: =IF(K13=1,"O", IF(K13=2,"O O","")) | L12: =IF(L13=1,"O", IF(L13=2,"O O","")) | M12: =IF(M13=1,"O", IF(M13=2,"O O","")) -> O | Q12: =IF(Q13=1,"O", IF(Q13=2,"O O","")) | R12: =IF(R13=1,"O", IF(R13=2,"O O","")) | S12: =IF(S13=1,"O", IF(S13=2,"O O","")) -> O | T12: =IF(T13=1,"O", IF(T13=2,"O O","")) | U12: =IF(U13=1,"O", IF(U13=2,"O O","")) | V12: =IF(V13=1,"O", IF(V13=2,"O O","")) -> O | W12: =IF(W13=1,"O", IF(W13=2,"O O","")) | X12: =IF(X13=1,"O", IF(X13=2,"O O","")) | Y12: =IF(Y13=1,"O", IF(Y13=2,"O O","")) -> O
E13: =IF($D14>0,FLOOR($D14/18,1),0)+IF(AND(MOD($D14,18)>=E$3,$D14>0),1,0)-IF(E$3-18>$D14,1,0) -> 0 | F13: =IF($D14>0,FLOOR($D14/18,1),0)+IF(AND(MOD($D14,18)>=F$3,$D14>0),1,0)-IF(F$3-18>$D14,1,0) -> 0 | G13: =IF($D14>0,FLOOR($D14/18,1),0)+IF(AND(MOD($D14,18)>=G$3,$D14>0),1,0)-IF(G$3-18>$D14,1,0) -> 0 | H13: =IF($D14>0,FLOOR($D14/18,1),0)+IF(AND(MOD($D14,18)>=H$3,$D14>0),1,0)-IF(H$3-18>$D14,1,0) -> 0 | I13: =IF($D14>0,FLOOR($D14/18,1),0)+IF(AND(MOD($D14,18)>=I$3,$D14>0),1,0)-IF(I$3-18>$D14,1,0) -> 0 | J13: =IF($D14>0,FLOOR($D14/18,1),0)+IF(AND(MOD($D14,18)>=J$3,$D14>0),1,0)-IF(J$3-18>$D14,1,0) -> 0 | K13: =IF($D14>0,FLOOR($D14/18,1),0)+IF(AND(MOD($D14,18)>=K$3,$D14>0),1,0)-IF(K$3-18>$D14,1,0) -> 0 | L13: =IF($D14>0,FLOOR($D14/18,1),0)+IF(AND(MOD($D14,18)>=L$3,$D14>0),1,0)-IF(L$3-18>$D14,1,0) -> 0 | M13: =IF($D14>0,FLOOR($D14/18,1),0)+IF(AND(MOD($D14,18)>=M$3,$D14>0),1,0)-IF(M$3-18>$D14,1,0) -> 1 | Q13: =IF($D14>0,FLOOR($D14/18,1),0)+IF(AND(MOD($D14,18)>=Q$3,$D14>0),1,0)-IF(Q$3-18>$D14,1,0) -> 0 | R13: =IF($D14>0,FLOOR($D14/18,1),0)+IF(AND(MOD($D14,18)>=R$3,$D14>0),1,0)-IF(R$3-18>$D14,1,0) -> 0 | S13: =IF($D14>0,FLOOR($D14/18,1),0)+IF(AND(MOD($D14,18)>=S$3,$D14>0),1,0)-IF(S$3-18>$D14,1,0) -> 1 | T13: =IF($D14>0,FLOOR($D14/18,1),0)+IF(AND(MOD($D14,18)>=T$3,$D14>0),1,0)-IF(T$3-18>$D14,1,0) -> 0 | U13: =IF($D14>0,FLOOR($D14/18,1),0)+IF(AND(MOD($D14,18)>=U$3,$D14>0),1,0)-IF(U$3-18>$D14,1,0) -> 0 | V13: =IF($D14>0,FLOOR($D14/18,1),0)+IF(AND(MOD($D14,18)>=V$3,$D14>0),1,0)-IF(V$3-18>$D14,1,0) -> 1 | W13: =IF($D14>0,FLOOR($D14/18,1),0)+IF(AND(MOD($D14,18)>=W$3,$D14>0),1,0)-IF(W$3-18>$D14,1,0) -> 0 | X13: =IF($D14>0,FLOOR($D14/18,1),0)+IF(AND(MOD($D14,18)>=X$3,$D14>0),1,0)-IF(X$3-18>$D14,1,0) -> 0 | Y13: =IF($D14>0,FLOOR($D14/18,1),0)+IF(AND(MOD($D14,18)>=Y$3,$D14>0),1,0)-IF(Y$3-18>$D14,1,0) -> 1
A14: ='Match Selection'!G4 -> R-Mac | B14: =VLOOKUP(A14, 'Master Input'!$A$11:$B$27, 2, FALSE) -> TEES | C14: =VLOOKUP(A14,'Master Input'!$A$11:$L$27,'Master Input'!$F$28, FALSE) -> 9 | D14: =C14-SMALL($C$8:$C$17,1) -> 4 | E14: 5 | F14: 4 | G14: 5 | H14: 4 | I14: 4 | J14: 6 | K14: 4 | L14: 4 | M14: 7 | N14: =IF(M14="","", SUM(E14:M14)) -> 43 | P14: =A14 -> R-Mac | Q14: 6 | R14: 4 | S14: 4 | T14: 3 | U14: 5 | V14: 7 | W14: 5 | X14: 4 | Y14: 6 | Z14: =IF(Y14="","", SUM(Q14:Y14)) -> 44 | AA14: =IF(Z14="", "", SUM(N14,Z14)) -> 87 | AB14: =IF(Y14="", "", AA14-C14) -> 78
E15: =IF(E16=1,"O", IF(E16=2,"O O","")) | F15: =IF(F16=1,"O", IF(F16=2,"O O","")) | G15: =IF(G16=1,"O", IF(G16=2,"O O","")) | H15: =IF(H16=1,"O", IF(H16=2,"O O","")) | I15: =IF(I16=1,"O", IF(I16=2,"O O","")) | J15: =IF(J16=1,"O", IF(J16=2,"O O","")) | K15: =IF(K16=1,"O", IF(K16=2,"O O","")) | L15: =IF(L16=1,"O", IF(L16=2,"O O","")) -> O | M15: =IF(M16=1,"O", IF(M16=2,"O O","")) -> O | Q15: =IF(Q16=1,"O", IF(Q16=2,"O O","")) | R15: =IF(R16=1,"O", IF(R16=2,"O O","")) | S15: =IF(S16=1,"O", IF(S16=2,"O O","")) -> O | T15: =IF(T16=1,"O", IF(T16=2,"O O","")) | U15: =IF(U16=1,"O", IF(U16=2,"O O","")) | V15: =IF(V16=1,"O", IF(V16=2,"O O","")) -> O | W15: =IF(W16=1,"O", IF(W16=2,"O O","")) | X15: =IF(X16=1,"O", IF(X16=2,"O O","")) | Y15: =IF(Y16=1,"O", IF(Y16=2,"O O","")) -> O
E16: =IF($D17>0,FLOOR($D17/18,1),0)+IF(AND(MOD($D17,18)>=E$3,$D17>0),1,0)-IF(E$3-18>$D17,1,0) -> 0 | F16: =IF($D17>0,FLOOR($D17/18,1),0)+IF(AND(MOD($D17,18)>=F$3,$D17>0),1,0)-IF(F$3-18>$D17,1,0) -> 0 | G16: =IF($D17>0,FLOOR($D17/18,1),0)+IF(AND(MOD($D17,18)>=G$3,$D17>0),1,0)-IF(G$3-18>$D17,1,0) -> 0 | H16: =IF($D17>0,FLOOR($D17/18,1),0)+IF(AND(MOD($D17,18)>=H$3,$D17>0),1,0)-IF(H$3-18>$D17,1,0) -> 0 | I16: =IF($D17>0,FLOOR($D17/18,1),0)+IF(AND(MOD($D17,18)>=I$3,$D17>0),1,0)-IF(I$3-18>$D17,1,0) -> 0 | J16: =IF($D17>0,FLOOR($D17/18,1),0)+IF(AND(MOD($D17,18)>=J$3,$D17>0),1,0)-IF(J$3-18>$D17,1,0) -> 0 | K16: =IF($D17>0,FLOOR($D17/18,1),0)+IF(AND(MOD($D17,18)>=K$3,$D17>0),1,0)-IF(K$3-18>$D17,1,0) -> 0 | L16: =IF($D17>0,FLOOR($D17/18,1),0)+IF(AND(MOD($D17,18)>=L$3,$D17>0),1,0)-IF(L$3-18>$D17,1,0) -> 1 | M16: =IF($D17>0,FLOOR($D17/18,1),0)+IF(AND(MOD($D17,18)>=M$3,$D17>0),1,0)-IF(M$3-18>$D17,1,0) -> 1 | Q16: =IF($D17>0,FLOOR($D17/18,1),0)+IF(AND(MOD($D17,18)>=Q$3,$D17>0),1,0)-IF(Q$3-18>$D17,1,0) -> 0 | R16: =IF($D17>0,FLOOR($D17/18,1),0)+IF(AND(MOD($D17,18)>=R$3,$D17>0),1,0)-IF(R$3-18>$D17,1,0) -> 0 | S16: =IF($D17>0,FLOOR($D17/18,1),0)+IF(AND(MOD($D17,18)>=S$3,$D17>0),1,0)-IF(S$3-18>$D17,1,0) -> 1 | T16: =IF($D17>0,FLOOR($D17/18,1),0)+IF(AND(MOD($D17,18)>=T$3,$D17>0),1,0)-IF(T$3-18>$D17,1,0) -> 0 | U16: =IF($D17>0,FLOOR($D17/18,1),0)+IF(AND(MOD($D17,18)>=U$3,$D17>0),1,0)-IF(U$3-18>$D17,1,0) -> 0 | V16: =IF($D17>0,FLOOR($D17/18,1),0)+IF(AND(MOD($D17,18)>=V$3,$D17>0),1,0)-IF(V$3-18>$D17,1,0) -> 1 | W16: =IF($D17>0,FLOOR($D17/18,1),0)+IF(AND(MOD($D17,18)>=W$3,$D17>0),1,0)-IF(W$3-18>$D17,1,0) -> 0 | X16: =IF($D17>0,FLOOR($D17/18,1),0)+IF(AND(MOD($D17,18)>=X$3,$D17>0),1,0)-IF(X$3-18>$D17,1,0) -> 0 | Y16: =IF($D17>0,FLOOR($D17/18,1),0)+IF(AND(MOD($D17,18)>=Y$3,$D17>0),1,0)-IF(Y$3-18>$D17,1,0) -> 1
A17: ='Match Selection'!G5 -> House | B17: =VLOOKUP(A17, 'Master Input'!$A$11:$B$27, 2, FALSE) -> TEES | C17: =VLOOKUP(A17,'Master Input'!$A$11:$L$27,'Master Input'!$F$28, FALSE) -> 10 | D17: =C17-SMALL($C$8:$C$17,1) -> 5 | E17: 6 | F17: 4 | G17: 3 | H17: 4 | I17: 5 | J17: 7 | K17: 5 | L17: 4 | M17: 9 | N17: =IF(M17="","", SUM(E17:M17)) -> 47 | P17: =A17 -> House | Q17: 6 | R17: 3 | S17: 3 | T17: 4 | U17: 6 | V17: 3 | W17: 5 | X17: 2 | Y17: 4 | Z17: =IF(Y17="","", SUM(Q17:Y17)) -> 36 | AA17: =IF(Z17="", "", SUM(N17,Z17)) -> 83 | AB17: =IF(Y17="", "", AA17-C17) -> 73
N18: Front | Z18: Back | AA18: Overall
A19: =B8 -> WEEZ | E19: =IF(OR(E8="",E11="",E14="",E17=""),"",SUM(E25:E26)) -> 12 | F19: =IF(OR(F8="",F11="",F14="",F17=""),"",SUM(F25:F26)) -> 12 | G19: =IF(OR(G8="",G11="",G14="",G17=""),"",SUM(G25:G26)) -> 0 | H19: =IF(OR(H8="",H11="",H14="",H17=""),"",SUM(H25:H26)) -> 4 | I19: =IF(OR(I8="",I11="",I14="",I17=""),"",SUM(I25:I26)) -> 12 | J19: =IF(OR(J8="",J11="",J14="",J17=""),"",SUM(J25:J26)) -> 12 | K19: =IF(OR(K8="",K11="",K14="",K17=""),"",SUM(K25:K26)) -> 6 | L19: =IF(OR(L8="",L11="",L14="",L17=""),"",SUM(L25:L26)) -> 6 | M19: =IF(OR(M8="",M11="",M14="",M17=""),"",SUM(M25:M26)) -> 12 | N19: =IF(OR(E8="",E11="",E14="",E17=""),"", SUM(E19:M19)) -> 76 | P19: =B8 -> WEEZ | Q19: =IF(OR(Q8="",Q11="",Q14="",Q17=""),"",SUM(Q25:Q26)) -> 12 | R19: =IF(OR(R8="",R11="",R14="",R17=""),"",SUM(R25:R26)) -> 0 | S19: =IF(OR(S8="",S11="",S14="",S17=""),"",SUM(S25:S26)) -> 0 | T19: =IF(OR(T8="",T11="",T14="",T17=""),"",SUM(T25:T26)) -> 6 | U19: =IF(OR(U8="",U11="",U14="",U17=""),"",SUM(U25:U26)) -> 12 | V19: =IF(OR(V8="",V11="",V14="",V17=""),"",SUM(V25:V26)) -> 0 | W19: =IF(OR(W8="",W11="",W14="",W17=""),"",SUM(W25:W26)) -> 6 | X19: =IF(OR(X8="",X11="",X14="",X17=""),"",SUM(X25:X26)) -> 0 | Y19: =IF(OR(Y8="",Y11="",Y14="",Y17=""),"",SUM(Y25:Y26)) -> 6 | Z19: =IF(OR(Q8="",Q11="",Q14="",Q17=""),"", SUM(Q19:Y19)) -> 42 | AA19: =IF(OR(E8="",E11="",E14="",E17=""),"", SUM(N19,Z19)) -> 118
A20: =B14 -> TEES | E20: =IF(OR(E8="",E11="",E14="",E17=""),"",SUM(E28:E29)) -> 0 | F20: =IF(OR(F8="",F11="",F14="",F17=""),"",SUM(F28:F29)) -> 0 | G20: =IF(OR(G8="",G11="",G14="",G17=""),"",SUM(G28:G29)) -> 12 | H20: =IF(OR(H8="",H11="",H14="",H17=""),"",SUM(H28:H29)) -> 8 | I20: =IF(OR(I8="",I11="",I14="",I17=""),"",SUM(I28:I29)) -> 0 | J20: =IF(OR(J8="",J11="",J14="",J17=""),"",SUM(J28:J29)) -> 0 | K20: =IF(OR(K8="",K11="",K14="",K17=""),"",SUM(K28:K29)) -> 6 | L20: =IF(OR(L8="",L11="",L14="",L17=""),"",SUM(L28:L29)) -> 6 | M20: =IF(OR(M8="",M11="",M14="",M17=""),"",SUM(M28:M29)) -> 0 | N20: =IF(OR(E8="",E11="",E14="",E17=""),"", SUM(E20:M20)) -> 32 | P20: =B14 -> TEES | Q20: =IF(OR(Q8="",Q11="",Q14="",Q17=""),"",SUM(Q28:Q29)) -> 0 | R20: =IF(OR(R8="",R11="",R14="",R17=""),"",SUM(R28:R29)) -> 12 | S20: =IF(OR(S8="",S11="",S14="",S17=""),"",SUM(S28:S29)) -> 12 | T20: =IF(OR(T8="",T11="",T14="",T17=""),"",SUM(T28:T29)) -> 6 | U20: =IF(OR(U8="",U11="",U14="",U17=""),"",SUM(U28:U29)) -> 0 | V20: =IF(OR(V8="",V11="",V14="",V17=""),"",SUM(V28:V29)) -> 12 | W20: =IF(OR(W8="",W11="",W14="",W17=""),"",SUM(W28:W29)) -> 6 | X20: =IF(OR(X8="",X11="",X14="",X17=""),"",SUM(X28:X29)) -> 12 | Y20: =IF(OR(Y8="",Y11="",Y14="",Y17=""),"",SUM(Y28:Y29)) -> 6 | Z20: =IF(OR(Q8="",Q11="",Q14="",Q17=""),"", SUM(Q20:Y20)) -> 66 | AA20: =IF(OR(E8="",E11="",E14="",E17=""),"", SUM(N20,Z20)) -> 98 | AB20: BC Pt TOTAL
L21: BC Points: | M21: =A19 -> WEEZ | N21: =IF(M19="","",IF(N19>N20,VLOOKUP($B$2,'Master Input'!$O$10:$R$23,'Master Input'!$P$11,FALSE),IF(N19=N20,VLOOKUP($B$2,'Master Input'!$O$10:$R$23,'Master Input'!$P$11,FALSE)/2,0))) -> 1 | X21: BC Points: | Y21: =P19 -> WEEZ | Z21: =IF(Y19="","",(IF(Z19>Z20,VLOOKUP($B$2,'Master Input'!$O$10:$R$23,'Master Input'!$Q$11,FALSE),IF(Z19=Z20,VLOOKUP($B$2,'Master Input'!$O$10:$R$23,'Master Input'!$Q$11,FALSE)/2,0)))) -> 0 | AA21: =IF(Y19="","",IF(AA19>AA20,VLOOKUP($B$2,'Master Input'!$O$10:$R$23,'Master Input'!$R$11,FALSE),IF(AA19=AA20,VLOOKUP($B$2,'Master Input'!$O$10:$R$23,'Master Input'!$R$11,FALSE)/2,0))) -> 2 | AB21: =IF(Y19="","",IF(AA21="","", SUM(N21,Z21,AA21))) -> 3
B22: 1 | C22: 2 | D22: 3 | E22: 4 | F22: 5 | G22: 6 | H22: 7 | I22: 8 | J22: 9 | K22: 10 | L22: 11 | M22: 12 | N22: 13 | O22: 14 | P22: 15 | Q22: 16 | R22: 17 | S22: 18 | T22: 19 | U22: 20 | V22: 21 | W22: 22 | X22: 23 | Y22: 24 | Z22: Hole | AA22: Holes | AB22: Point
B23: Match | E23: 12 | F23: 12 | G23: 12 | H23: 4 | I23: 12 | J23: 6 | K23: 6 | L23: 6 | M23: 6 | Q23: 12 | R23: 12 | S23: 12 | T23: 6 | U23: 12 | V23: 12 | W23: 3 | X23: 12 | Y23: 6 | Z23: Contr | AA23: Won | AB23: Share
B24: =B8 -> WEEZ | N24: =SUM(E24:M24) -> 0 | Z24: =SUM(Z25:Z26) -> 9.8333333 | AA24: =SUM(Z24,N24) -> 9.8333333
A25: =A8 -> Elger | E25: 0 | F25: 0 | G25: 0 | H25: 4 | I25: 0 | J25: 6 | K25: 6 | L25: 6 | M25: 6 | Q25: 0 | R25: 0 | S25: 0 | T25: 6 | U25: 0 | V25: 0 | W25: 3 | X25: 0 | Y25: 0 | Z25: =SUM(E25:M25,Q25:Y25)/12 -> 3.0833333 | AA25: =Z25/$Z$30*18 -> 3.0833333 | AB25: =$AB$21*AA25/AA$24 -> 0.94067797
A26: =A11 -> T-Mo | E26: 12 | F26: 12 | G26: 0 | H26: 0 | I26: 12 | J26: 6 | K26: 0 | L26: 0 | M26: 6 | Q26: 12 | R26: 0 | S26: 0 | T26: 0 | U26: 12 | V26: 0 | W26: 3 | X26: 0 | Y26: 6 | Z26: =SUM(E26:M26,Q26:Y26)/12 -> 6.75 | AA26: =Z26/$Z$30*18 -> 6.75 | AB26: =$AB$21*AA26/AA$24 -> 2.059322
B27: =B14 -> TEES | N27: =SUM(E27:M27) -> 0 | Z27: =SUM(Z28:Z29) -> 8.1666667 | AA27: =SUM(Z27,N27) -> 8.1666667
A28: =A14 -> R-Mac | E28: 0 | F28: 0 | G28: 0 | H28: 4 | I28: 0 | J28: 0 | K28: 6 | L28: 0 | M28: 0 | Q28: 0 | R28: 0 | S28: 0 | T28: 6 | U28: 0 | V28: 0 | W28: 3 | X28: 0 | Y28: 0 | Z28: =SUM(E28:M28,Q28:Y28)/12 -> 1.5833333 | AA28: =Z28/$Z$30*18 -> 1.5833333 | AB28: =(SUM('Master Input'!P$20:R$20)-$AB$21)*AA28/AA$27 -> 0.19387755
A29: =A17 -> House | E29: 0 | F29: 0 | G29: 12 | H29: 4 | I29: 0 | J29: 0 | K29: 0 | L29: 6 | M29: 0 | Q29: 0 | R29: 12 | S29: 12 | T29: 0 | U29: 0 | V29: 12 | W29: 3 | X29: 12 | Y29: 6 | Z29: =SUM(E29:M29,Q29:Y29)/12 -> 6.5833333 | AA29: =Z29/$Z$30*18 -> 6.5833333 | AB29: =(SUM('Master Input'!P$20:R$20)-$AB$21)*AA29/AA$27 -> 0.80612245
E30: =SUM(E25:E26,E28:E29) -> 12 | F30: =SUM(F25:F26,F28:F29) -> 12 | G30: =SUM(G25:G26,G28:G29) -> 12 | H30: =SUM(H25:H26,H28:H29) -> 12 | I30: =SUM(I25:I26,I28:I29) -> 12 | J30: =SUM(J25:J26,J28:J29) -> 12 | K30: =SUM(K25:K26,K28:K29) -> 12 | L30: =SUM(L25:L26,L28:L29) -> 12 | M30: =SUM(M25:M26,M28:M29) -> 12 | Q30: =SUM(Q25:Q26,Q28:Q29) -> 12 | R30: =SUM(R25:R26,R28:R29) -> 12 | S30: =SUM(S25:S26,S28:S29) -> 12 | T30: =SUM(T25:T26,T28:T29) -> 12 | U30: =SUM(U25:U26,U28:U29) -> 12 | V30: =SUM(V25:V26,V28:V29) -> 12 | W30: =SUM(W25:W26,W28:W29) -> 12 | X30: =SUM(X25:X26,X28:X29) -> 12 | ... Z30: =SUM(Z25:Z26,Z28:Z29) -> 18

Sheet R1_G2
A1: Group 2 | B1: ='Master Input'!F3 -> 0.048611111 | C1: ='Master Input'!$E$2 -> Round 1 | E1: ='Master Input'!$E$6 -> Sundance - Blue | P1: ='Master Input'!$E$2&" - "&A1 -> Round 1 - Group 2 | U1: ='Master Input'!$E$6 -> Sundance - Blue
A2: Hole: | B2: ='Match Selection'!B4 -> Dirty Dozen | D2: Hole: | E2: 1 | F2: 2 | G2: 3 | H2: 4 | I2: 5 | J2: 6 | K2: 7 | L2: 8 | M2: 9 | N2: OUT | P2: Hole: | Q2: 10 | R2: 11 | S2: 12 | T2: 13 | U2: 14 | V2: 15 | W2: 16 | X2: 17 | Y2: 18 | Z2: IN | AA2: TOTAL | AB2: NET
A3: Handicap: | D3: Handicap: | E3: =VLOOKUP($E1, 'Course List'!$A$3:$AS$14,5+E2, FALSE) -> 14 | F3: =VLOOKUP($E1, 'Course List'!$A$3:$AS$14,5+F2, FALSE) -> 16 | G3: =VLOOKUP($E1, 'Course List'!$A$3:$AS$14,5+G2, FALSE) -> 11 | H3: =VLOOKUP($E1, 'Course List'!$A$3:$AS$14,5+H2, FALSE) -> 12 | I3: =VLOOKUP($E1, 'Course List'!$A$3:$AS$14,5+I2, FALSE) -> 6 | J3: =VLOOKUP($E1, 'Course List'!$A$3:$AS$14,5+J2, FALSE) -> 8 | K3: =VLOOKUP($E1, 'Course List'!$A$3:$AS$14,5+K2, FALSE) -> 17 | L3: =VLOOKUP($E1, 'Course List'!$A$3:$AS$14,5+L2, FALSE) -> 5 | M3: =VLOOKUP($E1, 'Course List'!$A$3:$AS$14,5+M2, FALSE) -> 2 | P3: Handi: | Q3: =VLOOKUP($E1, 'Course List'!$A$3:$AS$14,5+Q2, FALSE) -> 9 | R3: =VLOOKUP($E1, 'Course List'!$A$3:$AS$14,5+R2, FALSE) -> 13 | S3: =VLOOKUP($E1, 'Course List'!$A$3:$AS$14,5+S2, FALSE) -> 4 | T3: =VLOOKUP($E1, 'Course List'!$A$3:$AS$14,5+T2, FALSE) -> 18 | U3: =VLOOKUP($E1, 'Course List'!$A$3:$AS$14,5+U2, FALSE) -> 7 | V3: =VLOOKUP($E1, 'Course List'!$A$3:$AS$14,5+V2, FALSE) -> 3 | W3: =VLOOKUP($E1, 'Course List'!$A$3:$AS$14,5+W2, FALSE) -> 10 | X3: =VLOOKUP($E1, 'Course List'!$A$3:$AS$14,5+X2, FALSE) -> 15 | Y3: =VLOOKUP($E1, 'Course List'!$A$3:$AS$14,5+Y2, FALSE) -> 1
A4: Par: | D4: Par: | E4: =VLOOKUP($E1, 'Course List'!$A$3:$AS$14,27+E2, FALSE) -> 4 | F4: =VLOOKUP($E1, 'Course List'!$A$3:$AS$14,27+F2, FALSE) -> 4 | G4: =VLOOKUP($E1, 'Course List'!$A$3:$AS$14,27+G2, FALSE) -> 3 | H4: =VLOOKUP($E1, 'Course List'!$A$3:$AS$14,27+H2, FALSE) -> 4 | I4: =VLOOKUP($E1, 'Course List'!$A$3:$AS$14,27+I2, FALSE) -> 4 | J4: =VLOOKUP($E1, 'Course List'!$A$3:$AS$14,27+J2, FALSE) -> 5 | K4: =VLOOKUP($E1, 'Course List'!$A$3:$AS$14,27+K2, FALSE) -> 4 | L4: =VLOOKUP($E1, 'Course List'!$A$3:$AS$14,27+L2, FALSE) -> 3 | M4: =VLOOKUP($E1, 'Course List'!$A$3:$AS$14,27+M2, FALSE) -> 5 | N4: =SUM(E4:M4) -> 36 | P4: Par: | Q4: =VLOOKUP($E1, 'Course List'!$A$3:$AS$14,27+Q2, FALSE) -> 4 | R4: =VLOOKUP($E1, 'Course List'!$A$3:$AS$14,27+R2, FALSE) -> 4 | S4: =VLOOKUP($E1, 'Course List'!$A$3:$AS$14,27+S2, FALSE) -> 4 | T4: =VLOOKUP($E1, 'Course List'!$A$3:$AS$14,27+T2, FALSE) -> 3 | U4: =VLOOKUP($E1, 'Course List'!$A$3:$AS$14,27+U2, FALSE) -> 5 | V4: =VLOOKUP($E1, 'Course List'!$A$3:$AS$14,27+V2, FALSE) -> 4 | W4: =VLOOKUP($E1, 'Course List'!$A$3:$AS$14,27+W2, FALSE) -> 5 | X4: =VLOOKUP($E1, 'Course List'!$A$3:$AS$14,27+X2, FALSE) -> 3 | Y4: =VLOOKUP($E1, 'Course List'!$A$3:$AS$14,27+Y2, FALSE) -> 4 | Z4: =SUM(Q4:Y4) -> 36 | AA4: =N4+Z4 -> 72
A5: Player | B5: Team | C5: Tee HCP | D5: Net HCP | E5: 1 | F5: 2 | G5: 3 | H5: 4 | I5: 5 | J5: 6 | K5: 7 | L5: 8 | M5: 9 | N5: OUT | P5: Player | Q5: 10 | R5: 11 | S5: 12 | T5: 13 | U5: 14 | V5: 15 | W5: 16 | X5: 17 | Y5: 18 | Z5: IN | AA5: Total Gross | AB5: Total Net
E6: =IF(E7=1,"O", IF(E7=2,"O O","")) | F6: =IF(F7=1,"O", IF(F7=2,"O O","")) | G6: =IF(G7=1,"O", IF(G7=2,"O O","")) | H6: =IF(H7=1,"O", IF(H7=2,"O O","")) | I6: =IF(I7=1,"O", IF(I7=2,"O O","")) | J6: =IF(J7=1,"O", IF(J7=2,"O O","")) | K6: =IF(K7=1,"O", IF(K7=2,"O O","")) | L6: =IF(L7=1,"O", IF(L7=2,"O O","")) | M6: =IF(M7=1,"O", IF(M7=2,"O O","")) | Q6: =IF(Q7=1,"O", IF(Q7=2,"O O","")) | R6: =IF(R7=1,"O", IF(R7=2,"O O","")) | S6: =IF(S7=1,"O", IF(S7=2,"O O","")) | T6: =IF(T7=1,"O", IF(T7=2,"O O","")) | U6: =IF(U7=1,"O", IF(U7=2,"O O","")) | V6: =IF(V7=1,"O", IF(V7=2,"O O","")) | W6: =IF(W7=1,"O", IF(W7=2,"O O","")) | X6: =IF(X7=1,"O", IF(X7=2,"O O","")) | Y6: =IF(Y7=1,"O", IF(Y7=2,"O O","")) -> O
E7: =IF($D8>0,FLOOR($D8/18,1),0)+IF(AND(MOD($D8,18)>=E$3,$D8>0),1,0)-IF(E$3-18>$D8,1,0) -> 0 | F7: =IF($D8>0,FLOOR($D8/18,1),0)+IF(AND(MOD($D8,18)>=F$3,$D8>0),1,0)-IF(F$3-18>$D8,1,0) -> 0 | G7: =IF($D8>0,FLOOR($D8/18,1),0)+IF(AND(MOD($D8,18)>=G$3,$D8>0),1,0)-IF(G$3-18>$D8,1,0) -> 0 | H7: =IF($D8>0,FLOOR($D8/18,1),0)+IF(AND(MOD($D8,18)>=H$3,$D8>0),1,0)-IF(H$3-18>$D8,1,0) -> 0 | I7: =IF($D8>0,FLOOR($D8/18,1),0)+IF(AND(MOD($D8,18)>=I$3,$D8>0),1,0)-IF(I$3-18>$D8,1,0) -> 0 | J7: =IF($D8>0,FLOOR($D8/18,1),0)+IF(AND(MOD($D8,18)>=J$3,$D8>0),1,0)-IF(J$3-18>$D8,1,0) -> 0 | K7: =IF($D8>0,FLOOR($D8/18,1),0)+IF(AND(MOD($D8,18)>=K$3,$D8>0),1,0)-IF(K$3-18>$D8,1,0) -> 0 | L7: =IF($D8>0,FLOOR($D8/18,1),0)+IF(AND(MOD($D8,18)>=L$3,$D8>0),1,0)-IF(L$3-18>$D8,1,0) -> 0 | M7: =IF($D8>0,FLOOR($D8/18,1),0)+IF(AND(MOD($D8,18)>=M$3,$D8>0),1,0)-IF(M$3-18>$D8,1,0) -> 0 | Q7: =IF($D8>0,FLOOR($D8/18,1),0)+IF(AND(MOD($D8,18)>=Q$3,$D8>0),1,0)-IF(Q$3-18>$D8,1,0) -> 0 | R7: =IF($D8>0,FLOOR($D8/18,1),0)+IF(AND(MOD($D8,18)>=R$3,$D8>0),1,0)-IF(R$3-18>$D8,1,0) -> 0 | S7: =IF($D8>0,FLOOR($D8/18,1),0)+IF(AND(MOD($D8,18)>=S$3,$D8>0),1,0)-IF(S$3-18>$D8,1,0) -> 0 | T7: =IF($D8>0,FLOOR($D8/18,1),0)+IF(AND(MOD($D8,18)>=T$3,$D8>0),1,0)-IF(T$3-18>$D8,1,0) -> 0 | U7: =IF($D8>0,FLOOR($D8/18,1),0)+IF(AND(MOD($D8,18)>=U$3,$D8>0),1,0)-IF(U$3-18>$D8,1,0) -> 0 | V7: =IF($D8>0,FLOOR($D8/18,1),0)+IF(AND(MOD($D8,18)>=V$3,$D8>0),1,0)-IF(V$3-18>$D8,1,0) -> 0 | W7: =IF($D8>0,FLOOR($D8/18,1),0)+IF(AND(MOD($D8,18)>=W$3,$D8>0),1,0)-IF(W$3-18>$D8,1,0) -> 0 | X7: =IF($D8>0,FLOOR($D8/18,1),0)+IF(AND(MOD($D8,18)>=X$3,$D8>0),1,0)-IF(X$3-18>$D8,1,0) -> 0 | Y7: =IF($D8>0,FLOOR($D8/18,1),0)+IF(AND(MOD($D8,18)>=Y$3,$D8>0),1,0)-IF(Y$3-18>$D8,1,0) -> 1
A8: ='Match Selection'!J4 -> Pace | B8: =VLOOKUP(A8, 'Master Input'!$A$11:$B$27, 2, FALSE) -> WEEZ | C8: =VLOOKUP(A8,'Master Input'!$A$11:$L$27,'Master Input'!$F$28, FALSE) -> 10 | D8: =C8-SMALL($C$8:$C$17,1) -> 1 | E8: 5 | F8: 6 | G8: 5 | H8: 5 | I8: 4 | J8: 7 | K8: 4 | L8: 5 | M8: 6 | N8: =IF(M8="","", SUM(E8:M8)) -> 47 | P8: =A8 -> Pace | Q8: 5 | R8: 4 | S8: 7 | T8: 3 | U8: 4 | V8: 4 | W8: 5 | X8: 3 | Y8: 7 | Z8: =IF(Y8="","", SUM(Q8:Y8)) -> 42 | AA8: =IF(Z8="", "", SUM(N8,Z8)) -> 89 | AB8: =IF(Y8="", "", AA8-C8) -> 79
E9: =IF(E10=1,"O", IF(E10=2,"O O","")) | F9: =IF(F10=1,"O", IF(F10=2,"O O","")) | G9: =IF(G10=1,"O", IF(G10=2,"O O","")) | H9: =IF(H10=1,"O", IF(H10=2,"O O","")) | I9: =IF(I10=1,"O", IF(I10=2,"O O","")) -> O | J9: =IF(J10=1,"O", IF(J10=2,"O O","")) -> O | K9: =IF(K10=1,"O", IF(K10=2,"O O","")) | L9: =IF(L10=1,"O", IF(L10=2,"O O","")) -> O | M9: =IF(M10=1,"O", IF(M10=2,"O O","")) -> O | Q9: =IF(Q10=1,"O", IF(Q10=2,"O O","")) | R9: =IF(R10=1,"O", IF(R10=2,"O O","")) | S9: =IF(S10=1,"O", IF(S10=2,"O O","")) -> O | T9: =IF(T10=1,"O", IF(T10=2,"O O","")) | U9: =IF(U10=1,"O", IF(U10=2,"O O","")) -> O | V9: =IF(V10=1,"O", IF(V10=2,"O O","")) -> O | W9: =IF(W10=1,"O", IF(W10=2,"O O","")) | X9: =IF(X10=1,"O", IF(X10=2,"O O","")) | Y9: =IF(Y10=1,"O", IF(Y10=2,"O O","")) -> O
E10: =IF($D11>0,FLOOR($D11/18,1),0)+IF(AND(MOD($D11,18)>=E$3,$D11>0),1,0)-IF(E$3-18>$D11,1,0) -> 0 | F10: =IF($D11>0,FLOOR($D11/18,1),0)+IF(AND(MOD($D11,18)>=F$3,$D11>0),1,0)-IF(F$3-18>$D11,1,0) -> 0 | G10: =IF($D11>0,FLOOR($D11/18,1),0)+IF(AND(MOD($D11,18)>=G$3,$D11>0),1,0)-IF(G$3-18>$D11,1,0) -> 0 | H10: =IF($D11>0,FLOOR($D11/18,1),0)+IF(AND(MOD($D11,18)>=H$3,$D11>0),1,0)-IF(H$3-18>$D11,1,0) -> 0 | I10: =IF($D11>0,FLOOR($D11/18,1),0)+IF(AND(MOD($D11,18)>=I$3,$D11>0),1,0)-IF(I$3-18>$D11,1,0) -> 1 | J10: =IF($D11>0,FLOOR($D11/18,1),0)+IF(AND(MOD($D11,18)>=J$3,$D11>0),1,0)-IF(J$3-18>$D11,1,0) -> 1 | K10: =IF($D11>0,FLOOR($D11/18,1),0)+IF(AND(MOD($D11,18)>=K$3,$D11>0),1,0)-IF(K$3-18>$D11,1,0) -> 0 | L10: =IF($D11>0,FLOOR($D11/18,1),0)+IF(AND(MOD($D11,18)>=L$3,$D11>0),1,0)-IF(L$3-18>$D11,1,0) -> 1 | M10: =IF($D11>0,FLOOR($D11/18,1),0)+IF(AND(MOD($D11,18)>=M$3,$D11>0),1,0)-IF(M$3-18>$D11,1,0) -> 1 | Q10: =IF($D11>0,FLOOR($D11/18,1),0)+IF(AND(MOD($D11,18)>=Q$3,$D11>0),1,0)-IF(Q$3-18>$D11,1,0) -> 0 | R10: =IF($D11>0,FLOOR($D11/18,1),0)+IF(AND(MOD($D11,18)>=R$3,$D11>0),1,0)-IF(R$3-18>$D11,1,0) -> 0 | S10: =IF($D11>0,FLOOR($D11/18,1),0)+IF(AND(MOD($D11,18)>=S$3,$D11>0),1,0)-IF(S$3-18>$D11,1,0) -> 1 | T10: =IF($D11>0,FLOOR($D11/18,1),0)+IF(AND(MOD($D11,18)>=T$3,$D11>0),1,0)-IF(T$3-18>$D11,1,0) -> 0 | U10: =IF($D11>0,FLOOR($D11/18,1),0)+IF(AND(MOD($D11,18)>=U$3,$D11>0),1,0)-IF(U$3-18>$D11,1,0) -> 1 | V10: =IF($D11>0,FLOOR($D11/18,1),0)+IF(AND(MOD($D11,18)>=V$3,$D11>0),1,0)-IF(V$3-18>$D11,1,0) -> 1 | W10: =IF($D11>0,FLOOR($D11/18,1),0)+IF(AND(MOD($D11,18)>=W$3,$D11>0),1,0)-IF(W$3-18>$D11,1,0) -> 0 | X10: =IF($D11>0,FLOOR($D11/18,1),0)+IF(AND(MOD($D11,18)>=X$3,$D11>0),1,0)-IF(X$3-18>$D11,1,0) -> 0 | Y10: =IF($D11>0,FLOOR($D11/18,1),0)+IF(AND(MOD($D11,18)>=Y$3,$D11>0),1,0)-IF(Y$3-18>$D11,1,0) -> 1
A11: ='Match Selection'!J5 -> Weezy | B11: =VLOOKUP(A11, 'Master Input'!$A$11:$B$27, 2, FALSE) -> WEEZ | C11: =VLOOKUP(A11,'Master Input'!$A$11:$L$27,'Master Input'!$F$28, FALSE) -> 17 | D11: =C11-SMALL($C$8:$C$17,1) -> 8 | E11: 5 | F11: 5 | G11: 3 | H11: 4 | I11: 6 | J11: 7 | K11: 3 | L11: 5 | M11: 9 | N11: =IF(M11="","", SUM(E11:M11)) -> 47 | P11: =A11 -> Weezy | Q11: 6 | R11: 4 | S11: 5 | T11: 3 | U11: 5 | V11: 4 | W11: 9 | X11: 5 | Y11: 5 | Z11: =IF(Y11="","", SUM(Q11:Y11)) -> 46 | AA11: =IF(Z11="", "", SUM(N11,Z11)) -> 93 | AB11: =IF(Y11="", "", AA11-C11) -> 76
